[2016-10-27 13:29:33] DEBUG [django.db.backends:89] (0.001) 
            SELECT name, type FROM sqlite_master
            WHERE type in ('table', 'view') AND NOT name='sqlite_sequence'
            ORDER BY name; args=None
[2016-10-27 13:29:33] DEBUG [django.db.backends:89] (0.000) SELECT "django_migrations"."app", "django_migrations"."name" FROM "django_migrations"; args=()
[2016-10-27 13:29:33] DEBUG [django.db.backends:89] (0.001) SELECT "auths_user"."password", "auths_user"."last_login", "auths_user"."is_superuser", "auths_user"."username", "auths_user"."first_name", "auths_user"."last_name", "auths_user"."email", "auths_user"."is_staff", "auths_user"."is_active", "auths_user"."date_joined", "auths_user"."id", "auths_user"."last_hierarchy_id", "auths_user"."last_module_id", "auths_user"."person_id", "auths_user"."updated_at", "auths_user"."registered_by" FROM "auths_user" WHERE "auths_user"."username" IS NULL; args=()
[2016-10-27 13:29:33] DEBUG [django.db.backends:89] (0.001) SELECT "oauth2_provider_accesstoken"."id", "oauth2_provider_accesstoken"."user_id", "oauth2_provider_accesstoken"."token", "oauth2_provider_accesstoken"."application_id", "oauth2_provider_accesstoken"."expires", "oauth2_provider_accesstoken"."scope", "auths_user"."password", "auths_user"."last_login", "auths_user"."is_superuser", "auths_user"."username", "auths_user"."first_name", "auths_user"."last_name", "auths_user"."email", "auths_user"."is_staff", "auths_user"."is_active", "auths_user"."date_joined", "auths_user"."id", "auths_user"."last_hierarchy_id", "auths_user"."last_module_id", "auths_user"."person_id", "auths_user"."updated_at", "auths_user"."registered_by", "oauth2_provider_application"."id", "oauth2_provider_application"."client_id", "oauth2_provider_application"."user_id", "oauth2_provider_application"."redirect_uris", "oauth2_provider_application"."client_type", "oauth2_provider_application"."authorization_grant_type", "oauth2_provider_application"."client_secret", "oauth2_provider_application"."name", "oauth2_provider_application"."skip_authorization" FROM "oauth2_provider_accesstoken" LEFT OUTER JOIN "auths_user" ON ("oauth2_provider_accesstoken"."user_id" = "auths_user"."id") INNER JOIN "oauth2_provider_application" ON ("oauth2_provider_accesstoken"."application_id" = "oauth2_provider_application"."id") WHERE "oauth2_provider_accesstoken"."token" = '4Jmb84m0IjvAkhGmXz6vqzNNX62XVV'; args=('4Jmb84m0IjvAkhGmXz6vqzNNX62XVV',)
[2016-10-27 13:29:33] DEBUG [django.db.backends:89] (0.000) SELECT "catalogo_categoria"."id", "catalogo_categoria"."nombre", "catalogo_categoria"."codigo", "catalogo_categoria"."estado" FROM "catalogo_categoria" WHERE ("catalogo_categoria"."codigo" LIKE '%%' ESCAPE '\' OR "catalogo_categoria"."nombre" LIKE '%%' ESCAPE '\'); args=('%%', '%%')
[2016-10-27 13:29:33] DEBUG [django.db.backends:89] (0.002) SELECT "auths_user"."password", "auths_user"."last_login", "auths_user"."is_superuser", "auths_user"."username", "auths_user"."first_name", "auths_user"."last_name", "auths_user"."email", "auths_user"."is_staff", "auths_user"."is_active", "auths_user"."date_joined", "auths_user"."id", "auths_user"."last_hierarchy_id", "auths_user"."last_module_id", "auths_user"."person_id", "auths_user"."updated_at", "auths_user"."registered_by" FROM "auths_user" WHERE "auths_user"."username" IS NULL; args=()
[2016-10-27 13:29:33] DEBUG [django.db.backends:89] (0.000) SELECT "oauth2_provider_accesstoken"."id", "oauth2_provider_accesstoken"."user_id", "oauth2_provider_accesstoken"."token", "oauth2_provider_accesstoken"."application_id", "oauth2_provider_accesstoken"."expires", "oauth2_provider_accesstoken"."scope", "auths_user"."password", "auths_user"."last_login", "auths_user"."is_superuser", "auths_user"."username", "auths_user"."first_name", "auths_user"."last_name", "auths_user"."email", "auths_user"."is_staff", "auths_user"."is_active", "auths_user"."date_joined", "auths_user"."id", "auths_user"."last_hierarchy_id", "auths_user"."last_module_id", "auths_user"."person_id", "auths_user"."updated_at", "auths_user"."registered_by", "oauth2_provider_application"."id", "oauth2_provider_application"."client_id", "oauth2_provider_application"."user_id", "oauth2_provider_application"."redirect_uris", "oauth2_provider_application"."client_type", "oauth2_provider_application"."authorization_grant_type", "oauth2_provider_application"."client_secret", "oauth2_provider_application"."name", "oauth2_provider_application"."skip_authorization" FROM "oauth2_provider_accesstoken" LEFT OUTER JOIN "auths_user" ON ("oauth2_provider_accesstoken"."user_id" = "auths_user"."id") INNER JOIN "oauth2_provider_application" ON ("oauth2_provider_accesstoken"."application_id" = "oauth2_provider_application"."id") WHERE "oauth2_provider_accesstoken"."token" = '4Jmb84m0IjvAkhGmXz6vqzNNX62XVV'; args=('4Jmb84m0IjvAkhGmXz6vqzNNX62XVV',)
[2016-10-27 13:29:33] DEBUG [django.db.backends:89] (0.000) SELECT COUNT(*) AS "__count" FROM "catalogo_autor"; args=()
[2016-10-27 13:29:33] DEBUG [django.db.backends:89] (0.000) SELECT "catalogo_autor"."id", "catalogo_autor"."nombre", "catalogo_autor"."direccion", "catalogo_autor"."fecha_nac", "catalogo_autor"."created_at", "catalogo_autor"."updated_at" FROM "catalogo_autor" LIMIT 5; args=()
[2016-10-27 13:29:34] DEBUG [django.db.backends:89] (0.001) SELECT "auths_user"."password", "auths_user"."last_login", "auths_user"."is_superuser", "auths_user"."username", "auths_user"."first_name", "auths_user"."last_name", "auths_user"."email", "auths_user"."is_staff", "auths_user"."is_active", "auths_user"."date_joined", "auths_user"."id", "auths_user"."last_hierarchy_id", "auths_user"."last_module_id", "auths_user"."person_id", "auths_user"."updated_at", "auths_user"."registered_by" FROM "auths_user" WHERE "auths_user"."username" IS NULL; args=()
[2016-10-27 13:29:34] DEBUG [django.db.backends:89] (0.000) SELECT "oauth2_provider_accesstoken"."id", "oauth2_provider_accesstoken"."user_id", "oauth2_provider_accesstoken"."token", "oauth2_provider_accesstoken"."application_id", "oauth2_provider_accesstoken"."expires", "oauth2_provider_accesstoken"."scope", "auths_user"."password", "auths_user"."last_login", "auths_user"."is_superuser", "auths_user"."username", "auths_user"."first_name", "auths_user"."last_name", "auths_user"."email", "auths_user"."is_staff", "auths_user"."is_active", "auths_user"."date_joined", "auths_user"."id", "auths_user"."last_hierarchy_id", "auths_user"."last_module_id", "auths_user"."person_id", "auths_user"."updated_at", "auths_user"."registered_by", "oauth2_provider_application"."id", "oauth2_provider_application"."client_id", "oauth2_provider_application"."user_id", "oauth2_provider_application"."redirect_uris", "oauth2_provider_application"."client_type", "oauth2_provider_application"."authorization_grant_type", "oauth2_provider_application"."client_secret", "oauth2_provider_application"."name", "oauth2_provider_application"."skip_authorization" FROM "oauth2_provider_accesstoken" LEFT OUTER JOIN "auths_user" ON ("oauth2_provider_accesstoken"."user_id" = "auths_user"."id") INNER JOIN "oauth2_provider_application" ON ("oauth2_provider_accesstoken"."application_id" = "oauth2_provider_application"."id") WHERE "oauth2_provider_accesstoken"."token" = '4Jmb84m0IjvAkhGmXz6vqzNNX62XVV'; args=('4Jmb84m0IjvAkhGmXz6vqzNNX62XVV',)
[2016-10-27 13:29:34] DEBUG [django.db.backends:89] (0.000) SELECT "catalogo_categoria"."id", "catalogo_categoria"."nombre", "catalogo_categoria"."codigo", "catalogo_categoria"."estado" FROM "catalogo_categoria" WHERE ("catalogo_categoria"."codigo" LIKE '%%' ESCAPE '\' OR "catalogo_categoria"."nombre" LIKE '%%' ESCAPE '\'); args=('%%', '%%')
[2016-10-27 13:29:36] DEBUG [django.db.backends:89] (0.001) SELECT "auths_user"."password", "auths_user"."last_login", "auths_user"."is_superuser", "auths_user"."username", "auths_user"."first_name", "auths_user"."last_name", "auths_user"."email", "auths_user"."is_staff", "auths_user"."is_active", "auths_user"."date_joined", "auths_user"."id", "auths_user"."last_hierarchy_id", "auths_user"."last_module_id", "auths_user"."person_id", "auths_user"."updated_at", "auths_user"."registered_by" FROM "auths_user" WHERE "auths_user"."username" IS NULL; args=()
[2016-10-27 13:29:36] DEBUG [django.db.backends:89] (0.001) SELECT "oauth2_provider_accesstoken"."id", "oauth2_provider_accesstoken"."user_id", "oauth2_provider_accesstoken"."token", "oauth2_provider_accesstoken"."application_id", "oauth2_provider_accesstoken"."expires", "oauth2_provider_accesstoken"."scope", "auths_user"."password", "auths_user"."last_login", "auths_user"."is_superuser", "auths_user"."username", "auths_user"."first_name", "auths_user"."last_name", "auths_user"."email", "auths_user"."is_staff", "auths_user"."is_active", "auths_user"."date_joined", "auths_user"."id", "auths_user"."last_hierarchy_id", "auths_user"."last_module_id", "auths_user"."person_id", "auths_user"."updated_at", "auths_user"."registered_by", "oauth2_provider_application"."id", "oauth2_provider_application"."client_id", "oauth2_provider_application"."user_id", "oauth2_provider_application"."redirect_uris", "oauth2_provider_application"."client_type", "oauth2_provider_application"."authorization_grant_type", "oauth2_provider_application"."client_secret", "oauth2_provider_application"."name", "oauth2_provider_application"."skip_authorization" FROM "oauth2_provider_accesstoken" LEFT OUTER JOIN "auths_user" ON ("oauth2_provider_accesstoken"."user_id" = "auths_user"."id") INNER JOIN "oauth2_provider_application" ON ("oauth2_provider_accesstoken"."application_id" = "oauth2_provider_application"."id") WHERE "oauth2_provider_accesstoken"."token" = '4Jmb84m0IjvAkhGmXz6vqzNNX62XVV'; args=('4Jmb84m0IjvAkhGmXz6vqzNNX62XVV',)
[2016-10-27 13:29:36] DEBUG [django.db.backends:89] (0.000) SELECT COUNT(*) AS "__count" FROM "catalogo_autor"; args=()
[2016-10-27 13:29:36] DEBUG [django.db.backends:89] (0.000) SELECT "catalogo_autor"."id", "catalogo_autor"."nombre", "catalogo_autor"."direccion", "catalogo_autor"."fecha_nac", "catalogo_autor"."created_at", "catalogo_autor"."updated_at" FROM "catalogo_autor" LIMIT 5; args=()
[2016-10-27 13:29:39] DEBUG [django.db.backends:89] (0.001) SELECT "auths_user"."password", "auths_user"."last_login", "auths_user"."is_superuser", "auths_user"."username", "auths_user"."first_name", "auths_user"."last_name", "auths_user"."email", "auths_user"."is_staff", "auths_user"."is_active", "auths_user"."date_joined", "auths_user"."id", "auths_user"."last_hierarchy_id", "auths_user"."last_module_id", "auths_user"."person_id", "auths_user"."updated_at", "auths_user"."registered_by" FROM "auths_user" WHERE "auths_user"."username" IS NULL; args=()
[2016-10-27 13:29:39] DEBUG [django.db.backends:89] (0.000) SELECT "oauth2_provider_accesstoken"."id", "oauth2_provider_accesstoken"."user_id", "oauth2_provider_accesstoken"."token", "oauth2_provider_accesstoken"."application_id", "oauth2_provider_accesstoken"."expires", "oauth2_provider_accesstoken"."scope", "auths_user"."password", "auths_user"."last_login", "auths_user"."is_superuser", "auths_user"."username", "auths_user"."first_name", "auths_user"."last_name", "auths_user"."email", "auths_user"."is_staff", "auths_user"."is_active", "auths_user"."date_joined", "auths_user"."id", "auths_user"."last_hierarchy_id", "auths_user"."last_module_id", "auths_user"."person_id", "auths_user"."updated_at", "auths_user"."registered_by", "oauth2_provider_application"."id", "oauth2_provider_application"."client_id", "oauth2_provider_application"."user_id", "oauth2_provider_application"."redirect_uris", "oauth2_provider_application"."client_type", "oauth2_provider_application"."authorization_grant_type", "oauth2_provider_application"."client_secret", "oauth2_provider_application"."name", "oauth2_provider_application"."skip_authorization" FROM "oauth2_provider_accesstoken" LEFT OUTER JOIN "auths_user" ON ("oauth2_provider_accesstoken"."user_id" = "auths_user"."id") INNER JOIN "oauth2_provider_application" ON ("oauth2_provider_accesstoken"."application_id" = "oauth2_provider_application"."id") WHERE "oauth2_provider_accesstoken"."token" = '4Jmb84m0IjvAkhGmXz6vqzNNX62XVV'; args=('4Jmb84m0IjvAkhGmXz6vqzNNX62XVV',)
[2016-10-27 13:29:39] DEBUG [django.db.backends:89] (0.000) SELECT COUNT(*) AS "__count" FROM "catalogo_autor"; args=()
[2016-10-27 13:29:39] DEBUG [django.db.backends:89] (0.000) SELECT "catalogo_autor"."id", "catalogo_autor"."nombre", "catalogo_autor"."direccion", "catalogo_autor"."fecha_nac", "catalogo_autor"."created_at", "catalogo_autor"."updated_at" FROM "catalogo_autor" LIMIT 2 OFFSET 5; args=()
[2016-10-27 18:00:18] DEBUG [django.db.backends:89] (0.000) 
            SELECT name, type FROM sqlite_master
            WHERE type in ('table', 'view') AND NOT name='sqlite_sequence'
            ORDER BY name; args=None
[2016-10-27 18:00:18] DEBUG [django.db.backends:89] (0.000) SELECT "django_migrations"."app", "django_migrations"."name" FROM "django_migrations"; args=()
[2016-10-27 18:00:34] DEBUG [django.db.backends:89] (0.000) 
            SELECT name, type FROM sqlite_master
            WHERE type in ('table', 'view') AND NOT name='sqlite_sequence'
            ORDER BY name; args=None
[2016-10-27 18:00:34] DEBUG [django.db.backends:89] (0.000) SELECT "django_migrations"."app", "django_migrations"."name" FROM "django_migrations"; args=()
[2016-10-27 18:00:53] WARNING [django.request:182] Not Found: /
[2016-10-27 18:00:53] DEBUG [django.template:927] Exception while resolving variable 'name' in template 'unknown'.
Traceback (most recent call last):
  File "E:\cursotaller\initial_vemo
\ve_vemo
\lib\site-packages\django\core\handlers\base.py", line 134, in get_response
    resolver_match = resolver.resolve(request.path_info)
  File "E:\cursotaller\initial_vemo
\ve_vemo
\lib\site-packages\django\core\urlresolvers.py", line 404, in resolve
    raise Resolver404({'tried': tried, 'path': new_path})
django.core.urlresolvers.Resolver404: {'path': '', 'tried': [[<RegexURLResolver <RegexURLPattern list> (admin:admin) ^admin/>], [<RegexURLResolver <module 'django.contrib.admindocs.urls' from 'E:\\cursotaller\\initial_vemo
\\ve_vemo
\\lib\\site-packages\\django\\contrib\\admindocs\\urls.py'> (None:None) ^admin/doc/>], [<RegexURLResolver <module 'rest_framework.urls' from 'E:\\cursotaller\\initial_vemo
\\ve_vemo
\\lib\\site-packages\\rest_framework\\urls.py'> (rest_framework:rest_framework) ^api-auth/>], [<RegexURLResolver <module 'oauth2_provider.urls' from 'E:\\cursotaller\\initial_vemo
\\ve_vemo
\\lib\\site-packages\\oauth2_provider\\urls.py'> (None:oauth2_provider) ^o/>], [<RegexURLResolver <module 'vemo
_service_apps.auths_api.urls' from 'E:\\cursotaller\\initial_vemo
\\vemo
_service\\vemo
_service_apps\\auths_api\\urls.py'> (None:None) ^api/auths/>], [<RegexURLResolver <module 'vemo
_service_apps.catalogo_api.urls' from 'E:\\cursotaller\\initial_vemo
\\vemo
_service\\vemo
_service_apps\\catalogo_api\\urls.py'> (None:None) ^api/catalogo/>]]}

During handling of the above exception, another exception occurred:

Traceback (most recent call last):
  File "E:\cursotaller\initial_vemo
\ve_vemo
\lib\site-packages\django\template\base.py", line 883, in _resolve_lookup
    current = current[bit]
TypeError: 'RegexURLResolver' object is not subscriptable

During handling of the above exception, another exception occurred:

Traceback (most recent call last):
  File "E:\cursotaller\initial_vemo
\ve_vemo
\lib\site-packages\django\template\base.py", line 891, in _resolve_lookup
    current = getattr(current, bit)
AttributeError: 'RegexURLResolver' object has no attribute 'name'

During handling of the above exception, another exception occurred:

Traceback (most recent call last):
  File "E:\cursotaller\initial_vemo
\ve_vemo
\lib\site-packages\django\template\base.py", line 898, in _resolve_lookup
    current = current[int(bit)]
ValueError: invalid literal for int() with base 10: 'name'

During handling of the above exception, another exception occurred:

Traceback (most recent call last):
  File "E:\cursotaller\initial_vemo
\ve_vemo
\lib\site-packages\django\template\base.py", line 905, in _resolve_lookup
    (bit, current))  # missing attribute
django.template.base.VariableDoesNotExist: Failed lookup for key [name] in '<RegexURLResolver <RegexURLPattern list> (admin:admin) ^admin/>'
[2016-10-27 18:00:53] DEBUG [django.template:927] Exception while resolving variable 'name' in template 'unknown'.
Traceback (most recent call last):
  File "E:\cursotaller\initial_vemo
\ve_vemo
\lib\site-packages\django\core\handlers\base.py", line 134, in get_response
    resolver_match = resolver.resolve(request.path_info)
  File "E:\cursotaller\initial_vemo
\ve_vemo
\lib\site-packages\django\core\urlresolvers.py", line 404, in resolve
    raise Resolver404({'tried': tried, 'path': new_path})
django.core.urlresolvers.Resolver404: {'path': '', 'tried': [[<RegexURLResolver <RegexURLPattern list> (admin:admin) ^admin/>], [<RegexURLResolver <module 'django.contrib.admindocs.urls' from 'E:\\cursotaller\\initial_vemo
\\ve_vemo
\\lib\\site-packages\\django\\contrib\\admindocs\\urls.py'> (None:None) ^admin/doc/>], [<RegexURLResolver <module 'rest_framework.urls' from 'E:\\cursotaller\\initial_vemo
\\ve_vemo
\\lib\\site-packages\\rest_framework\\urls.py'> (rest_framework:rest_framework) ^api-auth/>], [<RegexURLResolver <module 'oauth2_provider.urls' from 'E:\\cursotaller\\initial_vemo
\\ve_vemo
\\lib\\site-packages\\oauth2_provider\\urls.py'> (None:oauth2_provider) ^o/>], [<RegexURLResolver <module 'vemo
_service_apps.auths_api.urls' from 'E:\\cursotaller\\initial_vemo
\\vemo
_service\\vemo
_service_apps\\auths_api\\urls.py'> (None:None) ^api/auths/>], [<RegexURLResolver <module 'vemo
_service_apps.catalogo_api.urls' from 'E:\\cursotaller\\initial_vemo
\\vemo
_service\\vemo
_service_apps\\catalogo_api\\urls.py'> (None:None) ^api/catalogo/>]]}

During handling of the above exception, another exception occurred:

Traceback (most recent call last):
  File "E:\cursotaller\initial_vemo
\ve_vemo
\lib\site-packages\django\template\base.py", line 883, in _resolve_lookup
    current = current[bit]
TypeError: 'RegexURLResolver' object is not subscriptable

During handling of the above exception, another exception occurred:

Traceback (most recent call last):
  File "E:\cursotaller\initial_vemo
\ve_vemo
\lib\site-packages\django\template\base.py", line 891, in _resolve_lookup
    current = getattr(current, bit)
AttributeError: 'RegexURLResolver' object has no attribute 'name'

During handling of the above exception, another exception occurred:

Traceback (most recent call last):
  File "E:\cursotaller\initial_vemo
\ve_vemo
\lib\site-packages\django\template\base.py", line 898, in _resolve_lookup
    current = current[int(bit)]
ValueError: invalid literal for int() with base 10: 'name'

During handling of the above exception, another exception occurred:

Traceback (most recent call last):
  File "E:\cursotaller\initial_vemo
\ve_vemo
\lib\site-packages\django\template\base.py", line 905, in _resolve_lookup
    (bit, current))  # missing attribute
django.template.base.VariableDoesNotExist: Failed lookup for key [name] in "<RegexURLResolver <module 'django.contrib.admindocs.urls' from 'E:\\\\cursotaller\\\\initial_vemo
\\\\ve_vemo
\\\\lib\\\\site-packages\\\\django\\\\contrib\\\\admindocs\\\\urls.py'> (None:None) ^admin/doc/>"
[2016-10-27 18:00:53] DEBUG [django.template:927] Exception while resolving variable 'name' in template 'unknown'.
Traceback (most recent call last):
  File "E:\cursotaller\initial_vemo
\ve_vemo
\lib\site-packages\django\core\handlers\base.py", line 134, in get_response
    resolver_match = resolver.resolve(request.path_info)
  File "E:\cursotaller\initial_vemo
\ve_vemo
\lib\site-packages\django\core\urlresolvers.py", line 404, in resolve
    raise Resolver404({'tried': tried, 'path': new_path})
django.core.urlresolvers.Resolver404: {'path': '', 'tried': [[<RegexURLResolver <RegexURLPattern list> (admin:admin) ^admin/>], [<RegexURLResolver <module 'django.contrib.admindocs.urls' from 'E:\\cursotaller\\initial_vemo
\\ve_vemo
\\lib\\site-packages\\django\\contrib\\admindocs\\urls.py'> (None:None) ^admin/doc/>], [<RegexURLResolver <module 'rest_framework.urls' from 'E:\\cursotaller\\initial_vemo
\\ve_vemo
\\lib\\site-packages\\rest_framework\\urls.py'> (rest_framework:rest_framework) ^api-auth/>], [<RegexURLResolver <module 'oauth2_provider.urls' from 'E:\\cursotaller\\initial_vemo
\\ve_vemo
\\lib\\site-packages\\oauth2_provider\\urls.py'> (None:oauth2_provider) ^o/>], [<RegexURLResolver <module 'vemo
_service_apps.auths_api.urls' from 'E:\\cursotaller\\initial_vemo
\\vemo
_service\\vemo
_service_apps\\auths_api\\urls.py'> (None:None) ^api/auths/>], [<RegexURLResolver <module 'vemo
_service_apps.catalogo_api.urls' from 'E:\\cursotaller\\initial_vemo
\\vemo
_service\\vemo
_service_apps\\catalogo_api\\urls.py'> (None:None) ^api/catalogo/>]]}

During handling of the above exception, another exception occurred:

Traceback (most recent call last):
  File "E:\cursotaller\initial_vemo
\ve_vemo
\lib\site-packages\django\template\base.py", line 883, in _resolve_lookup
    current = current[bit]
TypeError: 'RegexURLResolver' object is not subscriptable

During handling of the above exception, another exception occurred:

Traceback (most recent call last):
  File "E:\cursotaller\initial_vemo
\ve_vemo
\lib\site-packages\django\template\base.py", line 891, in _resolve_lookup
    current = getattr(current, bit)
AttributeError: 'RegexURLResolver' object has no attribute 'name'

During handling of the above exception, another exception occurred:

Traceback (most recent call last):
  File "E:\cursotaller\initial_vemo
\ve_vemo
\lib\site-packages\django\template\base.py", line 898, in _resolve_lookup
    current = current[int(bit)]
ValueError: invalid literal for int() with base 10: 'name'

During handling of the above exception, another exception occurred:

Traceback (most recent call last):
  File "E:\cursotaller\initial_vemo
\ve_vemo
\lib\site-packages\django\template\base.py", line 905, in _resolve_lookup
    (bit, current))  # missing attribute
django.template.base.VariableDoesNotExist: Failed lookup for key [name] in "<RegexURLResolver <module 'rest_framework.urls' from 'E:\\\\cursotaller\\\\initial_vemo
\\\\ve_vemo
\\\\lib\\\\site-packages\\\\rest_framework\\\\urls.py'> (rest_framework:rest_framework) ^api-auth/>"
[2016-10-27 18:00:53] DEBUG [django.template:927] Exception while resolving variable 'name' in template 'unknown'.
Traceback (most recent call last):
  File "E:\cursotaller\initial_vemo
\ve_vemo
\lib\site-packages\django\core\handlers\base.py", line 134, in get_response
    resolver_match = resolver.resolve(request.path_info)
  File "E:\cursotaller\initial_vemo
\ve_vemo
\lib\site-packages\django\core\urlresolvers.py", line 404, in resolve
    raise Resolver404({'tried': tried, 'path': new_path})
django.core.urlresolvers.Resolver404: {'path': '', 'tried': [[<RegexURLResolver <RegexURLPattern list> (admin:admin) ^admin/>], [<RegexURLResolver <module 'django.contrib.admindocs.urls' from 'E:\\cursotaller\\initial_vemo
\\ve_vemo
\\lib\\site-packages\\django\\contrib\\admindocs\\urls.py'> (None:None) ^admin/doc/>], [<RegexURLResolver <module 'rest_framework.urls' from 'E:\\cursotaller\\initial_vemo
\\ve_vemo
\\lib\\site-packages\\rest_framework\\urls.py'> (rest_framework:rest_framework) ^api-auth/>], [<RegexURLResolver <module 'oauth2_provider.urls' from 'E:\\cursotaller\\initial_vemo
\\ve_vemo
\\lib\\site-packages\\oauth2_provider\\urls.py'> (None:oauth2_provider) ^o/>], [<RegexURLResolver <module 'vemo
_service_apps.auths_api.urls' from 'E:\\cursotaller\\initial_vemo
\\vemo
_service\\vemo
_service_apps\\auths_api\\urls.py'> (None:None) ^api/auths/>], [<RegexURLResolver <module 'vemo
_service_apps.catalogo_api.urls' from 'E:\\cursotaller\\initial_vemo
\\vemo
_service\\vemo
_service_apps\\catalogo_api\\urls.py'> (None:None) ^api/catalogo/>]]}

During handling of the above exception, another exception occurred:

Traceback (most recent call last):
  File "E:\cursotaller\initial_vemo
\ve_vemo
\lib\site-packages\django\template\base.py", line 883, in _resolve_lookup
    current = current[bit]
TypeError: 'RegexURLResolver' object is not subscriptable

During handling of the above exception, another exception occurred:

Traceback (most recent call last):
  File "E:\cursotaller\initial_vemo
\ve_vemo
\lib\site-packages\django\template\base.py", line 891, in _resolve_lookup
    current = getattr(current, bit)
AttributeError: 'RegexURLResolver' object has no attribute 'name'

During handling of the above exception, another exception occurred:

Traceback (most recent call last):
  File "E:\cursotaller\initial_vemo
\ve_vemo
\lib\site-packages\django\template\base.py", line 898, in _resolve_lookup
    current = current[int(bit)]
ValueError: invalid literal for int() with base 10: 'name'

During handling of the above exception, another exception occurred:

Traceback (most recent call last):
  File "E:\cursotaller\initial_vemo
\ve_vemo
\lib\site-packages\django\template\base.py", line 905, in _resolve_lookup
    (bit, current))  # missing attribute
django.template.base.VariableDoesNotExist: Failed lookup for key [name] in "<RegexURLResolver <module 'oauth2_provider.urls' from 'E:\\\\cursotaller\\\\initial_vemo
\\\\ve_vemo
\\\\lib\\\\site-packages\\\\oauth2_provider\\\\urls.py'> (None:oauth2_provider) ^o/>"
[2016-10-27 18:00:53] DEBUG [django.template:927] Exception while resolving variable 'name' in template 'unknown'.
Traceback (most recent call last):
  File "E:\cursotaller\initial_vemo
\ve_vemo
\lib\site-packages\django\core\handlers\base.py", line 134, in get_response
    resolver_match = resolver.resolve(request.path_info)
  File "E:\cursotaller\initial_vemo
\ve_vemo
\lib\site-packages\django\core\urlresolvers.py", line 404, in resolve
    raise Resolver404({'tried': tried, 'path': new_path})
django.core.urlresolvers.Resolver404: {'path': '', 'tried': [[<RegexURLResolver <RegexURLPattern list> (admin:admin) ^admin/>], [<RegexURLResolver <module 'django.contrib.admindocs.urls' from 'E:\\cursotaller\\initial_vemo
\\ve_vemo
\\lib\\site-packages\\django\\contrib\\admindocs\\urls.py'> (None:None) ^admin/doc/>], [<RegexURLResolver <module 'rest_framework.urls' from 'E:\\cursotaller\\initial_vemo
\\ve_vemo
\\lib\\site-packages\\rest_framework\\urls.py'> (rest_framework:rest_framework) ^api-auth/>], [<RegexURLResolver <module 'oauth2_provider.urls' from 'E:\\cursotaller\\initial_vemo
\\ve_vemo
\\lib\\site-packages\\oauth2_provider\\urls.py'> (None:oauth2_provider) ^o/>], [<RegexURLResolver <module 'vemo
_service_apps.auths_api.urls' from 'E:\\cursotaller\\initial_vemo
\\vemo
_service\\vemo
_service_apps\\auths_api\\urls.py'> (None:None) ^api/auths/>], [<RegexURLResolver <module 'vemo
_service_apps.catalogo_api.urls' from 'E:\\cursotaller\\initial_vemo
\\vemo
_service\\vemo
_service_apps\\catalogo_api\\urls.py'> (None:None) ^api/catalogo/>]]}

During handling of the above exception, another exception occurred:

Traceback (most recent call last):
  File "E:\cursotaller\initial_vemo
\ve_vemo
\lib\site-packages\django\template\base.py", line 883, in _resolve_lookup
    current = current[bit]
TypeError: 'RegexURLResolver' object is not subscriptable

During handling of the above exception, another exception occurred:

Traceback (most recent call last):
  File "E:\cursotaller\initial_vemo
\ve_vemo
\lib\site-packages\django\template\base.py", line 891, in _resolve_lookup
    current = getattr(current, bit)
AttributeError: 'RegexURLResolver' object has no attribute 'name'

During handling of the above exception, another exception occurred:

Traceback (most recent call last):
  File "E:\cursotaller\initial_vemo
\ve_vemo
\lib\site-packages\django\template\base.py", line 898, in _resolve_lookup
    current = current[int(bit)]
ValueError: invalid literal for int() with base 10: 'name'

During handling of the above exception, another exception occurred:

Traceback (most recent call last):
  File "E:\cursotaller\initial_vemo
\ve_vemo
\lib\site-packages\django\template\base.py", line 905, in _resolve_lookup
    (bit, current))  # missing attribute
django.template.base.VariableDoesNotExist: Failed lookup for key [name] in "<RegexURLResolver <module 'vemo
_service_apps.auths_api.urls' from 'E:\\\\cursotaller\\\\initial_vemo
\\\\vemo
_service\\\\vemo
_service_apps\\\\auths_api\\\\urls.py'> (None:None) ^api/auths/>"
[2016-10-27 18:00:53] DEBUG [django.template:927] Exception while resolving variable 'name' in template 'unknown'.
Traceback (most recent call last):
  File "E:\cursotaller\initial_vemo
\ve_vemo
\lib\site-packages\django\core\handlers\base.py", line 134, in get_response
    resolver_match = resolver.resolve(request.path_info)
  File "E:\cursotaller\initial_vemo
\ve_vemo
\lib\site-packages\django\core\urlresolvers.py", line 404, in resolve
    raise Resolver404({'tried': tried, 'path': new_path})
django.core.urlresolvers.Resolver404: {'path': '', 'tried': [[<RegexURLResolver <RegexURLPattern list> (admin:admin) ^admin/>], [<RegexURLResolver <module 'django.contrib.admindocs.urls' from 'E:\\cursotaller\\initial_vemo
\\ve_vemo
\\lib\\site-packages\\django\\contrib\\admindocs\\urls.py'> (None:None) ^admin/doc/>], [<RegexURLResolver <module 'rest_framework.urls' from 'E:\\cursotaller\\initial_vemo
\\ve_vemo
\\lib\\site-packages\\rest_framework\\urls.py'> (rest_framework:rest_framework) ^api-auth/>], [<RegexURLResolver <module 'oauth2_provider.urls' from 'E:\\cursotaller\\initial_vemo
\\ve_vemo
\\lib\\site-packages\\oauth2_provider\\urls.py'> (None:oauth2_provider) ^o/>], [<RegexURLResolver <module 'vemo
_service_apps.auths_api.urls' from 'E:\\cursotaller\\initial_vemo
\\vemo
_service\\vemo
_service_apps\\auths_api\\urls.py'> (None:None) ^api/auths/>], [<RegexURLResolver <module 'vemo
_service_apps.catalogo_api.urls' from 'E:\\cursotaller\\initial_vemo
\\vemo
_service\\vemo
_service_apps\\catalogo_api\\urls.py'> (None:None) ^api/catalogo/>]]}

During handling of the above exception, another exception occurred:

Traceback (most recent call last):
  File "E:\cursotaller\initial_vemo
\ve_vemo
\lib\site-packages\django\template\base.py", line 883, in _resolve_lookup
    current = current[bit]
TypeError: 'RegexURLResolver' object is not subscriptable

During handling of the above exception, another exception occurred:

Traceback (most recent call last):
  File "E:\cursotaller\initial_vemo
\ve_vemo
\lib\site-packages\django\template\base.py", line 891, in _resolve_lookup
    current = getattr(current, bit)
AttributeError: 'RegexURLResolver' object has no attribute 'name'

During handling of the above exception, another exception occurred:

Traceback (most recent call last):
  File "E:\cursotaller\initial_vemo
\ve_vemo
\lib\site-packages\django\template\base.py", line 898, in _resolve_lookup
    current = current[int(bit)]
ValueError: invalid literal for int() with base 10: 'name'

During handling of the above exception, another exception occurred:

Traceback (most recent call last):
  File "E:\cursotaller\initial_vemo
\ve_vemo
\lib\site-packages\django\template\base.py", line 905, in _resolve_lookup
    (bit, current))  # missing attribute
django.template.base.VariableDoesNotExist: Failed lookup for key [name] in "<RegexURLResolver <module 'vemo
_service_apps.catalogo_api.urls' from 'E:\\\\cursotaller\\\\initial_vemo
\\\\vemo
_service\\\\vemo
_service_apps\\\\catalogo_api\\\\urls.py'> (None:None) ^api/catalogo/>"
[2016-10-27 18:00:53] WARNING [django.request:182] Not Found: /favicon.ico
[2016-10-27 18:00:53] DEBUG [django.template:927] Exception while resolving variable 'name' in template 'unknown'.
Traceback (most recent call last):
  File "E:\cursotaller\initial_vemo
\ve_vemo
\lib\site-packages\django\core\handlers\base.py", line 134, in get_response
    resolver_match = resolver.resolve(request.path_info)
  File "E:\cursotaller\initial_vemo
\ve_vemo
\lib\site-packages\django\core\urlresolvers.py", line 404, in resolve
    raise Resolver404({'tried': tried, 'path': new_path})
django.core.urlresolvers.Resolver404: {'path': 'favicon.ico', 'tried': [[<RegexURLResolver <RegexURLPattern list> (admin:admin) ^admin/>], [<RegexURLResolver <module 'django.contrib.admindocs.urls' from 'E:\\cursotaller\\initial_vemo
\\ve_vemo
\\lib\\site-packages\\django\\contrib\\admindocs\\urls.py'> (None:None) ^admin/doc/>], [<RegexURLResolver <module 'rest_framework.urls' from 'E:\\cursotaller\\initial_vemo
\\ve_vemo
\\lib\\site-packages\\rest_framework\\urls.py'> (rest_framework:rest_framework) ^api-auth/>], [<RegexURLResolver <module 'oauth2_provider.urls' from 'E:\\cursotaller\\initial_vemo
\\ve_vemo
\\lib\\site-packages\\oauth2_provider\\urls.py'> (None:oauth2_provider) ^o/>], [<RegexURLResolver <module 'vemo
_service_apps.auths_api.urls' from 'E:\\cursotaller\\initial_vemo
\\vemo
_service\\vemo
_service_apps\\auths_api\\urls.py'> (None:None) ^api/auths/>], [<RegexURLResolver <module 'vemo
_service_apps.catalogo_api.urls' from 'E:\\cursotaller\\initial_vemo
\\vemo
_service\\vemo
_service_apps\\catalogo_api\\urls.py'> (None:None) ^api/catalogo/>]]}

During handling of the above exception, another exception occurred:

Traceback (most recent call last):
  File "E:\cursotaller\initial_vemo
\ve_vemo
\lib\site-packages\django\template\base.py", line 883, in _resolve_lookup
    current = current[bit]
TypeError: 'RegexURLResolver' object is not subscriptable

During handling of the above exception, another exception occurred:

Traceback (most recent call last):
  File "E:\cursotaller\initial_vemo
\ve_vemo
\lib\site-packages\django\template\base.py", line 891, in _resolve_lookup
    current = getattr(current, bit)
AttributeError: 'RegexURLResolver' object has no attribute 'name'

During handling of the above exception, another exception occurred:

Traceback (most recent call last):
  File "E:\cursotaller\initial_vemo
\ve_vemo
\lib\site-packages\django\template\base.py", line 898, in _resolve_lookup
    current = current[int(bit)]
ValueError: invalid literal for int() with base 10: 'name'

During handling of the above exception, another exception occurred:

Traceback (most recent call last):
  File "E:\cursotaller\initial_vemo
\ve_vemo
\lib\site-packages\django\template\base.py", line 905, in _resolve_lookup
    (bit, current))  # missing attribute
django.template.base.VariableDoesNotExist: Failed lookup for key [name] in '<RegexURLResolver <RegexURLPattern list> (admin:admin) ^admin/>'
[2016-10-27 18:00:53] DEBUG [django.template:927] Exception while resolving variable 'name' in template 'unknown'.
Traceback (most recent call last):
  File "E:\cursotaller\initial_vemo
\ve_vemo
\lib\site-packages\django\core\handlers\base.py", line 134, in get_response
    resolver_match = resolver.resolve(request.path_info)
  File "E:\cursotaller\initial_vemo
\ve_vemo
\lib\site-packages\django\core\urlresolvers.py", line 404, in resolve
    raise Resolver404({'tried': tried, 'path': new_path})
django.core.urlresolvers.Resolver404: {'path': 'favicon.ico', 'tried': [[<RegexURLResolver <RegexURLPattern list> (admin:admin) ^admin/>], [<RegexURLResolver <module 'django.contrib.admindocs.urls' from 'E:\\cursotaller\\initial_vemo
\\ve_vemo
\\lib\\site-packages\\django\\contrib\\admindocs\\urls.py'> (None:None) ^admin/doc/>], [<RegexURLResolver <module 'rest_framework.urls' from 'E:\\cursotaller\\initial_vemo
\\ve_vemo
\\lib\\site-packages\\rest_framework\\urls.py'> (rest_framework:rest_framework) ^api-auth/>], [<RegexURLResolver <module 'oauth2_provider.urls' from 'E:\\cursotaller\\initial_vemo
\\ve_vemo
\\lib\\site-packages\\oauth2_provider\\urls.py'> (None:oauth2_provider) ^o/>], [<RegexURLResolver <module 'vemo
_service_apps.auths_api.urls' from 'E:\\cursotaller\\initial_vemo
\\vemo
_service\\vemo
_service_apps\\auths_api\\urls.py'> (None:None) ^api/auths/>], [<RegexURLResolver <module 'vemo
_service_apps.catalogo_api.urls' from 'E:\\cursotaller\\initial_vemo
\\vemo
_service\\vemo
_service_apps\\catalogo_api\\urls.py'> (None:None) ^api/catalogo/>]]}

During handling of the above exception, another exception occurred:

Traceback (most recent call last):
  File "E:\cursotaller\initial_vemo
\ve_vemo
\lib\site-packages\django\template\base.py", line 883, in _resolve_lookup
    current = current[bit]
TypeError: 'RegexURLResolver' object is not subscriptable

During handling of the above exception, another exception occurred:

Traceback (most recent call last):
  File "E:\cursotaller\initial_vemo
\ve_vemo
\lib\site-packages\django\template\base.py", line 891, in _resolve_lookup
    current = getattr(current, bit)
AttributeError: 'RegexURLResolver' object has no attribute 'name'

During handling of the above exception, another exception occurred:

Traceback (most recent call last):
  File "E:\cursotaller\initial_vemo
\ve_vemo
\lib\site-packages\django\template\base.py", line 898, in _resolve_lookup
    current = current[int(bit)]
ValueError: invalid literal for int() with base 10: 'name'

During handling of the above exception, another exception occurred:

Traceback (most recent call last):
  File "E:\cursotaller\initial_vemo
\ve_vemo
\lib\site-packages\django\template\base.py", line 905, in _resolve_lookup
    (bit, current))  # missing attribute
django.template.base.VariableDoesNotExist: Failed lookup for key [name] in "<RegexURLResolver <module 'django.contrib.admindocs.urls' from 'E:\\\\cursotaller\\\\initial_vemo
\\\\ve_vemo
\\\\lib\\\\site-packages\\\\django\\\\contrib\\\\admindocs\\\\urls.py'> (None:None) ^admin/doc/>"
[2016-10-27 18:00:53] DEBUG [django.template:927] Exception while resolving variable 'name' in template 'unknown'.
Traceback (most recent call last):
  File "E:\cursotaller\initial_vemo
\ve_vemo
\lib\site-packages\django\core\handlers\base.py", line 134, in get_response
    resolver_match = resolver.resolve(request.path_info)
  File "E:\cursotaller\initial_vemo
\ve_vemo
\lib\site-packages\django\core\urlresolvers.py", line 404, in resolve
    raise Resolver404({'tried': tried, 'path': new_path})
django.core.urlresolvers.Resolver404: {'path': 'favicon.ico', 'tried': [[<RegexURLResolver <RegexURLPattern list> (admin:admin) ^admin/>], [<RegexURLResolver <module 'django.contrib.admindocs.urls' from 'E:\\cursotaller\\initial_vemo
\\ve_vemo
\\lib\\site-packages\\django\\contrib\\admindocs\\urls.py'> (None:None) ^admin/doc/>], [<RegexURLResolver <module 'rest_framework.urls' from 'E:\\cursotaller\\initial_vemo
\\ve_vemo
\\lib\\site-packages\\rest_framework\\urls.py'> (rest_framework:rest_framework) ^api-auth/>], [<RegexURLResolver <module 'oauth2_provider.urls' from 'E:\\cursotaller\\initial_vemo
\\ve_vemo
\\lib\\site-packages\\oauth2_provider\\urls.py'> (None:oauth2_provider) ^o/>], [<RegexURLResolver <module 'vemo
_service_apps.auths_api.urls' from 'E:\\cursotaller\\initial_vemo
\\vemo
_service\\vemo
_service_apps\\auths_api\\urls.py'> (None:None) ^api/auths/>], [<RegexURLResolver <module 'vemo
_service_apps.catalogo_api.urls' from 'E:\\cursotaller\\initial_vemo
\\vemo
_service\\vemo
_service_apps\\catalogo_api\\urls.py'> (None:None) ^api/catalogo/>]]}

During handling of the above exception, another exception occurred:

Traceback (most recent call last):
  File "E:\cursotaller\initial_vemo
\ve_vemo
\lib\site-packages\django\template\base.py", line 883, in _resolve_lookup
    current = current[bit]
TypeError: 'RegexURLResolver' object is not subscriptable

During handling of the above exception, another exception occurred:

Traceback (most recent call last):
  File "E:\cursotaller\initial_vemo
\ve_vemo
\lib\site-packages\django\template\base.py", line 891, in _resolve_lookup
    current = getattr(current, bit)
AttributeError: 'RegexURLResolver' object has no attribute 'name'

During handling of the above exception, another exception occurred:

Traceback (most recent call last):
  File "E:\cursotaller\initial_vemo
\ve_vemo
\lib\site-packages\django\template\base.py", line 898, in _resolve_lookup
    current = current[int(bit)]
ValueError: invalid literal for int() with base 10: 'name'

During handling of the above exception, another exception occurred:

Traceback (most recent call last):
  File "E:\cursotaller\initial_vemo
\ve_vemo
\lib\site-packages\django\template\base.py", line 905, in _resolve_lookup
    (bit, current))  # missing attribute
django.template.base.VariableDoesNotExist: Failed lookup for key [name] in "<RegexURLResolver <module 'rest_framework.urls' from 'E:\\\\cursotaller\\\\initial_vemo
\\\\ve_vemo
\\\\lib\\\\site-packages\\\\rest_framework\\\\urls.py'> (rest_framework:rest_framework) ^api-auth/>"
[2016-10-27 18:00:53] DEBUG [django.template:927] Exception while resolving variable 'name' in template 'unknown'.
Traceback (most recent call last):
  File "E:\cursotaller\initial_vemo
\ve_vemo
\lib\site-packages\django\core\handlers\base.py", line 134, in get_response
    resolver_match = resolver.resolve(request.path_info)
  File "E:\cursotaller\initial_vemo
\ve_vemo
\lib\site-packages\django\core\urlresolvers.py", line 404, in resolve
    raise Resolver404({'tried': tried, 'path': new_path})
django.core.urlresolvers.Resolver404: {'path': 'favicon.ico', 'tried': [[<RegexURLResolver <RegexURLPattern list> (admin:admin) ^admin/>], [<RegexURLResolver <module 'django.contrib.admindocs.urls' from 'E:\\cursotaller\\initial_vemo
\\ve_vemo
\\lib\\site-packages\\django\\contrib\\admindocs\\urls.py'> (None:None) ^admin/doc/>], [<RegexURLResolver <module 'rest_framework.urls' from 'E:\\cursotaller\\initial_vemo
\\ve_vemo
\\lib\\site-packages\\rest_framework\\urls.py'> (rest_framework:rest_framework) ^api-auth/>], [<RegexURLResolver <module 'oauth2_provider.urls' from 'E:\\cursotaller\\initial_vemo
\\ve_vemo
\\lib\\site-packages\\oauth2_provider\\urls.py'> (None:oauth2_provider) ^o/>], [<RegexURLResolver <module 'vemo
_service_apps.auths_api.urls' from 'E:\\cursotaller\\initial_vemo
\\vemo
_service\\vemo
_service_apps\\auths_api\\urls.py'> (None:None) ^api/auths/>], [<RegexURLResolver <module 'vemo
_service_apps.catalogo_api.urls' from 'E:\\cursotaller\\initial_vemo
\\vemo
_service\\vemo
_service_apps\\catalogo_api\\urls.py'> (None:None) ^api/catalogo/>]]}

During handling of the above exception, another exception occurred:

Traceback (most recent call last):
  File "E:\cursotaller\initial_vemo
\ve_vemo
\lib\site-packages\django\template\base.py", line 883, in _resolve_lookup
    current = current[bit]
TypeError: 'RegexURLResolver' object is not subscriptable

During handling of the above exception, another exception occurred:

Traceback (most recent call last):
  File "E:\cursotaller\initial_vemo
\ve_vemo
\lib\site-packages\django\template\base.py", line 891, in _resolve_lookup
    current = getattr(current, bit)
AttributeError: 'RegexURLResolver' object has no attribute 'name'

During handling of the above exception, another exception occurred:

Traceback (most recent call last):
  File "E:\cursotaller\initial_vemo
\ve_vemo
\lib\site-packages\django\template\base.py", line 898, in _resolve_lookup
    current = current[int(bit)]
ValueError: invalid literal for int() with base 10: 'name'

During handling of the above exception, another exception occurred:

Traceback (most recent call last):
  File "E:\cursotaller\initial_vemo
\ve_vemo
\lib\site-packages\django\template\base.py", line 905, in _resolve_lookup
    (bit, current))  # missing attribute
django.template.base.VariableDoesNotExist: Failed lookup for key [name] in "<RegexURLResolver <module 'oauth2_provider.urls' from 'E:\\\\cursotaller\\\\initial_vemo
\\\\ve_vemo
\\\\lib\\\\site-packages\\\\oauth2_provider\\\\urls.py'> (None:oauth2_provider) ^o/>"
[2016-10-27 18:00:53] DEBUG [django.template:927] Exception while resolving variable 'name' in template 'unknown'.
Traceback (most recent call last):
  File "E:\cursotaller\initial_vemo
\ve_vemo
\lib\site-packages\django\core\handlers\base.py", line 134, in get_response
    resolver_match = resolver.resolve(request.path_info)
  File "E:\cursotaller\initial_vemo
\ve_vemo
\lib\site-packages\django\core\urlresolvers.py", line 404, in resolve
    raise Resolver404({'tried': tried, 'path': new_path})
django.core.urlresolvers.Resolver404: {'path': 'favicon.ico', 'tried': [[<RegexURLResolver <RegexURLPattern list> (admin:admin) ^admin/>], [<RegexURLResolver <module 'django.contrib.admindocs.urls' from 'E:\\cursotaller\\initial_vemo
\\ve_vemo
\\lib\\site-packages\\django\\contrib\\admindocs\\urls.py'> (None:None) ^admin/doc/>], [<RegexURLResolver <module 'rest_framework.urls' from 'E:\\cursotaller\\initial_vemo
\\ve_vemo
\\lib\\site-packages\\rest_framework\\urls.py'> (rest_framework:rest_framework) ^api-auth/>], [<RegexURLResolver <module 'oauth2_provider.urls' from 'E:\\cursotaller\\initial_vemo
\\ve_vemo
\\lib\\site-packages\\oauth2_provider\\urls.py'> (None:oauth2_provider) ^o/>], [<RegexURLResolver <module 'vemo
_service_apps.auths_api.urls' from 'E:\\cursotaller\\initial_vemo
\\vemo
_service\\vemo
_service_apps\\auths_api\\urls.py'> (None:None) ^api/auths/>], [<RegexURLResolver <module 'vemo
_service_apps.catalogo_api.urls' from 'E:\\cursotaller\\initial_vemo
\\vemo
_service\\vemo
_service_apps\\catalogo_api\\urls.py'> (None:None) ^api/catalogo/>]]}

During handling of the above exception, another exception occurred:

Traceback (most recent call last):
  File "E:\cursotaller\initial_vemo
\ve_vemo
\lib\site-packages\django\template\base.py", line 883, in _resolve_lookup
    current = current[bit]
TypeError: 'RegexURLResolver' object is not subscriptable

During handling of the above exception, another exception occurred:

Traceback (most recent call last):
  File "E:\cursotaller\initial_vemo
\ve_vemo
\lib\site-packages\django\template\base.py", line 891, in _resolve_lookup
    current = getattr(current, bit)
AttributeError: 'RegexURLResolver' object has no attribute 'name'

During handling of the above exception, another exception occurred:

Traceback (most recent call last):
  File "E:\cursotaller\initial_vemo
\ve_vemo
\lib\site-packages\django\template\base.py", line 898, in _resolve_lookup
    current = current[int(bit)]
ValueError: invalid literal for int() with base 10: 'name'

During handling of the above exception, another exception occurred:

Traceback (most recent call last):
  File "E:\cursotaller\initial_vemo
\ve_vemo
\lib\site-packages\django\template\base.py", line 905, in _resolve_lookup
    (bit, current))  # missing attribute
django.template.base.VariableDoesNotExist: Failed lookup for key [name] in "<RegexURLResolver <module 'vemo
_service_apps.auths_api.urls' from 'E:\\\\cursotaller\\\\initial_vemo
\\\\vemo
_service\\\\vemo
_service_apps\\\\auths_api\\\\urls.py'> (None:None) ^api/auths/>"
[2016-10-27 18:00:53] DEBUG [django.template:927] Exception while resolving variable 'name' in template 'unknown'.
Traceback (most recent call last):
  File "E:\cursotaller\initial_vemo
\ve_vemo
\lib\site-packages\django\core\handlers\base.py", line 134, in get_response
    resolver_match = resolver.resolve(request.path_info)
  File "E:\cursotaller\initial_vemo
\ve_vemo
\lib\site-packages\django\core\urlresolvers.py", line 404, in resolve
    raise Resolver404({'tried': tried, 'path': new_path})
django.core.urlresolvers.Resolver404: {'path': 'favicon.ico', 'tried': [[<RegexURLResolver <RegexURLPattern list> (admin:admin) ^admin/>], [<RegexURLResolver <module 'django.contrib.admindocs.urls' from 'E:\\cursotaller\\initial_vemo
\\ve_vemo
\\lib\\site-packages\\django\\contrib\\admindocs\\urls.py'> (None:None) ^admin/doc/>], [<RegexURLResolver <module 'rest_framework.urls' from 'E:\\cursotaller\\initial_vemo
\\ve_vemo
\\lib\\site-packages\\rest_framework\\urls.py'> (rest_framework:rest_framework) ^api-auth/>], [<RegexURLResolver <module 'oauth2_provider.urls' from 'E:\\cursotaller\\initial_vemo
\\ve_vemo
\\lib\\site-packages\\oauth2_provider\\urls.py'> (None:oauth2_provider) ^o/>], [<RegexURLResolver <module 'vemo
_service_apps.auths_api.urls' from 'E:\\cursotaller\\initial_vemo
\\vemo
_service\\vemo
_service_apps\\auths_api\\urls.py'> (None:None) ^api/auths/>], [<RegexURLResolver <module 'vemo
_service_apps.catalogo_api.urls' from 'E:\\cursotaller\\initial_vemo
\\vemo
_service\\vemo
_service_apps\\catalogo_api\\urls.py'> (None:None) ^api/catalogo/>]]}

During handling of the above exception, another exception occurred:

Traceback (most recent call last):
  File "E:\cursotaller\initial_vemo
\ve_vemo
\lib\site-packages\django\template\base.py", line 883, in _resolve_lookup
    current = current[bit]
TypeError: 'RegexURLResolver' object is not subscriptable

During handling of the above exception, another exception occurred:

Traceback (most recent call last):
  File "E:\cursotaller\initial_vemo
\ve_vemo
\lib\site-packages\django\template\base.py", line 891, in _resolve_lookup
    current = getattr(current, bit)
AttributeError: 'RegexURLResolver' object has no attribute 'name'

During handling of the above exception, another exception occurred:

Traceback (most recent call last):
  File "E:\cursotaller\initial_vemo
\ve_vemo
\lib\site-packages\django\template\base.py", line 898, in _resolve_lookup
    current = current[int(bit)]
ValueError: invalid literal for int() with base 10: 'name'

During handling of the above exception, another exception occurred:

Traceback (most recent call last):
  File "E:\cursotaller\initial_vemo
\ve_vemo
\lib\site-packages\django\template\base.py", line 905, in _resolve_lookup
    (bit, current))  # missing attribute
django.template.base.VariableDoesNotExist: Failed lookup for key [name] in "<RegexURLResolver <module 'vemo
_service_apps.catalogo_api.urls' from 'E:\\\\cursotaller\\\\initial_vemo
\\\\vemo
_service\\\\vemo
_service_apps\\\\catalogo_api\\\\urls.py'> (None:None) ^api/catalogo/>"
[2016-10-27 18:00:59] DEBUG [django.db.backends:89] (0.000) SELECT "django_session"."session_key", "django_session"."session_data", "django_session"."expire_date" FROM "django_session" WHERE ("django_session"."expire_date" > '2016-10-28 00:00:59.546495' AND "django_session"."session_key" = '2glc6kvqzbp9tq0b534zvwzec1y4cfmv'); args=('2016-10-28 00:00:59.546495', '2glc6kvqzbp9tq0b534zvwzec1y4cfmv')
[2016-10-27 18:00:59] DEBUG [django.template:927] Exception while resolving variable 'is_popup' in template 'admin/login.html'.
Traceback (most recent call last):
  File "E:\cursotaller\initial_vemo
\ve_vemo
\lib\site-packages\django\template\base.py", line 883, in _resolve_lookup
    current = current[bit]
  File "E:\cursotaller\initial_vemo
\ve_vemo
\lib\site-packages\django\template\context.py", line 77, in __getitem__
    raise KeyError(key)
KeyError: 'is_popup'

During handling of the above exception, another exception occurred:

Traceback (most recent call last):
  File "E:\cursotaller\initial_vemo
\ve_vemo
\lib\site-packages\django\template\base.py", line 889, in _resolve_lookup
    if isinstance(current, BaseContext) and getattr(type(current), bit):
AttributeError: type object 'RequestContext' has no attribute 'is_popup'

During handling of the above exception, another exception occurred:

Traceback (most recent call last):
  File "E:\cursotaller\initial_vemo
\ve_vemo
\lib\site-packages\django\template\base.py", line 898, in _resolve_lookup
    current = current[int(bit)]
ValueError: invalid literal for int() with base 10: 'is_popup'

During handling of the above exception, another exception occurred:

Traceback (most recent call last):
  File "E:\cursotaller\initial_vemo
\ve_vemo
\lib\site-packages\django\template\base.py", line 905, in _resolve_lookup
    (bit, current))  # missing attribute
django.template.base.VariableDoesNotExist: Failed lookup for key [is_popup] in "[{'None': None, 'False': False, 'True': True}, {'csrf_token': <SimpleLazyObject: <function csrf.<locals>._get_val at 0x04948DB0>>, 'messages': <django.contrib.messages.storage.fallback.FallbackStorage object at 0x04E63410>, 'request': <WSGIRequest: GET '/admin/login/?next=/admin/'>, 'perms': <django.contrib.auth.context_processors.PermWrapper object at 0x04E51BB0>, 'user': <SimpleLazyObject: <django.contrib.auth.models.AnonymousUser object at 0x04E638B0>>, 'DEFAULT_MESSAGE_LEVELS': {'WARNING': 30, 'SUCCESS': 25, 'DEBUG': 10, 'INFO': 20, 'ERROR': 40}}, {}, {'LANGUAGE_CODE': 'en-us', 'available_apps': [], 'next': '/admin/', 'title': 'Log in', 'site_name': '127.0.0.1:9000', 'site': <django.contrib.sites.requests.RequestSite object at 0x04A0B930>, 'form': <AdminAuthenticationForm bound=False, valid=Unknown, fields=(username;password)>, 'app_path': '/admin/login/?next=/admin/', 'LANGUAGE_BIDI': False, 'site_title': <django.utils.functional.lazy.<locals>.__proxy__ object at 0x03CFF9F0>, 'site_url': '/', 'has_permission': False, 'site_header': <django.utils.functional.lazy.<locals>.__proxy__ object at 0x03CFFAB0>}]"
[2016-10-27 18:00:59] DEBUG [django.template:927] Exception while resolving variable 'is_popup' in template 'admin/login.html'.
Traceback (most recent call last):
  File "E:\cursotaller\initial_vemo
\ve_vemo
\lib\site-packages\django\template\base.py", line 883, in _resolve_lookup
    current = current[bit]
  File "E:\cursotaller\initial_vemo
\ve_vemo
\lib\site-packages\django\template\context.py", line 77, in __getitem__
    raise KeyError(key)
KeyError: 'is_popup'

During handling of the above exception, another exception occurred:

Traceback (most recent call last):
  File "E:\cursotaller\initial_vemo
\ve_vemo
\lib\site-packages\django\template\base.py", line 889, in _resolve_lookup
    if isinstance(current, BaseContext) and getattr(type(current), bit):
AttributeError: type object 'RequestContext' has no attribute 'is_popup'

During handling of the above exception, another exception occurred:

Traceback (most recent call last):
  File "E:\cursotaller\initial_vemo
\ve_vemo
\lib\site-packages\django\template\base.py", line 898, in _resolve_lookup
    current = current[int(bit)]
ValueError: invalid literal for int() with base 10: 'is_popup'

During handling of the above exception, another exception occurred:

Traceback (most recent call last):
  File "E:\cursotaller\initial_vemo
\ve_vemo
\lib\site-packages\django\template\base.py", line 905, in _resolve_lookup
    (bit, current))  # missing attribute
django.template.base.VariableDoesNotExist: Failed lookup for key [is_popup] in "[{'None': None, 'False': False, 'True': True}, {'csrf_token': <SimpleLazyObject: <function csrf.<locals>._get_val at 0x04948DB0>>, 'messages': <django.contrib.messages.storage.fallback.FallbackStorage object at 0x04E63410>, 'request': <WSGIRequest: GET '/admin/login/?next=/admin/'>, 'perms': <django.contrib.auth.context_processors.PermWrapper object at 0x04E51BB0>, 'user': <SimpleLazyObject: <django.contrib.auth.models.AnonymousUser object at 0x04E638B0>>, 'DEFAULT_MESSAGE_LEVELS': {'WARNING': 30, 'SUCCESS': 25, 'DEBUG': 10, 'INFO': 20, 'ERROR': 40}}, {}, {'LANGUAGE_CODE': 'en-us', 'available_apps': [], 'next': '/admin/', 'title': 'Log in', 'site_name': '127.0.0.1:9000', 'site': <django.contrib.sites.requests.RequestSite object at 0x04A0B930>, 'form': <AdminAuthenticationForm bound=False, valid=Unknown, fields=(username;password)>, 'app_path': '/admin/login/?next=/admin/', 'LANGUAGE_BIDI': False, 'site_title': <django.utils.functional.lazy.<locals>.__proxy__ object at 0x03CFF9F0>, 'site_url': '/', 'has_permission': False, 'site_header': <django.utils.functional.lazy.<locals>.__proxy__ object at 0x03CFFAB0>}]"
[2016-10-27 18:01:08] DEBUG [django.db.backends:89] (0.000) SELECT "auths_user"."password", "auths_user"."last_login", "auths_user"."is_superuser", "auths_user"."username", "auths_user"."first_name", "auths_user"."last_name", "auths_user"."email", "auths_user"."is_staff", "auths_user"."is_active", "auths_user"."date_joined", "auths_user"."id", "auths_user"."last_hierarchy_id", "auths_user"."last_module_id", "auths_user"."person_id", "auths_user"."updated_at", "auths_user"."registered_by" FROM "auths_user" WHERE "auths_user"."username" = 'admin'; args=('admin',)
[2016-10-27 18:01:08] DEBUG [django.db.backends:89] (0.000) SELECT (1) AS "a" FROM "django_session" WHERE "django_session"."session_key" = 'puz9kr6ghi9hv6saesho10jss8jv9ih3' LIMIT 1; args=('puz9kr6ghi9hv6saesho10jss8jv9ih3',)
[2016-10-27 18:01:08] DEBUG [django.db.backends:89] (0.000) BEGIN; args=None
[2016-10-27 18:01:08] DEBUG [django.db.backends:89] (0.000) INSERT INTO "django_session" ("session_key", "session_data", "expire_date") SELECT 'puz9kr6ghi9hv6saesho10jss8jv9ih3', 'MWM0OGIyODQ4NzI4MzRhZjAyMjIxNmY1YzZlNzUwYmUzNTU2OWFjMTp7fQ==', '2016-11-11 00:01:08.950181'; args=('puz9kr6ghi9hv6saesho10jss8jv9ih3', 'MWM0OGIyODQ4NzI4MzRhZjAyMjIxNmY1YzZlNzUwYmUzNTU2OWFjMTp7fQ==', '2016-11-11 00:01:08.950181')
[2016-10-27 18:01:09] DEBUG [django.db.backends:89] (0.000) SELECT "django_session"."session_key", "django_session"."session_data", "django_session"."expire_date" FROM "django_session" WHERE "django_session"."session_key" = 'puz9kr6ghi9hv6saesho10jss8jv9ih3'; args=('puz9kr6ghi9hv6saesho10jss8jv9ih3',)
[2016-10-27 18:01:09] DEBUG [django.db.backends:89] (0.000) BEGIN; args=None
[2016-10-27 18:01:09] DEBUG [django.db.backends:89] (0.000) DELETE FROM "django_session" WHERE "django_session"."session_key" IN ('puz9kr6ghi9hv6saesho10jss8jv9ih3'); args=('puz9kr6ghi9hv6saesho10jss8jv9ih3',)
[2016-10-27 18:01:09] DEBUG [django.db.backends:89] (0.000) BEGIN; args=None
[2016-10-27 18:01:09] DEBUG [django.db.backends:89] (0.000) UPDATE "auths_user" SET "last_login" = '2016-10-28 00:01:09.108271' WHERE "auths_user"."id" = '98c929be19fb4598b30233dd1ddbfcfd'; args=('2016-10-28 00:01:09.108271', '98c929be19fb4598b30233dd1ddbfcfd')
[2016-10-27 18:01:09] DEBUG [django.db.backends:89] (0.000) BEGIN; args=None
[2016-10-27 18:01:09] DEBUG [django.db.backends:89] (0.000) UPDATE "django_session" SET "session_data" = 'MzkyMmQzMGY3NmQzY2Q4YTJkNjE1MGFjY2Y1YjViMzU0ZWIwMWMyODp7Il9hdXRoX3VzZXJfYmFja2VuZCI6ImRqYW5nby5jb250cmliLmF1dGguYmFja2VuZHMuTW9kZWxCYWNrZW5kIiwiX2F1dGhfdXNlcl9pZCI6Ijk4YzkyOWJlLTE5ZmItNDU5OC1iMzAyLTMzZGQxZGRiZmNmZCIsIl9hdXRoX3VzZXJfaGFzaCI6Ijg3ZmM3NWRhMjRkYWVjMjdmMGUxMTc5ODYxMzYyYzFhMDliZWI2YTEifQ==', "expire_date" = '2016-11-11 00:01:09.183575' WHERE "django_session"."session_key" = 'puz9kr6ghi9hv6saesho10jss8jv9ih3'; args=('MzkyMmQzMGY3NmQzY2Q4YTJkNjE1MGFjY2Y1YjViMzU0ZWIwMWMyODp7Il9hdXRoX3VzZXJfYmFja2VuZCI6ImRqYW5nby5jb250cmliLmF1dGguYmFja2VuZHMuTW9kZWxCYWNrZW5kIiwiX2F1dGhfdXNlcl9pZCI6Ijk4YzkyOWJlLTE5ZmItNDU5OC1iMzAyLTMzZGQxZGRiZmNmZCIsIl9hdXRoX3VzZXJfaGFzaCI6Ijg3ZmM3NWRhMjRkYWVjMjdmMGUxMTc5ODYxMzYyYzFhMDliZWI2YTEifQ==', '2016-11-11 00:01:09.183575', 'puz9kr6ghi9hv6saesho10jss8jv9ih3')
[2016-10-27 18:01:09] DEBUG [django.db.backends:89] (0.000) INSERT INTO "django_session" ("session_key", "session_data", "expire_date") SELECT 'puz9kr6ghi9hv6saesho10jss8jv9ih3', 'MzkyMmQzMGY3NmQzY2Q4YTJkNjE1MGFjY2Y1YjViMzU0ZWIwMWMyODp7Il9hdXRoX3VzZXJfYmFja2VuZCI6ImRqYW5nby5jb250cmliLmF1dGguYmFja2VuZHMuTW9kZWxCYWNrZW5kIiwiX2F1dGhfdXNlcl9pZCI6Ijk4YzkyOWJlLTE5ZmItNDU5OC1iMzAyLTMzZGQxZGRiZmNmZCIsIl9hdXRoX3VzZXJfaGFzaCI6Ijg3ZmM3NWRhMjRkYWVjMjdmMGUxMTc5ODYxMzYyYzFhMDliZWI2YTEifQ==', '2016-11-11 00:01:09.183575'; args=('puz9kr6ghi9hv6saesho10jss8jv9ih3', 'MzkyMmQzMGY3NmQzY2Q4YTJkNjE1MGFjY2Y1YjViMzU0ZWIwMWMyODp7Il9hdXRoX3VzZXJfYmFja2VuZCI6ImRqYW5nby5jb250cmliLmF1dGguYmFja2VuZHMuTW9kZWxCYWNrZW5kIiwiX2F1dGhfdXNlcl9pZCI6Ijk4YzkyOWJlLTE5ZmItNDU5OC1iMzAyLTMzZGQxZGRiZmNmZCIsIl9hdXRoX3VzZXJfaGFzaCI6Ijg3ZmM3NWRhMjRkYWVjMjdmMGUxMTc5ODYxMzYyYzFhMDliZWI2YTEifQ==', '2016-11-11 00:01:09.183575')
[2016-10-27 18:01:09] DEBUG [django.db.backends:89] (0.004) SELECT "django_session"."session_key", "django_session"."session_data", "django_session"."expire_date" FROM "django_session" WHERE ("django_session"."expire_date" > '2016-10-28 00:01:09.297314' AND "django_session"."session_key" = 'puz9kr6ghi9hv6saesho10jss8jv9ih3'); args=('2016-10-28 00:01:09.297314', 'puz9kr6ghi9hv6saesho10jss8jv9ih3')
[2016-10-27 18:01:09] DEBUG [django.db.backends:89] (0.004) SELECT "auths_user"."password", "auths_user"."last_login", "auths_user"."is_superuser", "auths_user"."username", "auths_user"."first_name", "auths_user"."last_name", "auths_user"."email", "auths_user"."is_staff", "auths_user"."is_active", "auths_user"."date_joined", "auths_user"."id", "auths_user"."last_hierarchy_id", "auths_user"."last_module_id", "auths_user"."person_id", "auths_user"."updated_at", "auths_user"."registered_by" FROM "auths_user" WHERE "auths_user"."id" = '98c929be19fb4598b30233dd1ddbfcfd'; args=('98c929be19fb4598b30233dd1ddbfcfd',)
[2016-10-27 18:01:09] DEBUG [django.template:927] Exception while resolving variable 'is_popup' in template 'admin/index.html'.
Traceback (most recent call last):
  File "E:\cursotaller\initial_vemo
\ve_vemo
\lib\site-packages\django\template\base.py", line 883, in _resolve_lookup
    current = current[bit]
  File "E:\cursotaller\initial_vemo
\ve_vemo
\lib\site-packages\django\template\context.py", line 77, in __getitem__
    raise KeyError(key)
KeyError: 'is_popup'

During handling of the above exception, another exception occurred:

Traceback (most recent call last):
  File "E:\cursotaller\initial_vemo
\ve_vemo
\lib\site-packages\django\template\base.py", line 889, in _resolve_lookup
    if isinstance(current, BaseContext) and getattr(type(current), bit):
AttributeError: type object 'RequestContext' has no attribute 'is_popup'

During handling of the above exception, another exception occurred:

Traceback (most recent call last):
  File "E:\cursotaller\initial_vemo
\ve_vemo
\lib\site-packages\django\template\base.py", line 898, in _resolve_lookup
    current = current[int(bit)]
ValueError: invalid literal for int() with base 10: 'is_popup'

During handling of the above exception, another exception occurred:

Traceback (most recent call last):
  File "E:\cursotaller\initial_vemo
\ve_vemo
\lib\site-packages\django\template\base.py", line 905, in _resolve_lookup
    (bit, current))  # missing attribute
django.template.base.VariableDoesNotExist: Failed lookup for key [is_popup] in "[{'None': None, 'False': False, 'True': True}, {'csrf_token': <SimpleLazyObject: <function csrf.<locals>._get_val at 0x04A4E4B0>>, 'messages': <django.contrib.messages.storage.fallback.FallbackStorage object at 0x04A0BEB0>, 'request': <WSGIRequest: GET '/admin/'>, 'perms': <django.contrib.auth.context_processors.PermWrapper object at 0x04A24B90>, 'user': <SimpleLazyObject: <User: admin>>, 'DEFAULT_MESSAGE_LEVELS': {'WARNING': 30, 'SUCCESS': 25, 'DEBUG': 10, 'INFO': 20, 'ERROR': 40}}, {}, {'LANGUAGE_CODE': 'en-us', 'available_apps': [{'app_url': '/admin/auth/', 'has_module_perms': True, 'app_label': 'auth', 'name': <django.utils.functional.lazy.<locals>.__proxy__ object at 0x03D09030>, 'models': [{'perms': {'add': True, 'change': True, 'delete': True}, 'add_url': '/admin/auth/group/add/', 'admin_url': '/admin/auth/group/', 'name': <django.utils.functional.lazy.<locals>.__proxy__ object at 0x04A1FD30>, 'object_name': 'Group'}, {'perms': {'add': True, 'change': True, 'delete': True}, 'add_url': '/admin/auth/permission/add/', 'admin_url': '/admin/auth/permission/', 'name': <django.utils.functional.lazy.<locals>.__proxy__ object at 0x04A0BE70>, 'object_name': 'Permission'}]}, {'app_url': '/admin/auths/', 'has_module_perms': True, 'app_label': 'auths', 'name': 'Auths', 'models': [{'perms': {'add': True, 'change': True, 'delete': True}, 'add_url': '/admin/auths/hierarchytype/add/', 'admin_url': '/admin/auths/hierarchytype/', 'name': <django.utils.functional.lazy.<locals>.__proxy__ object at 0x04A0BCF0>, 'object_name': 'HierarchyType'}, {'perms': {'add': True, 'change': True, 'delete': True}, 'add_url': '/admin/auths/hierarchy/add/', 'admin_url': '/admin/auths/hierarchy/', 'name': <django.utils.functional.lazy.<locals>.__proxy__ object at 0x04A1F530>, 'object_name': 'Hierarchy'}, {'perms': {'add': True, 'change': True, 'delete': True}, 'add_url': '/admin/auths/menu/add/', 'admin_url': '/admin/auths/menu/', 'name': <django.utils.functional.lazy.<locals>.__proxy__ object at 0x04A0BFB0>, 'object_name': 'Menu'}, {'perms': {'add': True, 'change': True, 'delete': True}, 'add_url': '/admin/auths/person/add/', 'admin_url': '/admin/auths/person/', 'name': <django.utils.functional.lazy.<locals>.__proxy__ object at 0x04A0BBB0>, 'object_name': 'Person'}, {'perms': {'add': True, 'change': True, 'delete': True}, 'add_url': '/admin/auths/userhierarchygroup/add/', 'admin_url': '/admin/auths/userhierarchygroup/', 'name': <django.utils.functional.lazy.<locals>.__proxy__ object at 0x04A0BCB0>, 'object_name': 'UserHierarchyGroup'}, {'perms': {'add': True, 'change': True, 'delete': True}, 'add_url': '/admin/auths/userhierarchypermission/add/', 'admin_url': '/admin/auths/userhierarchypermission/', 'name': <django.utils.functional.lazy.<locals>.__proxy__ object at 0x04A0BC90>, 'object_name': 'UserHierarchyPermission'}, {'perms': {'add': True, 'change': True, 'delete': True}, 'add_url': '/admin/auths/user/add/', 'admin_url': '/admin/auths/user/', 'name': <django.utils.functional.lazy.<locals>.__proxy__ object at 0x04963430>, 'object_name': 'User'}]}, {'app_url': '/admin/catalogo/', 'has_module_perms': True, 'app_label': 'catalogo', 'name': 'Catalogo', 'models': [{'perms': {'add': True, 'change': True, 'delete': True}, 'add_url': '/admin/catalogo/autor/add/', 'admin_url': '/admin/catalogo/autor/', 'name': 'Autores', 'object_name': 'Autor'}, {'perms': {'add': True, 'change': True, 'delete': True}, 'add_url': '/admin/catalogo/categoria/add/', 'admin_url': '/admin/catalogo/categoria/', 'name': 'Categorias', 'object_name': 'Categoria'}, {'perms': {'add': True, 'change': True, 'delete': True}, 'add_url': '/admin/catalogo/libro/add/', 'admin_url': '/admin/catalogo/libro/', 'name': 'Libros', 'object_name': 'Libro'}]}, {'app_url': '/admin/contenttypes/', 'has_module_perms': True, 'app_label': 'contenttypes', 'name': <django.utils.functional.lazy.<locals>.__proxy__ object at 0x03D09070>, 'models': [{'perms': {'add': True, 'change': True, 'delete': True}, 'add_url': '/admin/contenttypes/contenttype/add/', 'admin_url': '/admin/contenttypes/contenttype/', 'name': <django.utils.functional.lazy.<locals>.__proxy__ object at 0x04A0BF30>, 'object_name': 'ContentType'}]}, {'app_url': '/admin/oauth2_provider/', 'has_module_perms': True, 'app_label': 'oauth2_provider', 'name': 'Django OAuth Toolkit', 'models': [{'perms': {'add': True, 'change': True, 'delete': True}, 'add_url': '/admin/oauth2_provider/accesstoken/add/', 'admin_url': '/admin/oauth2_provider/accesstoken/', 'name': <django.utils.functional.lazy.<locals>.__proxy__ object at 0x04A0BE50>, 'object_name': 'AccessToken'}, {'perms': {'add': True, 'change': True, 'delete': True}, 'add_url': '/admin/oauth2_provider/application/add/', 'admin_url': '/admin/oauth2_provider/application/', 'name': <django.utils.functional.lazy.<locals>.__proxy__ object at 0x04A1F690>, 'object_name': 'Application'}, {'perms': {'add': True, 'change': True, 'delete': True}, 'add_url': '/admin/oauth2_provider/grant/add/', 'admin_url': '/admin/oauth2_provider/grant/', 'name': <django.utils.functional.lazy.<locals>.__proxy__ object at 0x04A0BCD0>, 'object_name': 'Grant'}, {'perms': {'add': True, 'change': True, 'delete': True}, 'add_url': '/admin/oauth2_provider/refreshtoken/add/', 'admin_url': '/admin/oauth2_provider/refreshtoken/', 'name': <django.utils.functional.lazy.<locals>.__proxy__ object at 0x04A1F450>, 'object_name': 'RefreshToken'}]}], 'app_list': [{'app_url': '/admin/auth/', 'has_module_perms': True, 'app_label': 'auth', 'name': <django.utils.functional.lazy.<locals>.__proxy__ object at 0x03D09030>, 'models': [{'perms': {'add': True, 'change': True, 'delete': True}, 'add_url': '/admin/auth/group/add/', 'admin_url': '/admin/auth/group/', 'name': <django.utils.functional.lazy.<locals>.__proxy__ object at 0x04A1FC70>, 'object_name': 'Group'}, {'perms': {'add': True, 'change': True, 'delete': True}, 'add_url': '/admin/auth/permission/add/', 'admin_url': '/admin/auth/permission/', 'name': <django.utils.functional.lazy.<locals>.__proxy__ object at 0x04A1F3D0>, 'object_name': 'Permission'}]}, {'app_url': '/admin/auths/', 'has_module_perms': True, 'app_label': 'auths', 'name': 'Auths', 'models': [{'perms': {'add': True, 'change': True, 'delete': True}, 'add_url': '/admin/auths/hierarchytype/add/', 'admin_url': '/admin/auths/hierarchytype/', 'name': <django.utils.functional.lazy.<locals>.__proxy__ object at 0x04A1FCF0>, 'object_name': 'HierarchyType'}, {'perms': {'add': True, 'change': True, 'delete': True}, 'add_url': '/admin/auths/hierarchy/add/', 'admin_url': '/admin/auths/hierarchy/', 'name': <django.utils.functional.lazy.<locals>.__proxy__ object at 0x04A1F410>, 'object_name': 'Hierarchy'}, {'perms': {'add': True, 'change': True, 'delete': True}, 'add_url': '/admin/auths/menu/add/', 'admin_url': '/admin/auths/menu/', 'name': <django.utils.functional.lazy.<locals>.__proxy__ object at 0x04A1FDF0>, 'object_name': 'Menu'}, {'perms': {'add': True, 'change': True, 'delete': True}, 'add_url': '/admin/auths/person/add/', 'admin_url': '/admin/auths/person/', 'name': <django.utils.functional.lazy.<locals>.__proxy__ object at 0x04A1FBB0>, 'object_name': 'Person'}, {'perms': {'add': True, 'change': True, 'delete': True}, 'add_url': '/admin/auths/userhierarchygroup/add/', 'admin_url': '/admin/auths/userhierarchygroup/', 'name': <django.utils.functional.lazy.<locals>.__proxy__ object at 0x04A1FD50>, 'object_name': 'UserHierarchyGroup'}, {'perms': {'add': True, 'change': True, 'delete': True}, 'add_url': '/admin/auths/userhierarchypermission/add/', 'admin_url': '/admin/auths/userhierarchypermission/', 'name': <django.utils.functional.lazy.<locals>.__proxy__ object at 0x04A1F7F0>, 'object_name': 'UserHierarchyPermission'}, {'perms': {'add': True, 'change': True, 'delete': True}, 'add_url': '/admin/auths/user/add/', 'admin_url': '/admin/auths/user/', 'name': <django.utils.functional.lazy.<locals>.__proxy__ object at 0x04A1F350>, 'object_name': 'User'}]}, {'app_url': '/admin/catalogo/', 'has_module_perms': True, 'app_label': 'catalogo', 'name': 'Catalogo', 'models': [{'perms': {'add': True, 'change': True, 'delete': True}, 'add_url': '/admin/catalogo/autor/add/', 'admin_url': '/admin/catalogo/autor/', 'name': 'Autores', 'object_name': 'Autor'}, {'perms': {'add': True, 'change': True, 'delete': True}, 'add_url': '/admin/catalogo/categoria/add/', 'admin_url': '/admin/catalogo/categoria/', 'name': 'Categorias', 'object_name': 'Categoria'}, {'perms': {'add': True, 'change': True, 'delete': True}, 'add_url': '/admin/catalogo/libro/add/', 'admin_url': '/admin/catalogo/libro/', 'name': 'Libros', 'object_name': 'Libro'}]}, {'app_url': '/admin/contenttypes/', 'has_module_perms': True, 'app_label': 'contenttypes', 'name': <django.utils.functional.lazy.<locals>.__proxy__ object at 0x03D09070>, 'models': [{'perms': {'add': True, 'change': True, 'delete': True}, 'add_url': '/admin/contenttypes/contenttype/add/', 'admin_url': '/admin/contenttypes/contenttype/', 'name': <django.utils.functional.lazy.<locals>.__proxy__ object at 0x04A1F890>, 'object_name': 'ContentType'}]}, {'app_url': '/admin/oauth2_provider/', 'has_module_perms': True, 'app_label': 'oauth2_provider', 'name': 'Django OAuth Toolkit', 'models': [{'perms': {'add': True, 'change': True, 'delete': True}, 'add_url': '/admin/oauth2_provider/accesstoken/add/', 'admin_url': '/admin/oauth2_provider/accesstoken/', 'name': <django.utils.functional.lazy.<locals>.__proxy__ object at 0x04A1F850>, 'object_name': 'AccessToken'}, {'perms': {'add': True, 'change': True, 'delete': True}, 'add_url': '/admin/oauth2_provider/application/add/', 'admin_url': '/admin/oauth2_provider/application/', 'name': <django.utils.functional.lazy.<locals>.__proxy__ object at 0x04E639D0>, 'object_name': 'Application'}, {'perms': {'add': True, 'change': True, 'delete': True}, 'add_url': '/admin/oauth2_provider/grant/add/', 'admin_url': '/admin/oauth2_provider/grant/', 'name': <django.utils.functional.lazy.<locals>.__proxy__ object at 0x04A1F0D0>, 'object_name': 'Grant'}, {'perms': {'add': True, 'change': True, 'delete': True}, 'add_url': '/admin/oauth2_provider/refreshtoken/add/', 'admin_url': '/admin/oauth2_provider/refreshtoken/', 'name': <django.utils.functional.lazy.<locals>.__proxy__ object at 0x04E63970>, 'object_name': 'RefreshToken'}]}], 'LANGUAGE_BIDI': False, 'title': <django.utils.functional.lazy.<locals>.__proxy__ object at 0x03CFFAF0>, 'site_title': <django.utils.functional.lazy.<locals>.__proxy__ object at 0x03CFF9F0>, 'site_url': '/', 'has_permission': True, 'site_header': <django.utils.functional.lazy.<locals>.__proxy__ object at 0x03CFFAB0>}]"
[2016-10-27 18:01:09] DEBUG [django.template:927] Exception while resolving variable 'is_popup' in template 'admin/index.html'.
Traceback (most recent call last):
  File "E:\cursotaller\initial_vemo
\ve_vemo
\lib\site-packages\django\template\base.py", line 883, in _resolve_lookup
    current = current[bit]
  File "E:\cursotaller\initial_vemo
\ve_vemo
\lib\site-packages\django\template\context.py", line 77, in __getitem__
    raise KeyError(key)
KeyError: 'is_popup'

During handling of the above exception, another exception occurred:

Traceback (most recent call last):
  File "E:\cursotaller\initial_vemo
\ve_vemo
\lib\site-packages\django\template\base.py", line 889, in _resolve_lookup
    if isinstance(current, BaseContext) and getattr(type(current), bit):
AttributeError: type object 'RequestContext' has no attribute 'is_popup'

During handling of the above exception, another exception occurred:

Traceback (most recent call last):
  File "E:\cursotaller\initial_vemo
\ve_vemo
\lib\site-packages\django\template\base.py", line 898, in _resolve_lookup
    current = current[int(bit)]
ValueError: invalid literal for int() with base 10: 'is_popup'

During handling of the above exception, another exception occurred:

Traceback (most recent call last):
  File "E:\cursotaller\initial_vemo
\ve_vemo
\lib\site-packages\django\template\base.py", line 905, in _resolve_lookup
    (bit, current))  # missing attribute
django.template.base.VariableDoesNotExist: Failed lookup for key [is_popup] in "[{'None': None, 'False': False, 'True': True}, {'csrf_token': <SimpleLazyObject: <function csrf.<locals>._get_val at 0x04A4E4B0>>, 'messages': <django.contrib.messages.storage.fallback.FallbackStorage object at 0x04A0BEB0>, 'request': <WSGIRequest: GET '/admin/'>, 'perms': <django.contrib.auth.context_processors.PermWrapper object at 0x04A24B90>, 'user': <SimpleLazyObject: <User: admin>>, 'DEFAULT_MESSAGE_LEVELS': {'WARNING': 30, 'SUCCESS': 25, 'DEBUG': 10, 'INFO': 20, 'ERROR': 40}}, {}, {'LANGUAGE_CODE': 'en-us', 'available_apps': [{'app_url': '/admin/auth/', 'has_module_perms': True, 'app_label': 'auth', 'name': <django.utils.functional.lazy.<locals>.__proxy__ object at 0x03D09030>, 'models': [{'perms': {'add': True, 'change': True, 'delete': True}, 'add_url': '/admin/auth/group/add/', 'admin_url': '/admin/auth/group/', 'name': <django.utils.functional.lazy.<locals>.__proxy__ object at 0x04A1FD30>, 'object_name': 'Group'}, {'perms': {'add': True, 'change': True, 'delete': True}, 'add_url': '/admin/auth/permission/add/', 'admin_url': '/admin/auth/permission/', 'name': <django.utils.functional.lazy.<locals>.__proxy__ object at 0x04A0BE70>, 'object_name': 'Permission'}]}, {'app_url': '/admin/auths/', 'has_module_perms': True, 'app_label': 'auths', 'name': 'Auths', 'models': [{'perms': {'add': True, 'change': True, 'delete': True}, 'add_url': '/admin/auths/hierarchytype/add/', 'admin_url': '/admin/auths/hierarchytype/', 'name': <django.utils.functional.lazy.<locals>.__proxy__ object at 0x04A0BCF0>, 'object_name': 'HierarchyType'}, {'perms': {'add': True, 'change': True, 'delete': True}, 'add_url': '/admin/auths/hierarchy/add/', 'admin_url': '/admin/auths/hierarchy/', 'name': <django.utils.functional.lazy.<locals>.__proxy__ object at 0x04A1F530>, 'object_name': 'Hierarchy'}, {'perms': {'add': True, 'change': True, 'delete': True}, 'add_url': '/admin/auths/menu/add/', 'admin_url': '/admin/auths/menu/', 'name': <django.utils.functional.lazy.<locals>.__proxy__ object at 0x04A0BFB0>, 'object_name': 'Menu'}, {'perms': {'add': True, 'change': True, 'delete': True}, 'add_url': '/admin/auths/person/add/', 'admin_url': '/admin/auths/person/', 'name': <django.utils.functional.lazy.<locals>.__proxy__ object at 0x04A0BBB0>, 'object_name': 'Person'}, {'perms': {'add': True, 'change': True, 'delete': True}, 'add_url': '/admin/auths/userhierarchygroup/add/', 'admin_url': '/admin/auths/userhierarchygroup/', 'name': <django.utils.functional.lazy.<locals>.__proxy__ object at 0x04A0BCB0>, 'object_name': 'UserHierarchyGroup'}, {'perms': {'add': True, 'change': True, 'delete': True}, 'add_url': '/admin/auths/userhierarchypermission/add/', 'admin_url': '/admin/auths/userhierarchypermission/', 'name': <django.utils.functional.lazy.<locals>.__proxy__ object at 0x04A0BC90>, 'object_name': 'UserHierarchyPermission'}, {'perms': {'add': True, 'change': True, 'delete': True}, 'add_url': '/admin/auths/user/add/', 'admin_url': '/admin/auths/user/', 'name': <django.utils.functional.lazy.<locals>.__proxy__ object at 0x04963430>, 'object_name': 'User'}]}, {'app_url': '/admin/catalogo/', 'has_module_perms': True, 'app_label': 'catalogo', 'name': 'Catalogo', 'models': [{'perms': {'add': True, 'change': True, 'delete': True}, 'add_url': '/admin/catalogo/autor/add/', 'admin_url': '/admin/catalogo/autor/', 'name': 'Autores', 'object_name': 'Autor'}, {'perms': {'add': True, 'change': True, 'delete': True}, 'add_url': '/admin/catalogo/categoria/add/', 'admin_url': '/admin/catalogo/categoria/', 'name': 'Categorias', 'object_name': 'Categoria'}, {'perms': {'add': True, 'change': True, 'delete': True}, 'add_url': '/admin/catalogo/libro/add/', 'admin_url': '/admin/catalogo/libro/', 'name': 'Libros', 'object_name': 'Libro'}]}, {'app_url': '/admin/contenttypes/', 'has_module_perms': True, 'app_label': 'contenttypes', 'name': <django.utils.functional.lazy.<locals>.__proxy__ object at 0x03D09070>, 'models': [{'perms': {'add': True, 'change': True, 'delete': True}, 'add_url': '/admin/contenttypes/contenttype/add/', 'admin_url': '/admin/contenttypes/contenttype/', 'name': <django.utils.functional.lazy.<locals>.__proxy__ object at 0x04A0BF30>, 'object_name': 'ContentType'}]}, {'app_url': '/admin/oauth2_provider/', 'has_module_perms': True, 'app_label': 'oauth2_provider', 'name': 'Django OAuth Toolkit', 'models': [{'perms': {'add': True, 'change': True, 'delete': True}, 'add_url': '/admin/oauth2_provider/accesstoken/add/', 'admin_url': '/admin/oauth2_provider/accesstoken/', 'name': <django.utils.functional.lazy.<locals>.__proxy__ object at 0x04A0BE50>, 'object_name': 'AccessToken'}, {'perms': {'add': True, 'change': True, 'delete': True}, 'add_url': '/admin/oauth2_provider/application/add/', 'admin_url': '/admin/oauth2_provider/application/', 'name': <django.utils.functional.lazy.<locals>.__proxy__ object at 0x04A1F690>, 'object_name': 'Application'}, {'perms': {'add': True, 'change': True, 'delete': True}, 'add_url': '/admin/oauth2_provider/grant/add/', 'admin_url': '/admin/oauth2_provider/grant/', 'name': <django.utils.functional.lazy.<locals>.__proxy__ object at 0x04A0BCD0>, 'object_name': 'Grant'}, {'perms': {'add': True, 'change': True, 'delete': True}, 'add_url': '/admin/oauth2_provider/refreshtoken/add/', 'admin_url': '/admin/oauth2_provider/refreshtoken/', 'name': <django.utils.functional.lazy.<locals>.__proxy__ object at 0x04A1F450>, 'object_name': 'RefreshToken'}]}], 'app_list': [{'app_url': '/admin/auth/', 'has_module_perms': True, 'app_label': 'auth', 'name': <django.utils.functional.lazy.<locals>.__proxy__ object at 0x03D09030>, 'models': [{'perms': {'add': True, 'change': True, 'delete': True}, 'add_url': '/admin/auth/group/add/', 'admin_url': '/admin/auth/group/', 'name': <django.utils.functional.lazy.<locals>.__proxy__ object at 0x04A1FC70>, 'object_name': 'Group'}, {'perms': {'add': True, 'change': True, 'delete': True}, 'add_url': '/admin/auth/permission/add/', 'admin_url': '/admin/auth/permission/', 'name': <django.utils.functional.lazy.<locals>.__proxy__ object at 0x04A1F3D0>, 'object_name': 'Permission'}]}, {'app_url': '/admin/auths/', 'has_module_perms': True, 'app_label': 'auths', 'name': 'Auths', 'models': [{'perms': {'add': True, 'change': True, 'delete': True}, 'add_url': '/admin/auths/hierarchytype/add/', 'admin_url': '/admin/auths/hierarchytype/', 'name': <django.utils.functional.lazy.<locals>.__proxy__ object at 0x04A1FCF0>, 'object_name': 'HierarchyType'}, {'perms': {'add': True, 'change': True, 'delete': True}, 'add_url': '/admin/auths/hierarchy/add/', 'admin_url': '/admin/auths/hierarchy/', 'name': <django.utils.functional.lazy.<locals>.__proxy__ object at 0x04A1F410>, 'object_name': 'Hierarchy'}, {'perms': {'add': True, 'change': True, 'delete': True}, 'add_url': '/admin/auths/menu/add/', 'admin_url': '/admin/auths/menu/', 'name': <django.utils.functional.lazy.<locals>.__proxy__ object at 0x04A1FDF0>, 'object_name': 'Menu'}, {'perms': {'add': True, 'change': True, 'delete': True}, 'add_url': '/admin/auths/person/add/', 'admin_url': '/admin/auths/person/', 'name': <django.utils.functional.lazy.<locals>.__proxy__ object at 0x04A1FBB0>, 'object_name': 'Person'}, {'perms': {'add': True, 'change': True, 'delete': True}, 'add_url': '/admin/auths/userhierarchygroup/add/', 'admin_url': '/admin/auths/userhierarchygroup/', 'name': <django.utils.functional.lazy.<locals>.__proxy__ object at 0x04A1FD50>, 'object_name': 'UserHierarchyGroup'}, {'perms': {'add': True, 'change': True, 'delete': True}, 'add_url': '/admin/auths/userhierarchypermission/add/', 'admin_url': '/admin/auths/userhierarchypermission/', 'name': <django.utils.functional.lazy.<locals>.__proxy__ object at 0x04A1F7F0>, 'object_name': 'UserHierarchyPermission'}, {'perms': {'add': True, 'change': True, 'delete': True}, 'add_url': '/admin/auths/user/add/', 'admin_url': '/admin/auths/user/', 'name': <django.utils.functional.lazy.<locals>.__proxy__ object at 0x04A1F350>, 'object_name': 'User'}]}, {'app_url': '/admin/catalogo/', 'has_module_perms': True, 'app_label': 'catalogo', 'name': 'Catalogo', 'models': [{'perms': {'add': True, 'change': True, 'delete': True}, 'add_url': '/admin/catalogo/autor/add/', 'admin_url': '/admin/catalogo/autor/', 'name': 'Autores', 'object_name': 'Autor'}, {'perms': {'add': True, 'change': True, 'delete': True}, 'add_url': '/admin/catalogo/categoria/add/', 'admin_url': '/admin/catalogo/categoria/', 'name': 'Categorias', 'object_name': 'Categoria'}, {'perms': {'add': True, 'change': True, 'delete': True}, 'add_url': '/admin/catalogo/libro/add/', 'admin_url': '/admin/catalogo/libro/', 'name': 'Libros', 'object_name': 'Libro'}]}, {'app_url': '/admin/contenttypes/', 'has_module_perms': True, 'app_label': 'contenttypes', 'name': <django.utils.functional.lazy.<locals>.__proxy__ object at 0x03D09070>, 'models': [{'perms': {'add': True, 'change': True, 'delete': True}, 'add_url': '/admin/contenttypes/contenttype/add/', 'admin_url': '/admin/contenttypes/contenttype/', 'name': <django.utils.functional.lazy.<locals>.__proxy__ object at 0x04A1F890>, 'object_name': 'ContentType'}]}, {'app_url': '/admin/oauth2_provider/', 'has_module_perms': True, 'app_label': 'oauth2_provider', 'name': 'Django OAuth Toolkit', 'models': [{'perms': {'add': True, 'change': True, 'delete': True}, 'add_url': '/admin/oauth2_provider/accesstoken/add/', 'admin_url': '/admin/oauth2_provider/accesstoken/', 'name': <django.utils.functional.lazy.<locals>.__proxy__ object at 0x04A1F850>, 'object_name': 'AccessToken'}, {'perms': {'add': True, 'change': True, 'delete': True}, 'add_url': '/admin/oauth2_provider/application/add/', 'admin_url': '/admin/oauth2_provider/application/', 'name': <django.utils.functional.lazy.<locals>.__proxy__ object at 0x04E639D0>, 'object_name': 'Application'}, {'perms': {'add': True, 'change': True, 'delete': True}, 'add_url': '/admin/oauth2_provider/grant/add/', 'admin_url': '/admin/oauth2_provider/grant/', 'name': <django.utils.functional.lazy.<locals>.__proxy__ object at 0x04A1F0D0>, 'object_name': 'Grant'}, {'perms': {'add': True, 'change': True, 'delete': True}, 'add_url': '/admin/oauth2_provider/refreshtoken/add/', 'admin_url': '/admin/oauth2_provider/refreshtoken/', 'name': <django.utils.functional.lazy.<locals>.__proxy__ object at 0x04E63970>, 'object_name': 'RefreshToken'}]}], 'LANGUAGE_BIDI': False, 'title': <django.utils.functional.lazy.<locals>.__proxy__ object at 0x03CFFAF0>, 'site_title': <django.utils.functional.lazy.<locals>.__proxy__ object at 0x03CFF9F0>, 'site_url': '/', 'has_permission': True, 'site_header': <django.utils.functional.lazy.<locals>.__proxy__ object at 0x03CFFAB0>}]"
[2016-10-27 18:01:09] DEBUG [django.db.backends:89] (0.004) SELECT "django_admin_log"."id", "django_admin_log"."action_time", "django_admin_log"."user_id", "django_admin_log"."content_type_id", "django_admin_log"."object_id", "django_admin_log"."object_repr", "django_admin_log"."action_flag", "django_admin_log"."change_message", "auths_user"."password", "auths_user"."last_login", "auths_user"."is_superuser", "auths_user"."username", "auths_user"."first_name", "auths_user"."last_name", "auths_user"."email", "auths_user"."is_staff", "auths_user"."is_active", "auths_user"."date_joined", "auths_user"."id", "auths_user"."last_hierarchy_id", "auths_user"."last_module_id", "auths_user"."person_id", "auths_user"."updated_at", "auths_user"."registered_by", "django_content_type"."id", "django_content_type"."app_label", "django_content_type"."model" FROM "django_admin_log" INNER JOIN "auths_user" ON ("django_admin_log"."user_id" = "auths_user"."id") LEFT OUTER JOIN "django_content_type" ON ("django_admin_log"."content_type_id" = "django_content_type"."id") WHERE "django_admin_log"."user_id" = '98c929be19fb4598b30233dd1ddbfcfd' ORDER BY "django_admin_log"."action_time" DESC LIMIT 10; args=('98c929be19fb4598b30233dd1ddbfcfd',)
[2016-10-27 18:03:51] WARNING [django.request:182] Not Found: /
[2016-10-27 18:03:51] DEBUG [django.template:927] Exception while resolving variable 'name' in template 'unknown'.
Traceback (most recent call last):
  File "E:\cursotaller\initial_vemo
\ve_vemo
\lib\site-packages\django\core\handlers\base.py", line 134, in get_response
    resolver_match = resolver.resolve(request.path_info)
  File "E:\cursotaller\initial_vemo
\ve_vemo
\lib\site-packages\django\core\urlresolvers.py", line 404, in resolve
    raise Resolver404({'tried': tried, 'path': new_path})
django.core.urlresolvers.Resolver404: {'path': '', 'tried': [[<RegexURLResolver <RegexURLPattern list> (admin:admin) ^admin/>], [<RegexURLResolver <module 'django.contrib.admindocs.urls' from 'E:\\cursotaller\\initial_vemo
\\ve_vemo
\\lib\\site-packages\\django\\contrib\\admindocs\\urls.py'> (None:None) ^admin/doc/>], [<RegexURLResolver <module 'rest_framework.urls' from 'E:\\cursotaller\\initial_vemo
\\ve_vemo
\\lib\\site-packages\\rest_framework\\urls.py'> (rest_framework:rest_framework) ^api-auth/>], [<RegexURLResolver <module 'oauth2_provider.urls' from 'E:\\cursotaller\\initial_vemo
\\ve_vemo
\\lib\\site-packages\\oauth2_provider\\urls.py'> (None:oauth2_provider) ^o/>], [<RegexURLResolver <module 'vemo
_service_apps.auths_api.urls' from 'E:\\cursotaller\\initial_vemo
\\vemo
_service\\vemo
_service_apps\\auths_api\\urls.py'> (None:None) ^api/auths/>], [<RegexURLResolver <module 'vemo
_service_apps.catalogo_api.urls' from 'E:\\cursotaller\\initial_vemo
\\vemo
_service\\vemo
_service_apps\\catalogo_api\\urls.py'> (None:None) ^api/catalogo/>]]}

During handling of the above exception, another exception occurred:

Traceback (most recent call last):
  File "E:\cursotaller\initial_vemo
\ve_vemo
\lib\site-packages\django\template\base.py", line 883, in _resolve_lookup
    current = current[bit]
TypeError: 'RegexURLResolver' object is not subscriptable

During handling of the above exception, another exception occurred:

Traceback (most recent call last):
  File "E:\cursotaller\initial_vemo
\ve_vemo
\lib\site-packages\django\template\base.py", line 891, in _resolve_lookup
    current = getattr(current, bit)
AttributeError: 'RegexURLResolver' object has no attribute 'name'

During handling of the above exception, another exception occurred:

Traceback (most recent call last):
  File "E:\cursotaller\initial_vemo
\ve_vemo
\lib\site-packages\django\template\base.py", line 898, in _resolve_lookup
    current = current[int(bit)]
ValueError: invalid literal for int() with base 10: 'name'

During handling of the above exception, another exception occurred:

Traceback (most recent call last):
  File "E:\cursotaller\initial_vemo
\ve_vemo
\lib\site-packages\django\template\base.py", line 905, in _resolve_lookup
    (bit, current))  # missing attribute
django.template.base.VariableDoesNotExist: Failed lookup for key [name] in '<RegexURLResolver <RegexURLPattern list> (admin:admin) ^admin/>'
[2016-10-27 18:03:51] DEBUG [django.template:927] Exception while resolving variable 'name' in template 'unknown'.
Traceback (most recent call last):
  File "E:\cursotaller\initial_vemo
\ve_vemo
\lib\site-packages\django\core\handlers\base.py", line 134, in get_response
    resolver_match = resolver.resolve(request.path_info)
  File "E:\cursotaller\initial_vemo
\ve_vemo
\lib\site-packages\django\core\urlresolvers.py", line 404, in resolve
    raise Resolver404({'tried': tried, 'path': new_path})
django.core.urlresolvers.Resolver404: {'path': '', 'tried': [[<RegexURLResolver <RegexURLPattern list> (admin:admin) ^admin/>], [<RegexURLResolver <module 'django.contrib.admindocs.urls' from 'E:\\cursotaller\\initial_vemo
\\ve_vemo
\\lib\\site-packages\\django\\contrib\\admindocs\\urls.py'> (None:None) ^admin/doc/>], [<RegexURLResolver <module 'rest_framework.urls' from 'E:\\cursotaller\\initial_vemo
\\ve_vemo
\\lib\\site-packages\\rest_framework\\urls.py'> (rest_framework:rest_framework) ^api-auth/>], [<RegexURLResolver <module 'oauth2_provider.urls' from 'E:\\cursotaller\\initial_vemo
\\ve_vemo
\\lib\\site-packages\\oauth2_provider\\urls.py'> (None:oauth2_provider) ^o/>], [<RegexURLResolver <module 'vemo
_service_apps.auths_api.urls' from 'E:\\cursotaller\\initial_vemo
\\vemo
_service\\vemo
_service_apps\\auths_api\\urls.py'> (None:None) ^api/auths/>], [<RegexURLResolver <module 'vemo
_service_apps.catalogo_api.urls' from 'E:\\cursotaller\\initial_vemo
\\vemo
_service\\vemo
_service_apps\\catalogo_api\\urls.py'> (None:None) ^api/catalogo/>]]}

During handling of the above exception, another exception occurred:

Traceback (most recent call last):
  File "E:\cursotaller\initial_vemo
\ve_vemo
\lib\site-packages\django\template\base.py", line 883, in _resolve_lookup
    current = current[bit]
TypeError: 'RegexURLResolver' object is not subscriptable

During handling of the above exception, another exception occurred:

Traceback (most recent call last):
  File "E:\cursotaller\initial_vemo
\ve_vemo
\lib\site-packages\django\template\base.py", line 891, in _resolve_lookup
    current = getattr(current, bit)
AttributeError: 'RegexURLResolver' object has no attribute 'name'

During handling of the above exception, another exception occurred:

Traceback (most recent call last):
  File "E:\cursotaller\initial_vemo
\ve_vemo
\lib\site-packages\django\template\base.py", line 898, in _resolve_lookup
    current = current[int(bit)]
ValueError: invalid literal for int() with base 10: 'name'

During handling of the above exception, another exception occurred:

Traceback (most recent call last):
  File "E:\cursotaller\initial_vemo
\ve_vemo
\lib\site-packages\django\template\base.py", line 905, in _resolve_lookup
    (bit, current))  # missing attribute
django.template.base.VariableDoesNotExist: Failed lookup for key [name] in "<RegexURLResolver <module 'django.contrib.admindocs.urls' from 'E:\\\\cursotaller\\\\initial_vemo
\\\\ve_vemo
\\\\lib\\\\site-packages\\\\django\\\\contrib\\\\admindocs\\\\urls.py'> (None:None) ^admin/doc/>"
[2016-10-27 18:03:51] DEBUG [django.template:927] Exception while resolving variable 'name' in template 'unknown'.
Traceback (most recent call last):
  File "E:\cursotaller\initial_vemo
\ve_vemo
\lib\site-packages\django\core\handlers\base.py", line 134, in get_response
    resolver_match = resolver.resolve(request.path_info)
  File "E:\cursotaller\initial_vemo
\ve_vemo
\lib\site-packages\django\core\urlresolvers.py", line 404, in resolve
    raise Resolver404({'tried': tried, 'path': new_path})
django.core.urlresolvers.Resolver404: {'path': '', 'tried': [[<RegexURLResolver <RegexURLPattern list> (admin:admin) ^admin/>], [<RegexURLResolver <module 'django.contrib.admindocs.urls' from 'E:\\cursotaller\\initial_vemo
\\ve_vemo
\\lib\\site-packages\\django\\contrib\\admindocs\\urls.py'> (None:None) ^admin/doc/>], [<RegexURLResolver <module 'rest_framework.urls' from 'E:\\cursotaller\\initial_vemo
\\ve_vemo
\\lib\\site-packages\\rest_framework\\urls.py'> (rest_framework:rest_framework) ^api-auth/>], [<RegexURLResolver <module 'oauth2_provider.urls' from 'E:\\cursotaller\\initial_vemo
\\ve_vemo
\\lib\\site-packages\\oauth2_provider\\urls.py'> (None:oauth2_provider) ^o/>], [<RegexURLResolver <module 'vemo
_service_apps.auths_api.urls' from 'E:\\cursotaller\\initial_vemo
\\vemo
_service\\vemo
_service_apps\\auths_api\\urls.py'> (None:None) ^api/auths/>], [<RegexURLResolver <module 'vemo
_service_apps.catalogo_api.urls' from 'E:\\cursotaller\\initial_vemo
\\vemo
_service\\vemo
_service_apps\\catalogo_api\\urls.py'> (None:None) ^api/catalogo/>]]}

During handling of the above exception, another exception occurred:

Traceback (most recent call last):
  File "E:\cursotaller\initial_vemo
\ve_vemo
\lib\site-packages\django\template\base.py", line 883, in _resolve_lookup
    current = current[bit]
TypeError: 'RegexURLResolver' object is not subscriptable

During handling of the above exception, another exception occurred:

Traceback (most recent call last):
  File "E:\cursotaller\initial_vemo
\ve_vemo
\lib\site-packages\django\template\base.py", line 891, in _resolve_lookup
    current = getattr(current, bit)
AttributeError: 'RegexURLResolver' object has no attribute 'name'

During handling of the above exception, another exception occurred:

Traceback (most recent call last):
  File "E:\cursotaller\initial_vemo
\ve_vemo
\lib\site-packages\django\template\base.py", line 898, in _resolve_lookup
    current = current[int(bit)]
ValueError: invalid literal for int() with base 10: 'name'

During handling of the above exception, another exception occurred:

Traceback (most recent call last):
  File "E:\cursotaller\initial_vemo
\ve_vemo
\lib\site-packages\django\template\base.py", line 905, in _resolve_lookup
    (bit, current))  # missing attribute
django.template.base.VariableDoesNotExist: Failed lookup for key [name] in "<RegexURLResolver <module 'rest_framework.urls' from 'E:\\\\cursotaller\\\\initial_vemo
\\\\ve_vemo
\\\\lib\\\\site-packages\\\\rest_framework\\\\urls.py'> (rest_framework:rest_framework) ^api-auth/>"
[2016-10-27 18:03:51] DEBUG [django.template:927] Exception while resolving variable 'name' in template 'unknown'.
Traceback (most recent call last):
  File "E:\cursotaller\initial_vemo
\ve_vemo
\lib\site-packages\django\core\handlers\base.py", line 134, in get_response
    resolver_match = resolver.resolve(request.path_info)
  File "E:\cursotaller\initial_vemo
\ve_vemo
\lib\site-packages\django\core\urlresolvers.py", line 404, in resolve
    raise Resolver404({'tried': tried, 'path': new_path})
django.core.urlresolvers.Resolver404: {'path': '', 'tried': [[<RegexURLResolver <RegexURLPattern list> (admin:admin) ^admin/>], [<RegexURLResolver <module 'django.contrib.admindocs.urls' from 'E:\\cursotaller\\initial_vemo
\\ve_vemo
\\lib\\site-packages\\django\\contrib\\admindocs\\urls.py'> (None:None) ^admin/doc/>], [<RegexURLResolver <module 'rest_framework.urls' from 'E:\\cursotaller\\initial_vemo
\\ve_vemo
\\lib\\site-packages\\rest_framework\\urls.py'> (rest_framework:rest_framework) ^api-auth/>], [<RegexURLResolver <module 'oauth2_provider.urls' from 'E:\\cursotaller\\initial_vemo
\\ve_vemo
\\lib\\site-packages\\oauth2_provider\\urls.py'> (None:oauth2_provider) ^o/>], [<RegexURLResolver <module 'vemo
_service_apps.auths_api.urls' from 'E:\\cursotaller\\initial_vemo
\\vemo
_service\\vemo
_service_apps\\auths_api\\urls.py'> (None:None) ^api/auths/>], [<RegexURLResolver <module 'vemo
_service_apps.catalogo_api.urls' from 'E:\\cursotaller\\initial_vemo
\\vemo
_service\\vemo
_service_apps\\catalogo_api\\urls.py'> (None:None) ^api/catalogo/>]]}

During handling of the above exception, another exception occurred:

Traceback (most recent call last):
  File "E:\cursotaller\initial_vemo
\ve_vemo
\lib\site-packages\django\template\base.py", line 883, in _resolve_lookup
    current = current[bit]
TypeError: 'RegexURLResolver' object is not subscriptable

During handling of the above exception, another exception occurred:

Traceback (most recent call last):
  File "E:\cursotaller\initial_vemo
\ve_vemo
\lib\site-packages\django\template\base.py", line 891, in _resolve_lookup
    current = getattr(current, bit)
AttributeError: 'RegexURLResolver' object has no attribute 'name'

During handling of the above exception, another exception occurred:

Traceback (most recent call last):
  File "E:\cursotaller\initial_vemo
\ve_vemo
\lib\site-packages\django\template\base.py", line 898, in _resolve_lookup
    current = current[int(bit)]
ValueError: invalid literal for int() with base 10: 'name'

During handling of the above exception, another exception occurred:

Traceback (most recent call last):
  File "E:\cursotaller\initial_vemo
\ve_vemo
\lib\site-packages\django\template\base.py", line 905, in _resolve_lookup
    (bit, current))  # missing attribute
django.template.base.VariableDoesNotExist: Failed lookup for key [name] in "<RegexURLResolver <module 'oauth2_provider.urls' from 'E:\\\\cursotaller\\\\initial_vemo
\\\\ve_vemo
\\\\lib\\\\site-packages\\\\oauth2_provider\\\\urls.py'> (None:oauth2_provider) ^o/>"
[2016-10-27 18:03:51] DEBUG [django.template:927] Exception while resolving variable 'name' in template 'unknown'.
Traceback (most recent call last):
  File "E:\cursotaller\initial_vemo
\ve_vemo
\lib\site-packages\django\core\handlers\base.py", line 134, in get_response
    resolver_match = resolver.resolve(request.path_info)
  File "E:\cursotaller\initial_vemo
\ve_vemo
\lib\site-packages\django\core\urlresolvers.py", line 404, in resolve
    raise Resolver404({'tried': tried, 'path': new_path})
django.core.urlresolvers.Resolver404: {'path': '', 'tried': [[<RegexURLResolver <RegexURLPattern list> (admin:admin) ^admin/>], [<RegexURLResolver <module 'django.contrib.admindocs.urls' from 'E:\\cursotaller\\initial_vemo
\\ve_vemo
\\lib\\site-packages\\django\\contrib\\admindocs\\urls.py'> (None:None) ^admin/doc/>], [<RegexURLResolver <module 'rest_framework.urls' from 'E:\\cursotaller\\initial_vemo
\\ve_vemo
\\lib\\site-packages\\rest_framework\\urls.py'> (rest_framework:rest_framework) ^api-auth/>], [<RegexURLResolver <module 'oauth2_provider.urls' from 'E:\\cursotaller\\initial_vemo
\\ve_vemo
\\lib\\site-packages\\oauth2_provider\\urls.py'> (None:oauth2_provider) ^o/>], [<RegexURLResolver <module 'vemo
_service_apps.auths_api.urls' from 'E:\\cursotaller\\initial_vemo
\\vemo
_service\\vemo
_service_apps\\auths_api\\urls.py'> (None:None) ^api/auths/>], [<RegexURLResolver <module 'vemo
_service_apps.catalogo_api.urls' from 'E:\\cursotaller\\initial_vemo
\\vemo
_service\\vemo
_service_apps\\catalogo_api\\urls.py'> (None:None) ^api/catalogo/>]]}

During handling of the above exception, another exception occurred:

Traceback (most recent call last):
  File "E:\cursotaller\initial_vemo
\ve_vemo
\lib\site-packages\django\template\base.py", line 883, in _resolve_lookup
    current = current[bit]
TypeError: 'RegexURLResolver' object is not subscriptable

During handling of the above exception, another exception occurred:

Traceback (most recent call last):
  File "E:\cursotaller\initial_vemo
\ve_vemo
\lib\site-packages\django\template\base.py", line 891, in _resolve_lookup
    current = getattr(current, bit)
AttributeError: 'RegexURLResolver' object has no attribute 'name'

During handling of the above exception, another exception occurred:

Traceback (most recent call last):
  File "E:\cursotaller\initial_vemo
\ve_vemo
\lib\site-packages\django\template\base.py", line 898, in _resolve_lookup
    current = current[int(bit)]
ValueError: invalid literal for int() with base 10: 'name'

During handling of the above exception, another exception occurred:

Traceback (most recent call last):
  File "E:\cursotaller\initial_vemo
\ve_vemo
\lib\site-packages\django\template\base.py", line 905, in _resolve_lookup
    (bit, current))  # missing attribute
django.template.base.VariableDoesNotExist: Failed lookup for key [name] in "<RegexURLResolver <module 'vemo
_service_apps.auths_api.urls' from 'E:\\\\cursotaller\\\\initial_vemo
\\\\vemo
_service\\\\vemo
_service_apps\\\\auths_api\\\\urls.py'> (None:None) ^api/auths/>"
[2016-10-27 18:03:51] DEBUG [django.template:927] Exception while resolving variable 'name' in template 'unknown'.
Traceback (most recent call last):
  File "E:\cursotaller\initial_vemo
\ve_vemo
\lib\site-packages\django\core\handlers\base.py", line 134, in get_response
    resolver_match = resolver.resolve(request.path_info)
  File "E:\cursotaller\initial_vemo
\ve_vemo
\lib\site-packages\django\core\urlresolvers.py", line 404, in resolve
    raise Resolver404({'tried': tried, 'path': new_path})
django.core.urlresolvers.Resolver404: {'path': '', 'tried': [[<RegexURLResolver <RegexURLPattern list> (admin:admin) ^admin/>], [<RegexURLResolver <module 'django.contrib.admindocs.urls' from 'E:\\cursotaller\\initial_vemo
\\ve_vemo
\\lib\\site-packages\\django\\contrib\\admindocs\\urls.py'> (None:None) ^admin/doc/>], [<RegexURLResolver <module 'rest_framework.urls' from 'E:\\cursotaller\\initial_vemo
\\ve_vemo
\\lib\\site-packages\\rest_framework\\urls.py'> (rest_framework:rest_framework) ^api-auth/>], [<RegexURLResolver <module 'oauth2_provider.urls' from 'E:\\cursotaller\\initial_vemo
\\ve_vemo
\\lib\\site-packages\\oauth2_provider\\urls.py'> (None:oauth2_provider) ^o/>], [<RegexURLResolver <module 'vemo
_service_apps.auths_api.urls' from 'E:\\cursotaller\\initial_vemo
\\vemo
_service\\vemo
_service_apps\\auths_api\\urls.py'> (None:None) ^api/auths/>], [<RegexURLResolver <module 'vemo
_service_apps.catalogo_api.urls' from 'E:\\cursotaller\\initial_vemo
\\vemo
_service\\vemo
_service_apps\\catalogo_api\\urls.py'> (None:None) ^api/catalogo/>]]}

During handling of the above exception, another exception occurred:

Traceback (most recent call last):
  File "E:\cursotaller\initial_vemo
\ve_vemo
\lib\site-packages\django\template\base.py", line 883, in _resolve_lookup
    current = current[bit]
TypeError: 'RegexURLResolver' object is not subscriptable

During handling of the above exception, another exception occurred:

Traceback (most recent call last):
  File "E:\cursotaller\initial_vemo
\ve_vemo
\lib\site-packages\django\template\base.py", line 891, in _resolve_lookup
    current = getattr(current, bit)
AttributeError: 'RegexURLResolver' object has no attribute 'name'

During handling of the above exception, another exception occurred:

Traceback (most recent call last):
  File "E:\cursotaller\initial_vemo
\ve_vemo
\lib\site-packages\django\template\base.py", line 898, in _resolve_lookup
    current = current[int(bit)]
ValueError: invalid literal for int() with base 10: 'name'

During handling of the above exception, another exception occurred:

Traceback (most recent call last):
  File "E:\cursotaller\initial_vemo
\ve_vemo
\lib\site-packages\django\template\base.py", line 905, in _resolve_lookup
    (bit, current))  # missing attribute
django.template.base.VariableDoesNotExist: Failed lookup for key [name] in "<RegexURLResolver <module 'vemo
_service_apps.catalogo_api.urls' from 'E:\\\\cursotaller\\\\initial_vemo
\\\\vemo
_service\\\\vemo
_service_apps\\\\catalogo_api\\\\urls.py'> (None:None) ^api/catalogo/>"
[2016-10-27 18:03:51] WARNING [django.request:182] Not Found: /favicon.ico
[2016-10-27 18:03:51] DEBUG [django.template:927] Exception while resolving variable 'name' in template 'unknown'.
Traceback (most recent call last):
  File "E:\cursotaller\initial_vemo
\ve_vemo
\lib\site-packages\django\core\handlers\base.py", line 134, in get_response
    resolver_match = resolver.resolve(request.path_info)
  File "E:\cursotaller\initial_vemo
\ve_vemo
\lib\site-packages\django\core\urlresolvers.py", line 404, in resolve
    raise Resolver404({'tried': tried, 'path': new_path})
django.core.urlresolvers.Resolver404: {'path': 'favicon.ico', 'tried': [[<RegexURLResolver <RegexURLPattern list> (admin:admin) ^admin/>], [<RegexURLResolver <module 'django.contrib.admindocs.urls' from 'E:\\cursotaller\\initial_vemo
\\ve_vemo
\\lib\\site-packages\\django\\contrib\\admindocs\\urls.py'> (None:None) ^admin/doc/>], [<RegexURLResolver <module 'rest_framework.urls' from 'E:\\cursotaller\\initial_vemo
\\ve_vemo
\\lib\\site-packages\\rest_framework\\urls.py'> (rest_framework:rest_framework) ^api-auth/>], [<RegexURLResolver <module 'oauth2_provider.urls' from 'E:\\cursotaller\\initial_vemo
\\ve_vemo
\\lib\\site-packages\\oauth2_provider\\urls.py'> (None:oauth2_provider) ^o/>], [<RegexURLResolver <module 'vemo
_service_apps.auths_api.urls' from 'E:\\cursotaller\\initial_vemo
\\vemo
_service\\vemo
_service_apps\\auths_api\\urls.py'> (None:None) ^api/auths/>], [<RegexURLResolver <module 'vemo
_service_apps.catalogo_api.urls' from 'E:\\cursotaller\\initial_vemo
\\vemo
_service\\vemo
_service_apps\\catalogo_api\\urls.py'> (None:None) ^api/catalogo/>]]}

During handling of the above exception, another exception occurred:

Traceback (most recent call last):
  File "E:\cursotaller\initial_vemo
\ve_vemo
\lib\site-packages\django\template\base.py", line 883, in _resolve_lookup
    current = current[bit]
TypeError: 'RegexURLResolver' object is not subscriptable

During handling of the above exception, another exception occurred:

Traceback (most recent call last):
  File "E:\cursotaller\initial_vemo
\ve_vemo
\lib\site-packages\django\template\base.py", line 891, in _resolve_lookup
    current = getattr(current, bit)
AttributeError: 'RegexURLResolver' object has no attribute 'name'

During handling of the above exception, another exception occurred:

Traceback (most recent call last):
  File "E:\cursotaller\initial_vemo
\ve_vemo
\lib\site-packages\django\template\base.py", line 898, in _resolve_lookup
    current = current[int(bit)]
ValueError: invalid literal for int() with base 10: 'name'

During handling of the above exception, another exception occurred:

Traceback (most recent call last):
  File "E:\cursotaller\initial_vemo
\ve_vemo
\lib\site-packages\django\template\base.py", line 905, in _resolve_lookup
    (bit, current))  # missing attribute
django.template.base.VariableDoesNotExist: Failed lookup for key [name] in '<RegexURLResolver <RegexURLPattern list> (admin:admin) ^admin/>'
[2016-10-27 18:03:51] DEBUG [django.template:927] Exception while resolving variable 'name' in template 'unknown'.
Traceback (most recent call last):
  File "E:\cursotaller\initial_vemo
\ve_vemo
\lib\site-packages\django\core\handlers\base.py", line 134, in get_response
    resolver_match = resolver.resolve(request.path_info)
  File "E:\cursotaller\initial_vemo
\ve_vemo
\lib\site-packages\django\core\urlresolvers.py", line 404, in resolve
    raise Resolver404({'tried': tried, 'path': new_path})
django.core.urlresolvers.Resolver404: {'path': 'favicon.ico', 'tried': [[<RegexURLResolver <RegexURLPattern list> (admin:admin) ^admin/>], [<RegexURLResolver <module 'django.contrib.admindocs.urls' from 'E:\\cursotaller\\initial_vemo
\\ve_vemo
\\lib\\site-packages\\django\\contrib\\admindocs\\urls.py'> (None:None) ^admin/doc/>], [<RegexURLResolver <module 'rest_framework.urls' from 'E:\\cursotaller\\initial_vemo
\\ve_vemo
\\lib\\site-packages\\rest_framework\\urls.py'> (rest_framework:rest_framework) ^api-auth/>], [<RegexURLResolver <module 'oauth2_provider.urls' from 'E:\\cursotaller\\initial_vemo
\\ve_vemo
\\lib\\site-packages\\oauth2_provider\\urls.py'> (None:oauth2_provider) ^o/>], [<RegexURLResolver <module 'vemo
_service_apps.auths_api.urls' from 'E:\\cursotaller\\initial_vemo
\\vemo
_service\\vemo
_service_apps\\auths_api\\urls.py'> (None:None) ^api/auths/>], [<RegexURLResolver <module 'vemo
_service_apps.catalogo_api.urls' from 'E:\\cursotaller\\initial_vemo
\\vemo
_service\\vemo
_service_apps\\catalogo_api\\urls.py'> (None:None) ^api/catalogo/>]]}

During handling of the above exception, another exception occurred:

Traceback (most recent call last):
  File "E:\cursotaller\initial_vemo
\ve_vemo
\lib\site-packages\django\template\base.py", line 883, in _resolve_lookup
    current = current[bit]
TypeError: 'RegexURLResolver' object is not subscriptable

During handling of the above exception, another exception occurred:

Traceback (most recent call last):
  File "E:\cursotaller\initial_vemo
\ve_vemo
\lib\site-packages\django\template\base.py", line 891, in _resolve_lookup
    current = getattr(current, bit)
AttributeError: 'RegexURLResolver' object has no attribute 'name'

During handling of the above exception, another exception occurred:

Traceback (most recent call last):
  File "E:\cursotaller\initial_vemo
\ve_vemo
\lib\site-packages\django\template\base.py", line 898, in _resolve_lookup
    current = current[int(bit)]
ValueError: invalid literal for int() with base 10: 'name'

During handling of the above exception, another exception occurred:

Traceback (most recent call last):
  File "E:\cursotaller\initial_vemo
\ve_vemo
\lib\site-packages\django\template\base.py", line 905, in _resolve_lookup
    (bit, current))  # missing attribute
django.template.base.VariableDoesNotExist: Failed lookup for key [name] in "<RegexURLResolver <module 'django.contrib.admindocs.urls' from 'E:\\\\cursotaller\\\\initial_vemo
\\\\ve_vemo
\\\\lib\\\\site-packages\\\\django\\\\contrib\\\\admindocs\\\\urls.py'> (None:None) ^admin/doc/>"
[2016-10-27 18:03:51] DEBUG [django.template:927] Exception while resolving variable 'name' in template 'unknown'.
Traceback (most recent call last):
  File "E:\cursotaller\initial_vemo
\ve_vemo
\lib\site-packages\django\core\handlers\base.py", line 134, in get_response
    resolver_match = resolver.resolve(request.path_info)
  File "E:\cursotaller\initial_vemo
\ve_vemo
\lib\site-packages\django\core\urlresolvers.py", line 404, in resolve
    raise Resolver404({'tried': tried, 'path': new_path})
django.core.urlresolvers.Resolver404: {'path': 'favicon.ico', 'tried': [[<RegexURLResolver <RegexURLPattern list> (admin:admin) ^admin/>], [<RegexURLResolver <module 'django.contrib.admindocs.urls' from 'E:\\cursotaller\\initial_vemo
\\ve_vemo
\\lib\\site-packages\\django\\contrib\\admindocs\\urls.py'> (None:None) ^admin/doc/>], [<RegexURLResolver <module 'rest_framework.urls' from 'E:\\cursotaller\\initial_vemo
\\ve_vemo
\\lib\\site-packages\\rest_framework\\urls.py'> (rest_framework:rest_framework) ^api-auth/>], [<RegexURLResolver <module 'oauth2_provider.urls' from 'E:\\cursotaller\\initial_vemo
\\ve_vemo
\\lib\\site-packages\\oauth2_provider\\urls.py'> (None:oauth2_provider) ^o/>], [<RegexURLResolver <module 'vemo
_service_apps.auths_api.urls' from 'E:\\cursotaller\\initial_vemo
\\vemo
_service\\vemo
_service_apps\\auths_api\\urls.py'> (None:None) ^api/auths/>], [<RegexURLResolver <module 'vemo
_service_apps.catalogo_api.urls' from 'E:\\cursotaller\\initial_vemo
\\vemo
_service\\vemo
_service_apps\\catalogo_api\\urls.py'> (None:None) ^api/catalogo/>]]}

During handling of the above exception, another exception occurred:

Traceback (most recent call last):
  File "E:\cursotaller\initial_vemo
\ve_vemo
\lib\site-packages\django\template\base.py", line 883, in _resolve_lookup
    current = current[bit]
TypeError: 'RegexURLResolver' object is not subscriptable

During handling of the above exception, another exception occurred:

Traceback (most recent call last):
  File "E:\cursotaller\initial_vemo
\ve_vemo
\lib\site-packages\django\template\base.py", line 891, in _resolve_lookup
    current = getattr(current, bit)
AttributeError: 'RegexURLResolver' object has no attribute 'name'

During handling of the above exception, another exception occurred:

Traceback (most recent call last):
  File "E:\cursotaller\initial_vemo
\ve_vemo
\lib\site-packages\django\template\base.py", line 898, in _resolve_lookup
    current = current[int(bit)]
ValueError: invalid literal for int() with base 10: 'name'

During handling of the above exception, another exception occurred:

Traceback (most recent call last):
  File "E:\cursotaller\initial_vemo
\ve_vemo
\lib\site-packages\django\template\base.py", line 905, in _resolve_lookup
    (bit, current))  # missing attribute
django.template.base.VariableDoesNotExist: Failed lookup for key [name] in "<RegexURLResolver <module 'rest_framework.urls' from 'E:\\\\cursotaller\\\\initial_vemo
\\\\ve_vemo
\\\\lib\\\\site-packages\\\\rest_framework\\\\urls.py'> (rest_framework:rest_framework) ^api-auth/>"
[2016-10-27 18:03:51] DEBUG [django.template:927] Exception while resolving variable 'name' in template 'unknown'.
Traceback (most recent call last):
  File "E:\cursotaller\initial_vemo
\ve_vemo
\lib\site-packages\django\core\handlers\base.py", line 134, in get_response
    resolver_match = resolver.resolve(request.path_info)
  File "E:\cursotaller\initial_vemo
\ve_vemo
\lib\site-packages\django\core\urlresolvers.py", line 404, in resolve
    raise Resolver404({'tried': tried, 'path': new_path})
django.core.urlresolvers.Resolver404: {'path': 'favicon.ico', 'tried': [[<RegexURLResolver <RegexURLPattern list> (admin:admin) ^admin/>], [<RegexURLResolver <module 'django.contrib.admindocs.urls' from 'E:\\cursotaller\\initial_vemo
\\ve_vemo
\\lib\\site-packages\\django\\contrib\\admindocs\\urls.py'> (None:None) ^admin/doc/>], [<RegexURLResolver <module 'rest_framework.urls' from 'E:\\cursotaller\\initial_vemo
\\ve_vemo
\\lib\\site-packages\\rest_framework\\urls.py'> (rest_framework:rest_framework) ^api-auth/>], [<RegexURLResolver <module 'oauth2_provider.urls' from 'E:\\cursotaller\\initial_vemo
\\ve_vemo
\\lib\\site-packages\\oauth2_provider\\urls.py'> (None:oauth2_provider) ^o/>], [<RegexURLResolver <module 'vemo
_service_apps.auths_api.urls' from 'E:\\cursotaller\\initial_vemo
\\vemo
_service\\vemo
_service_apps\\auths_api\\urls.py'> (None:None) ^api/auths/>], [<RegexURLResolver <module 'vemo
_service_apps.catalogo_api.urls' from 'E:\\cursotaller\\initial_vemo
\\vemo
_service\\vemo
_service_apps\\catalogo_api\\urls.py'> (None:None) ^api/catalogo/>]]}

During handling of the above exception, another exception occurred:

Traceback (most recent call last):
  File "E:\cursotaller\initial_vemo
\ve_vemo
\lib\site-packages\django\template\base.py", line 883, in _resolve_lookup
    current = current[bit]
TypeError: 'RegexURLResolver' object is not subscriptable

During handling of the above exception, another exception occurred:

Traceback (most recent call last):
  File "E:\cursotaller\initial_vemo
\ve_vemo
\lib\site-packages\django\template\base.py", line 891, in _resolve_lookup
    current = getattr(current, bit)
AttributeError: 'RegexURLResolver' object has no attribute 'name'

During handling of the above exception, another exception occurred:

Traceback (most recent call last):
  File "E:\cursotaller\initial_vemo
\ve_vemo
\lib\site-packages\django\template\base.py", line 898, in _resolve_lookup
    current = current[int(bit)]
ValueError: invalid literal for int() with base 10: 'name'

During handling of the above exception, another exception occurred:

Traceback (most recent call last):
  File "E:\cursotaller\initial_vemo
\ve_vemo
\lib\site-packages\django\template\base.py", line 905, in _resolve_lookup
    (bit, current))  # missing attribute
django.template.base.VariableDoesNotExist: Failed lookup for key [name] in "<RegexURLResolver <module 'oauth2_provider.urls' from 'E:\\\\cursotaller\\\\initial_vemo
\\\\ve_vemo
\\\\lib\\\\site-packages\\\\oauth2_provider\\\\urls.py'> (None:oauth2_provider) ^o/>"
[2016-10-27 18:03:51] DEBUG [django.template:927] Exception while resolving variable 'name' in template 'unknown'.
Traceback (most recent call last):
  File "E:\cursotaller\initial_vemo
\ve_vemo
\lib\site-packages\django\core\handlers\base.py", line 134, in get_response
    resolver_match = resolver.resolve(request.path_info)
  File "E:\cursotaller\initial_vemo
\ve_vemo
\lib\site-packages\django\core\urlresolvers.py", line 404, in resolve
    raise Resolver404({'tried': tried, 'path': new_path})
django.core.urlresolvers.Resolver404: {'path': 'favicon.ico', 'tried': [[<RegexURLResolver <RegexURLPattern list> (admin:admin) ^admin/>], [<RegexURLResolver <module 'django.contrib.admindocs.urls' from 'E:\\cursotaller\\initial_vemo
\\ve_vemo
\\lib\\site-packages\\django\\contrib\\admindocs\\urls.py'> (None:None) ^admin/doc/>], [<RegexURLResolver <module 'rest_framework.urls' from 'E:\\cursotaller\\initial_vemo
\\ve_vemo
\\lib\\site-packages\\rest_framework\\urls.py'> (rest_framework:rest_framework) ^api-auth/>], [<RegexURLResolver <module 'oauth2_provider.urls' from 'E:\\cursotaller\\initial_vemo
\\ve_vemo
\\lib\\site-packages\\oauth2_provider\\urls.py'> (None:oauth2_provider) ^o/>], [<RegexURLResolver <module 'vemo
_service_apps.auths_api.urls' from 'E:\\cursotaller\\initial_vemo
\\vemo
_service\\vemo
_service_apps\\auths_api\\urls.py'> (None:None) ^api/auths/>], [<RegexURLResolver <module 'vemo
_service_apps.catalogo_api.urls' from 'E:\\cursotaller\\initial_vemo
\\vemo
_service\\vemo
_service_apps\\catalogo_api\\urls.py'> (None:None) ^api/catalogo/>]]}

During handling of the above exception, another exception occurred:

Traceback (most recent call last):
  File "E:\cursotaller\initial_vemo
\ve_vemo
\lib\site-packages\django\template\base.py", line 883, in _resolve_lookup
    current = current[bit]
TypeError: 'RegexURLResolver' object is not subscriptable

During handling of the above exception, another exception occurred:

Traceback (most recent call last):
  File "E:\cursotaller\initial_vemo
\ve_vemo
\lib\site-packages\django\template\base.py", line 891, in _resolve_lookup
    current = getattr(current, bit)
AttributeError: 'RegexURLResolver' object has no attribute 'name'

During handling of the above exception, another exception occurred:

Traceback (most recent call last):
  File "E:\cursotaller\initial_vemo
\ve_vemo
\lib\site-packages\django\template\base.py", line 898, in _resolve_lookup
    current = current[int(bit)]
ValueError: invalid literal for int() with base 10: 'name'

During handling of the above exception, another exception occurred:

Traceback (most recent call last):
  File "E:\cursotaller\initial_vemo
\ve_vemo
\lib\site-packages\django\template\base.py", line 905, in _resolve_lookup
    (bit, current))  # missing attribute
django.template.base.VariableDoesNotExist: Failed lookup for key [name] in "<RegexURLResolver <module 'vemo
_service_apps.auths_api.urls' from 'E:\\\\cursotaller\\\\initial_vemo
\\\\vemo
_service\\\\vemo
_service_apps\\\\auths_api\\\\urls.py'> (None:None) ^api/auths/>"
[2016-10-27 18:03:51] DEBUG [django.template:927] Exception while resolving variable 'name' in template 'unknown'.
Traceback (most recent call last):
  File "E:\cursotaller\initial_vemo
\ve_vemo
\lib\site-packages\django\core\handlers\base.py", line 134, in get_response
    resolver_match = resolver.resolve(request.path_info)
  File "E:\cursotaller\initial_vemo
\ve_vemo
\lib\site-packages\django\core\urlresolvers.py", line 404, in resolve
    raise Resolver404({'tried': tried, 'path': new_path})
django.core.urlresolvers.Resolver404: {'path': 'favicon.ico', 'tried': [[<RegexURLResolver <RegexURLPattern list> (admin:admin) ^admin/>], [<RegexURLResolver <module 'django.contrib.admindocs.urls' from 'E:\\cursotaller\\initial_vemo
\\ve_vemo
\\lib\\site-packages\\django\\contrib\\admindocs\\urls.py'> (None:None) ^admin/doc/>], [<RegexURLResolver <module 'rest_framework.urls' from 'E:\\cursotaller\\initial_vemo
\\ve_vemo
\\lib\\site-packages\\rest_framework\\urls.py'> (rest_framework:rest_framework) ^api-auth/>], [<RegexURLResolver <module 'oauth2_provider.urls' from 'E:\\cursotaller\\initial_vemo
\\ve_vemo
\\lib\\site-packages\\oauth2_provider\\urls.py'> (None:oauth2_provider) ^o/>], [<RegexURLResolver <module 'vemo
_service_apps.auths_api.urls' from 'E:\\cursotaller\\initial_vemo
\\vemo
_service\\vemo
_service_apps\\auths_api\\urls.py'> (None:None) ^api/auths/>], [<RegexURLResolver <module 'vemo
_service_apps.catalogo_api.urls' from 'E:\\cursotaller\\initial_vemo
\\vemo
_service\\vemo
_service_apps\\catalogo_api\\urls.py'> (None:None) ^api/catalogo/>]]}

During handling of the above exception, another exception occurred:

Traceback (most recent call last):
  File "E:\cursotaller\initial_vemo
\ve_vemo
\lib\site-packages\django\template\base.py", line 883, in _resolve_lookup
    current = current[bit]
TypeError: 'RegexURLResolver' object is not subscriptable

During handling of the above exception, another exception occurred:

Traceback (most recent call last):
  File "E:\cursotaller\initial_vemo
\ve_vemo
\lib\site-packages\django\template\base.py", line 891, in _resolve_lookup
    current = getattr(current, bit)
AttributeError: 'RegexURLResolver' object has no attribute 'name'

During handling of the above exception, another exception occurred:

Traceback (most recent call last):
  File "E:\cursotaller\initial_vemo
\ve_vemo
\lib\site-packages\django\template\base.py", line 898, in _resolve_lookup
    current = current[int(bit)]
ValueError: invalid literal for int() with base 10: 'name'

During handling of the above exception, another exception occurred:

Traceback (most recent call last):
  File "E:\cursotaller\initial_vemo
\ve_vemo
\lib\site-packages\django\template\base.py", line 905, in _resolve_lookup
    (bit, current))  # missing attribute
django.template.base.VariableDoesNotExist: Failed lookup for key [name] in "<RegexURLResolver <module 'vemo
_service_apps.catalogo_api.urls' from 'E:\\\\cursotaller\\\\initial_vemo
\\\\vemo
_service\\\\vemo
_service_apps\\\\catalogo_api\\\\urls.py'> (None:None) ^api/catalogo/>"
[2016-10-27 18:04:16] WARNING [django.request:182] Not Found: /vemo
_web
[2016-10-27 18:04:16] DEBUG [django.template:927] Exception while resolving variable 'name' in template 'unknown'.
Traceback (most recent call last):
  File "E:\cursotaller\initial_vemo
\ve_vemo
\lib\site-packages\django\core\handlers\base.py", line 134, in get_response
    resolver_match = resolver.resolve(request.path_info)
  File "E:\cursotaller\initial_vemo
\ve_vemo
\lib\site-packages\django\core\urlresolvers.py", line 404, in resolve
    raise Resolver404({'tried': tried, 'path': new_path})
django.core.urlresolvers.Resolver404: {'path': 'vemo
_web', 'tried': [[<RegexURLResolver <RegexURLPattern list> (admin:admin) ^admin/>], [<RegexURLResolver <module 'django.contrib.admindocs.urls' from 'E:\\cursotaller\\initial_vemo
\\ve_vemo
\\lib\\site-packages\\django\\contrib\\admindocs\\urls.py'> (None:None) ^admin/doc/>], [<RegexURLResolver <module 'rest_framework.urls' from 'E:\\cursotaller\\initial_vemo
\\ve_vemo
\\lib\\site-packages\\rest_framework\\urls.py'> (rest_framework:rest_framework) ^api-auth/>], [<RegexURLResolver <module 'oauth2_provider.urls' from 'E:\\cursotaller\\initial_vemo
\\ve_vemo
\\lib\\site-packages\\oauth2_provider\\urls.py'> (None:oauth2_provider) ^o/>], [<RegexURLResolver <module 'vemo
_service_apps.auths_api.urls' from 'E:\\cursotaller\\initial_vemo
\\vemo
_service\\vemo
_service_apps\\auths_api\\urls.py'> (None:None) ^api/auths/>], [<RegexURLResolver <module 'vemo
_service_apps.catalogo_api.urls' from 'E:\\cursotaller\\initial_vemo
\\vemo
_service\\vemo
_service_apps\\catalogo_api\\urls.py'> (None:None) ^api/catalogo/>]]}

During handling of the above exception, another exception occurred:

Traceback (most recent call last):
  File "E:\cursotaller\initial_vemo
\ve_vemo
\lib\site-packages\django\template\base.py", line 883, in _resolve_lookup
    current = current[bit]
TypeError: 'RegexURLResolver' object is not subscriptable

During handling of the above exception, another exception occurred:

Traceback (most recent call last):
  File "E:\cursotaller\initial_vemo
\ve_vemo
\lib\site-packages\django\template\base.py", line 891, in _resolve_lookup
    current = getattr(current, bit)
AttributeError: 'RegexURLResolver' object has no attribute 'name'

During handling of the above exception, another exception occurred:

Traceback (most recent call last):
  File "E:\cursotaller\initial_vemo
\ve_vemo
\lib\site-packages\django\template\base.py", line 898, in _resolve_lookup
    current = current[int(bit)]
ValueError: invalid literal for int() with base 10: 'name'

During handling of the above exception, another exception occurred:

Traceback (most recent call last):
  File "E:\cursotaller\initial_vemo
\ve_vemo
\lib\site-packages\django\template\base.py", line 905, in _resolve_lookup
    (bit, current))  # missing attribute
django.template.base.VariableDoesNotExist: Failed lookup for key [name] in '<RegexURLResolver <RegexURLPattern list> (admin:admin) ^admin/>'
[2016-10-27 18:04:16] DEBUG [django.template:927] Exception while resolving variable 'name' in template 'unknown'.
Traceback (most recent call last):
  File "E:\cursotaller\initial_vemo
\ve_vemo
\lib\site-packages\django\core\handlers\base.py", line 134, in get_response
    resolver_match = resolver.resolve(request.path_info)
  File "E:\cursotaller\initial_vemo
\ve_vemo
\lib\site-packages\django\core\urlresolvers.py", line 404, in resolve
    raise Resolver404({'tried': tried, 'path': new_path})
django.core.urlresolvers.Resolver404: {'path': 'vemo
_web', 'tried': [[<RegexURLResolver <RegexURLPattern list> (admin:admin) ^admin/>], [<RegexURLResolver <module 'django.contrib.admindocs.urls' from 'E:\\cursotaller\\initial_vemo
\\ve_vemo
\\lib\\site-packages\\django\\contrib\\admindocs\\urls.py'> (None:None) ^admin/doc/>], [<RegexURLResolver <module 'rest_framework.urls' from 'E:\\cursotaller\\initial_vemo
\\ve_vemo
\\lib\\site-packages\\rest_framework\\urls.py'> (rest_framework:rest_framework) ^api-auth/>], [<RegexURLResolver <module 'oauth2_provider.urls' from 'E:\\cursotaller\\initial_vemo
\\ve_vemo
\\lib\\site-packages\\oauth2_provider\\urls.py'> (None:oauth2_provider) ^o/>], [<RegexURLResolver <module 'vemo
_service_apps.auths_api.urls' from 'E:\\cursotaller\\initial_vemo
\\vemo
_service\\vemo
_service_apps\\auths_api\\urls.py'> (None:None) ^api/auths/>], [<RegexURLResolver <module 'vemo
_service_apps.catalogo_api.urls' from 'E:\\cursotaller\\initial_vemo
\\vemo
_service\\vemo
_service_apps\\catalogo_api\\urls.py'> (None:None) ^api/catalogo/>]]}

During handling of the above exception, another exception occurred:

Traceback (most recent call last):
  File "E:\cursotaller\initial_vemo
\ve_vemo
\lib\site-packages\django\template\base.py", line 883, in _resolve_lookup
    current = current[bit]
TypeError: 'RegexURLResolver' object is not subscriptable

During handling of the above exception, another exception occurred:

Traceback (most recent call last):
  File "E:\cursotaller\initial_vemo
\ve_vemo
\lib\site-packages\django\template\base.py", line 891, in _resolve_lookup
    current = getattr(current, bit)
AttributeError: 'RegexURLResolver' object has no attribute 'name'

During handling of the above exception, another exception occurred:

Traceback (most recent call last):
  File "E:\cursotaller\initial_vemo
\ve_vemo
\lib\site-packages\django\template\base.py", line 898, in _resolve_lookup
    current = current[int(bit)]
ValueError: invalid literal for int() with base 10: 'name'

During handling of the above exception, another exception occurred:

Traceback (most recent call last):
  File "E:\cursotaller\initial_vemo
\ve_vemo
\lib\site-packages\django\template\base.py", line 905, in _resolve_lookup
    (bit, current))  # missing attribute
django.template.base.VariableDoesNotExist: Failed lookup for key [name] in "<RegexURLResolver <module 'django.contrib.admindocs.urls' from 'E:\\\\cursotaller\\\\initial_vemo
\\\\ve_vemo
\\\\lib\\\\site-packages\\\\django\\\\contrib\\\\admindocs\\\\urls.py'> (None:None) ^admin/doc/>"
[2016-10-27 18:04:16] DEBUG [django.template:927] Exception while resolving variable 'name' in template 'unknown'.
Traceback (most recent call last):
  File "E:\cursotaller\initial_vemo
\ve_vemo
\lib\site-packages\django\core\handlers\base.py", line 134, in get_response
    resolver_match = resolver.resolve(request.path_info)
  File "E:\cursotaller\initial_vemo
\ve_vemo
\lib\site-packages\django\core\urlresolvers.py", line 404, in resolve
    raise Resolver404({'tried': tried, 'path': new_path})
django.core.urlresolvers.Resolver404: {'path': 'vemo
_web', 'tried': [[<RegexURLResolver <RegexURLPattern list> (admin:admin) ^admin/>], [<RegexURLResolver <module 'django.contrib.admindocs.urls' from 'E:\\cursotaller\\initial_vemo
\\ve_vemo
\\lib\\site-packages\\django\\contrib\\admindocs\\urls.py'> (None:None) ^admin/doc/>], [<RegexURLResolver <module 'rest_framework.urls' from 'E:\\cursotaller\\initial_vemo
\\ve_vemo
\\lib\\site-packages\\rest_framework\\urls.py'> (rest_framework:rest_framework) ^api-auth/>], [<RegexURLResolver <module 'oauth2_provider.urls' from 'E:\\cursotaller\\initial_vemo
\\ve_vemo
\\lib\\site-packages\\oauth2_provider\\urls.py'> (None:oauth2_provider) ^o/>], [<RegexURLResolver <module 'vemo
_service_apps.auths_api.urls' from 'E:\\cursotaller\\initial_vemo
\\vemo
_service\\vemo
_service_apps\\auths_api\\urls.py'> (None:None) ^api/auths/>], [<RegexURLResolver <module 'vemo
_service_apps.catalogo_api.urls' from 'E:\\cursotaller\\initial_vemo
\\vemo
_service\\vemo
_service_apps\\catalogo_api\\urls.py'> (None:None) ^api/catalogo/>]]}

During handling of the above exception, another exception occurred:

Traceback (most recent call last):
  File "E:\cursotaller\initial_vemo
\ve_vemo
\lib\site-packages\django\template\base.py", line 883, in _resolve_lookup
    current = current[bit]
TypeError: 'RegexURLResolver' object is not subscriptable

During handling of the above exception, another exception occurred:

Traceback (most recent call last):
  File "E:\cursotaller\initial_vemo
\ve_vemo
\lib\site-packages\django\template\base.py", line 891, in _resolve_lookup
    current = getattr(current, bit)
AttributeError: 'RegexURLResolver' object has no attribute 'name'

During handling of the above exception, another exception occurred:

Traceback (most recent call last):
  File "E:\cursotaller\initial_vemo
\ve_vemo
\lib\site-packages\django\template\base.py", line 898, in _resolve_lookup
    current = current[int(bit)]
ValueError: invalid literal for int() with base 10: 'name'

During handling of the above exception, another exception occurred:

Traceback (most recent call last):
  File "E:\cursotaller\initial_vemo
\ve_vemo
\lib\site-packages\django\template\base.py", line 905, in _resolve_lookup
    (bit, current))  # missing attribute
django.template.base.VariableDoesNotExist: Failed lookup for key [name] in "<RegexURLResolver <module 'rest_framework.urls' from 'E:\\\\cursotaller\\\\initial_vemo
\\\\ve_vemo
\\\\lib\\\\site-packages\\\\rest_framework\\\\urls.py'> (rest_framework:rest_framework) ^api-auth/>"
[2016-10-27 18:04:16] DEBUG [django.template:927] Exception while resolving variable 'name' in template 'unknown'.
Traceback (most recent call last):
  File "E:\cursotaller\initial_vemo
\ve_vemo
\lib\site-packages\django\core\handlers\base.py", line 134, in get_response
    resolver_match = resolver.resolve(request.path_info)
  File "E:\cursotaller\initial_vemo
\ve_vemo
\lib\site-packages\django\core\urlresolvers.py", line 404, in resolve
    raise Resolver404({'tried': tried, 'path': new_path})
django.core.urlresolvers.Resolver404: {'path': 'vemo
_web', 'tried': [[<RegexURLResolver <RegexURLPattern list> (admin:admin) ^admin/>], [<RegexURLResolver <module 'django.contrib.admindocs.urls' from 'E:\\cursotaller\\initial_vemo
\\ve_vemo
\\lib\\site-packages\\django\\contrib\\admindocs\\urls.py'> (None:None) ^admin/doc/>], [<RegexURLResolver <module 'rest_framework.urls' from 'E:\\cursotaller\\initial_vemo
\\ve_vemo
\\lib\\site-packages\\rest_framework\\urls.py'> (rest_framework:rest_framework) ^api-auth/>], [<RegexURLResolver <module 'oauth2_provider.urls' from 'E:\\cursotaller\\initial_vemo
\\ve_vemo
\\lib\\site-packages\\oauth2_provider\\urls.py'> (None:oauth2_provider) ^o/>], [<RegexURLResolver <module 'vemo
_service_apps.auths_api.urls' from 'E:\\cursotaller\\initial_vemo
\\vemo
_service\\vemo
_service_apps\\auths_api\\urls.py'> (None:None) ^api/auths/>], [<RegexURLResolver <module 'vemo
_service_apps.catalogo_api.urls' from 'E:\\cursotaller\\initial_vemo
\\vemo
_service\\vemo
_service_apps\\catalogo_api\\urls.py'> (None:None) ^api/catalogo/>]]}

During handling of the above exception, another exception occurred:

Traceback (most recent call last):
  File "E:\cursotaller\initial_vemo
\ve_vemo
\lib\site-packages\django\template\base.py", line 883, in _resolve_lookup
    current = current[bit]
TypeError: 'RegexURLResolver' object is not subscriptable

During handling of the above exception, another exception occurred:

Traceback (most recent call last):
  File "E:\cursotaller\initial_vemo
\ve_vemo
\lib\site-packages\django\template\base.py", line 891, in _resolve_lookup
    current = getattr(current, bit)
AttributeError: 'RegexURLResolver' object has no attribute 'name'

During handling of the above exception, another exception occurred:

Traceback (most recent call last):
  File "E:\cursotaller\initial_vemo
\ve_vemo
\lib\site-packages\django\template\base.py", line 898, in _resolve_lookup
    current = current[int(bit)]
ValueError: invalid literal for int() with base 10: 'name'

During handling of the above exception, another exception occurred:

Traceback (most recent call last):
  File "E:\cursotaller\initial_vemo
\ve_vemo
\lib\site-packages\django\template\base.py", line 905, in _resolve_lookup
    (bit, current))  # missing attribute
django.template.base.VariableDoesNotExist: Failed lookup for key [name] in "<RegexURLResolver <module 'oauth2_provider.urls' from 'E:\\\\cursotaller\\\\initial_vemo
\\\\ve_vemo
\\\\lib\\\\site-packages\\\\oauth2_provider\\\\urls.py'> (None:oauth2_provider) ^o/>"
[2016-10-27 18:04:16] DEBUG [django.template:927] Exception while resolving variable 'name' in template 'unknown'.
Traceback (most recent call last):
  File "E:\cursotaller\initial_vemo
\ve_vemo
\lib\site-packages\django\core\handlers\base.py", line 134, in get_response
    resolver_match = resolver.resolve(request.path_info)
  File "E:\cursotaller\initial_vemo
\ve_vemo
\lib\site-packages\django\core\urlresolvers.py", line 404, in resolve
    raise Resolver404({'tried': tried, 'path': new_path})
django.core.urlresolvers.Resolver404: {'path': 'vemo
_web', 'tried': [[<RegexURLResolver <RegexURLPattern list> (admin:admin) ^admin/>], [<RegexURLResolver <module 'django.contrib.admindocs.urls' from 'E:\\cursotaller\\initial_vemo
\\ve_vemo
\\lib\\site-packages\\django\\contrib\\admindocs\\urls.py'> (None:None) ^admin/doc/>], [<RegexURLResolver <module 'rest_framework.urls' from 'E:\\cursotaller\\initial_vemo
\\ve_vemo
\\lib\\site-packages\\rest_framework\\urls.py'> (rest_framework:rest_framework) ^api-auth/>], [<RegexURLResolver <module 'oauth2_provider.urls' from 'E:\\cursotaller\\initial_vemo
\\ve_vemo
\\lib\\site-packages\\oauth2_provider\\urls.py'> (None:oauth2_provider) ^o/>], [<RegexURLResolver <module 'vemo
_service_apps.auths_api.urls' from 'E:\\cursotaller\\initial_vemo
\\vemo
_service\\vemo
_service_apps\\auths_api\\urls.py'> (None:None) ^api/auths/>], [<RegexURLResolver <module 'vemo
_service_apps.catalogo_api.urls' from 'E:\\cursotaller\\initial_vemo
\\vemo
_service\\vemo
_service_apps\\catalogo_api\\urls.py'> (None:None) ^api/catalogo/>]]}

During handling of the above exception, another exception occurred:

Traceback (most recent call last):
  File "E:\cursotaller\initial_vemo
\ve_vemo
\lib\site-packages\django\template\base.py", line 883, in _resolve_lookup
    current = current[bit]
TypeError: 'RegexURLResolver' object is not subscriptable

During handling of the above exception, another exception occurred:

Traceback (most recent call last):
  File "E:\cursotaller\initial_vemo
\ve_vemo
\lib\site-packages\django\template\base.py", line 891, in _resolve_lookup
    current = getattr(current, bit)
AttributeError: 'RegexURLResolver' object has no attribute 'name'

During handling of the above exception, another exception occurred:

Traceback (most recent call last):
  File "E:\cursotaller\initial_vemo
\ve_vemo
\lib\site-packages\django\template\base.py", line 898, in _resolve_lookup
    current = current[int(bit)]
ValueError: invalid literal for int() with base 10: 'name'

During handling of the above exception, another exception occurred:

Traceback (most recent call last):
  File "E:\cursotaller\initial_vemo
\ve_vemo
\lib\site-packages\django\template\base.py", line 905, in _resolve_lookup
    (bit, current))  # missing attribute
django.template.base.VariableDoesNotExist: Failed lookup for key [name] in "<RegexURLResolver <module 'vemo
_service_apps.auths_api.urls' from 'E:\\\\cursotaller\\\\initial_vemo
\\\\vemo
_service\\\\vemo
_service_apps\\\\auths_api\\\\urls.py'> (None:None) ^api/auths/>"
[2016-10-27 18:04:16] DEBUG [django.template:927] Exception while resolving variable 'name' in template 'unknown'.
Traceback (most recent call last):
  File "E:\cursotaller\initial_vemo
\ve_vemo
\lib\site-packages\django\core\handlers\base.py", line 134, in get_response
    resolver_match = resolver.resolve(request.path_info)
  File "E:\cursotaller\initial_vemo
\ve_vemo
\lib\site-packages\django\core\urlresolvers.py", line 404, in resolve
    raise Resolver404({'tried': tried, 'path': new_path})
django.core.urlresolvers.Resolver404: {'path': 'vemo
_web', 'tried': [[<RegexURLResolver <RegexURLPattern list> (admin:admin) ^admin/>], [<RegexURLResolver <module 'django.contrib.admindocs.urls' from 'E:\\cursotaller\\initial_vemo
\\ve_vemo
\\lib\\site-packages\\django\\contrib\\admindocs\\urls.py'> (None:None) ^admin/doc/>], [<RegexURLResolver <module 'rest_framework.urls' from 'E:\\cursotaller\\initial_vemo
\\ve_vemo
\\lib\\site-packages\\rest_framework\\urls.py'> (rest_framework:rest_framework) ^api-auth/>], [<RegexURLResolver <module 'oauth2_provider.urls' from 'E:\\cursotaller\\initial_vemo
\\ve_vemo
\\lib\\site-packages\\oauth2_provider\\urls.py'> (None:oauth2_provider) ^o/>], [<RegexURLResolver <module 'vemo
_service_apps.auths_api.urls' from 'E:\\cursotaller\\initial_vemo
\\vemo
_service\\vemo
_service_apps\\auths_api\\urls.py'> (None:None) ^api/auths/>], [<RegexURLResolver <module 'vemo
_service_apps.catalogo_api.urls' from 'E:\\cursotaller\\initial_vemo
\\vemo
_service\\vemo
_service_apps\\catalogo_api\\urls.py'> (None:None) ^api/catalogo/>]]}

During handling of the above exception, another exception occurred:

Traceback (most recent call last):
  File "E:\cursotaller\initial_vemo
\ve_vemo
\lib\site-packages\django\template\base.py", line 883, in _resolve_lookup
    current = current[bit]
TypeError: 'RegexURLResolver' object is not subscriptable

During handling of the above exception, another exception occurred:

Traceback (most recent call last):
  File "E:\cursotaller\initial_vemo
\ve_vemo
\lib\site-packages\django\template\base.py", line 891, in _resolve_lookup
    current = getattr(current, bit)
AttributeError: 'RegexURLResolver' object has no attribute 'name'

During handling of the above exception, another exception occurred:

Traceback (most recent call last):
  File "E:\cursotaller\initial_vemo
\ve_vemo
\lib\site-packages\django\template\base.py", line 898, in _resolve_lookup
    current = current[int(bit)]
ValueError: invalid literal for int() with base 10: 'name'

During handling of the above exception, another exception occurred:

Traceback (most recent call last):
  File "E:\cursotaller\initial_vemo
\ve_vemo
\lib\site-packages\django\template\base.py", line 905, in _resolve_lookup
    (bit, current))  # missing attribute
django.template.base.VariableDoesNotExist: Failed lookup for key [name] in "<RegexURLResolver <module 'vemo
_service_apps.catalogo_api.urls' from 'E:\\\\cursotaller\\\\initial_vemo
\\\\vemo
_service\\\\vemo
_service_apps\\\\catalogo_api\\\\urls.py'> (None:None) ^api/catalogo/>"
[2016-10-27 18:04:31] DEBUG [django.template:927] Exception while resolving variable 'is_popup' in template 'admin/login.html'.
Traceback (most recent call last):
  File "E:\cursotaller\initial_vemo
\ve_vemo
\lib\site-packages\django\template\base.py", line 883, in _resolve_lookup
    current = current[bit]
  File "E:\cursotaller\initial_vemo
\ve_vemo
\lib\site-packages\django\template\context.py", line 77, in __getitem__
    raise KeyError(key)
KeyError: 'is_popup'

During handling of the above exception, another exception occurred:

Traceback (most recent call last):
  File "E:\cursotaller\initial_vemo
\ve_vemo
\lib\site-packages\django\template\base.py", line 889, in _resolve_lookup
    if isinstance(current, BaseContext) and getattr(type(current), bit):
AttributeError: type object 'RequestContext' has no attribute 'is_popup'

During handling of the above exception, another exception occurred:

Traceback (most recent call last):
  File "E:\cursotaller\initial_vemo
\ve_vemo
\lib\site-packages\django\template\base.py", line 898, in _resolve_lookup
    current = current[int(bit)]
ValueError: invalid literal for int() with base 10: 'is_popup'

During handling of the above exception, another exception occurred:

Traceback (most recent call last):
  File "E:\cursotaller\initial_vemo
\ve_vemo
\lib\site-packages\django\template\base.py", line 905, in _resolve_lookup
    (bit, current))  # missing attribute
django.template.base.VariableDoesNotExist: Failed lookup for key [is_popup] in "[{'None': None, 'False': False, 'True': True}, {'csrf_token': <SimpleLazyObject: <function csrf.<locals>._get_val at 0x04A4E420>>, 'messages': <django.contrib.messages.storage.fallback.FallbackStorage object at 0x04A365B0>, 'request': <WSGIRequest: GET '/admin/login/?next=/admin/'>, 'perms': <django.contrib.auth.context_processors.PermWrapper object at 0x04E51BB0>, 'user': <SimpleLazyObject: <django.contrib.auth.models.AnonymousUser object at 0x04A36F50>>, 'DEFAULT_MESSAGE_LEVELS': {'WARNING': 30, 'SUCCESS': 25, 'DEBUG': 10, 'INFO': 20, 'ERROR': 40}}, {}, {'LANGUAGE_CODE': 'en-us', 'available_apps': [], 'next': '/admin/', 'title': 'Log in', 'site_name': 'localhost:9000', 'site': <django.contrib.sites.requests.RequestSite object at 0x04A36050>, 'form': <AdminAuthenticationForm bound=False, valid=Unknown, fields=(username;password)>, 'app_path': '/admin/login/?next=/admin/', 'LANGUAGE_BIDI': False, 'site_title': <django.utils.functional.lazy.<locals>.__proxy__ object at 0x03CFF9F0>, 'site_url': '/', 'has_permission': False, 'site_header': <django.utils.functional.lazy.<locals>.__proxy__ object at 0x03CFFAB0>}]"
[2016-10-27 18:04:31] DEBUG [django.template:927] Exception while resolving variable 'is_popup' in template 'admin/login.html'.
Traceback (most recent call last):
  File "E:\cursotaller\initial_vemo
\ve_vemo
\lib\site-packages\django\template\base.py", line 883, in _resolve_lookup
    current = current[bit]
  File "E:\cursotaller\initial_vemo
\ve_vemo
\lib\site-packages\django\template\context.py", line 77, in __getitem__
    raise KeyError(key)
KeyError: 'is_popup'

During handling of the above exception, another exception occurred:

Traceback (most recent call last):
  File "E:\cursotaller\initial_vemo
\ve_vemo
\lib\site-packages\django\template\base.py", line 889, in _resolve_lookup
    if isinstance(current, BaseContext) and getattr(type(current), bit):
AttributeError: type object 'RequestContext' has no attribute 'is_popup'

During handling of the above exception, another exception occurred:

Traceback (most recent call last):
  File "E:\cursotaller\initial_vemo
\ve_vemo
\lib\site-packages\django\template\base.py", line 898, in _resolve_lookup
    current = current[int(bit)]
ValueError: invalid literal for int() with base 10: 'is_popup'

During handling of the above exception, another exception occurred:

Traceback (most recent call last):
  File "E:\cursotaller\initial_vemo
\ve_vemo
\lib\site-packages\django\template\base.py", line 905, in _resolve_lookup
    (bit, current))  # missing attribute
django.template.base.VariableDoesNotExist: Failed lookup for key [is_popup] in "[{'None': None, 'False': False, 'True': True}, {'csrf_token': <SimpleLazyObject: <function csrf.<locals>._get_val at 0x04A4E420>>, 'messages': <django.contrib.messages.storage.fallback.FallbackStorage object at 0x04A365B0>, 'request': <WSGIRequest: GET '/admin/login/?next=/admin/'>, 'perms': <django.contrib.auth.context_processors.PermWrapper object at 0x04E51BB0>, 'user': <SimpleLazyObject: <django.contrib.auth.models.AnonymousUser object at 0x04A36F50>>, 'DEFAULT_MESSAGE_LEVELS': {'WARNING': 30, 'SUCCESS': 25, 'DEBUG': 10, 'INFO': 20, 'ERROR': 40}}, {}, {'LANGUAGE_CODE': 'en-us', 'available_apps': [], 'next': '/admin/', 'title': 'Log in', 'site_name': 'localhost:9000', 'site': <django.contrib.sites.requests.RequestSite object at 0x04A36050>, 'form': <AdminAuthenticationForm bound=False, valid=Unknown, fields=(username;password)>, 'app_path': '/admin/login/?next=/admin/', 'LANGUAGE_BIDI': False, 'site_title': <django.utils.functional.lazy.<locals>.__proxy__ object at 0x03CFF9F0>, 'site_url': '/', 'has_permission': False, 'site_header': <django.utils.functional.lazy.<locals>.__proxy__ object at 0x03CFFAB0>}]"
[2016-10-27 18:04:39] DEBUG [django.db.backends:89] (0.004) SELECT "auths_user"."password", "auths_user"."last_login", "auths_user"."is_superuser", "auths_user"."username", "auths_user"."first_name", "auths_user"."last_name", "auths_user"."email", "auths_user"."is_staff", "auths_user"."is_active", "auths_user"."date_joined", "auths_user"."id", "auths_user"."last_hierarchy_id", "auths_user"."last_module_id", "auths_user"."person_id", "auths_user"."updated_at", "auths_user"."registered_by" FROM "auths_user" WHERE "auths_user"."username" = 'admin'; args=('admin',)
[2016-10-27 18:04:39] DEBUG [django.db.backends:89] (0.000) SELECT (1) AS "a" FROM "django_session" WHERE "django_session"."session_key" = 'f8z2fe2r4z2rz5jv1jkq6t0tuojjzju0' LIMIT 1; args=('f8z2fe2r4z2rz5jv1jkq6t0tuojjzju0',)
[2016-10-27 18:04:39] DEBUG [django.db.backends:89] (0.000) BEGIN; args=None
[2016-10-27 18:04:39] DEBUG [django.db.backends:89] (0.021) INSERT INTO "django_session" ("session_key", "session_data", "expire_date") SELECT 'f8z2fe2r4z2rz5jv1jkq6t0tuojjzju0', 'MWM0OGIyODQ4NzI4MzRhZjAyMjIxNmY1YzZlNzUwYmUzNTU2OWFjMTp7fQ==', '2016-11-11 00:04:39.711588'; args=('f8z2fe2r4z2rz5jv1jkq6t0tuojjzju0', 'MWM0OGIyODQ4NzI4MzRhZjAyMjIxNmY1YzZlNzUwYmUzNTU2OWFjMTp7fQ==', '2016-11-11 00:04:39.711588')
[2016-10-27 18:04:39] DEBUG [django.db.backends:89] (0.000) SELECT "django_session"."session_key", "django_session"."session_data", "django_session"."expire_date" FROM "django_session" WHERE "django_session"."session_key" = 'f8z2fe2r4z2rz5jv1jkq6t0tuojjzju0'; args=('f8z2fe2r4z2rz5jv1jkq6t0tuojjzju0',)
[2016-10-27 18:04:39] DEBUG [django.db.backends:89] (0.004) BEGIN; args=None
[2016-10-27 18:04:39] DEBUG [django.db.backends:89] (0.000) DELETE FROM "django_session" WHERE "django_session"."session_key" IN ('f8z2fe2r4z2rz5jv1jkq6t0tuojjzju0'); args=('f8z2fe2r4z2rz5jv1jkq6t0tuojjzju0',)
[2016-10-27 18:04:39] DEBUG [django.db.backends:89] (0.000) BEGIN; args=None
[2016-10-27 18:04:39] DEBUG [django.db.backends:89] (0.000) UPDATE "auths_user" SET "last_login" = '2016-10-28 00:04:39.996905' WHERE "auths_user"."id" = '98c929be19fb4598b30233dd1ddbfcfd'; args=('2016-10-28 00:04:39.996905', '98c929be19fb4598b30233dd1ddbfcfd')
[2016-10-27 18:04:40] DEBUG [django.db.backends:89] (0.000) BEGIN; args=None
[2016-10-27 18:04:40] DEBUG [django.db.backends:89] (0.000) UPDATE "django_session" SET "session_data" = 'MzkyMmQzMGY3NmQzY2Q4YTJkNjE1MGFjY2Y1YjViMzU0ZWIwMWMyODp7Il9hdXRoX3VzZXJfYmFja2VuZCI6ImRqYW5nby5jb250cmliLmF1dGguYmFja2VuZHMuTW9kZWxCYWNrZW5kIiwiX2F1dGhfdXNlcl9pZCI6Ijk4YzkyOWJlLTE5ZmItNDU5OC1iMzAyLTMzZGQxZGRiZmNmZCIsIl9hdXRoX3VzZXJfaGFzaCI6Ijg3ZmM3NWRhMjRkYWVjMjdmMGUxMTc5ODYxMzYyYzFhMDliZWI2YTEifQ==', "expire_date" = '2016-11-11 00:04:40.073448' WHERE "django_session"."session_key" = 'f8z2fe2r4z2rz5jv1jkq6t0tuojjzju0'; args=('MzkyMmQzMGY3NmQzY2Q4YTJkNjE1MGFjY2Y1YjViMzU0ZWIwMWMyODp7Il9hdXRoX3VzZXJfYmFja2VuZCI6ImRqYW5nby5jb250cmliLmF1dGguYmFja2VuZHMuTW9kZWxCYWNrZW5kIiwiX2F1dGhfdXNlcl9pZCI6Ijk4YzkyOWJlLTE5ZmItNDU5OC1iMzAyLTMzZGQxZGRiZmNmZCIsIl9hdXRoX3VzZXJfaGFzaCI6Ijg3ZmM3NWRhMjRkYWVjMjdmMGUxMTc5ODYxMzYyYzFhMDliZWI2YTEifQ==', '2016-11-11 00:04:40.073448', 'f8z2fe2r4z2rz5jv1jkq6t0tuojjzju0')
[2016-10-27 18:04:40] DEBUG [django.db.backends:89] (0.000) INSERT INTO "django_session" ("session_key", "session_data", "expire_date") SELECT 'f8z2fe2r4z2rz5jv1jkq6t0tuojjzju0', 'MzkyMmQzMGY3NmQzY2Q4YTJkNjE1MGFjY2Y1YjViMzU0ZWIwMWMyODp7Il9hdXRoX3VzZXJfYmFja2VuZCI6ImRqYW5nby5jb250cmliLmF1dGguYmFja2VuZHMuTW9kZWxCYWNrZW5kIiwiX2F1dGhfdXNlcl9pZCI6Ijk4YzkyOWJlLTE5ZmItNDU5OC1iMzAyLTMzZGQxZGRiZmNmZCIsIl9hdXRoX3VzZXJfaGFzaCI6Ijg3ZmM3NWRhMjRkYWVjMjdmMGUxMTc5ODYxMzYyYzFhMDliZWI2YTEifQ==', '2016-11-11 00:04:40.073448'; args=('f8z2fe2r4z2rz5jv1jkq6t0tuojjzju0', 'MzkyMmQzMGY3NmQzY2Q4YTJkNjE1MGFjY2Y1YjViMzU0ZWIwMWMyODp7Il9hdXRoX3VzZXJfYmFja2VuZCI6ImRqYW5nby5jb250cmliLmF1dGguYmFja2VuZHMuTW9kZWxCYWNrZW5kIiwiX2F1dGhfdXNlcl9pZCI6Ijk4YzkyOWJlLTE5ZmItNDU5OC1iMzAyLTMzZGQxZGRiZmNmZCIsIl9hdXRoX3VzZXJfaGFzaCI6Ijg3ZmM3NWRhMjRkYWVjMjdmMGUxMTc5ODYxMzYyYzFhMDliZWI2YTEifQ==', '2016-11-11 00:04:40.073448')
[2016-10-27 18:04:40] DEBUG [django.db.backends:89] (0.000) SELECT "django_session"."session_key", "django_session"."session_data", "django_session"."expire_date" FROM "django_session" WHERE ("django_session"."expire_date" > '2016-10-28 00:04:40.455260' AND "django_session"."session_key" = 'f8z2fe2r4z2rz5jv1jkq6t0tuojjzju0'); args=('2016-10-28 00:04:40.455260', 'f8z2fe2r4z2rz5jv1jkq6t0tuojjzju0')
[2016-10-27 18:04:40] DEBUG [django.db.backends:89] (0.000) SELECT "auths_user"."password", "auths_user"."last_login", "auths_user"."is_superuser", "auths_user"."username", "auths_user"."first_name", "auths_user"."last_name", "auths_user"."email", "auths_user"."is_staff", "auths_user"."is_active", "auths_user"."date_joined", "auths_user"."id", "auths_user"."last_hierarchy_id", "auths_user"."last_module_id", "auths_user"."person_id", "auths_user"."updated_at", "auths_user"."registered_by" FROM "auths_user" WHERE "auths_user"."id" = '98c929be19fb4598b30233dd1ddbfcfd'; args=('98c929be19fb4598b30233dd1ddbfcfd',)
[2016-10-27 18:04:40] DEBUG [django.template:927] Exception while resolving variable 'is_popup' in template 'admin/index.html'.
Traceback (most recent call last):
  File "E:\cursotaller\initial_vemo
\ve_vemo
\lib\site-packages\django\template\base.py", line 883, in _resolve_lookup
    current = current[bit]
  File "E:\cursotaller\initial_vemo
\ve_vemo
\lib\site-packages\django\template\context.py", line 77, in __getitem__
    raise KeyError(key)
KeyError: 'is_popup'

During handling of the above exception, another exception occurred:

Traceback (most recent call last):
  File "E:\cursotaller\initial_vemo
\ve_vemo
\lib\site-packages\django\template\base.py", line 889, in _resolve_lookup
    if isinstance(current, BaseContext) and getattr(type(current), bit):
AttributeError: type object 'RequestContext' has no attribute 'is_popup'

During handling of the above exception, another exception occurred:

Traceback (most recent call last):
  File "E:\cursotaller\initial_vemo
\ve_vemo
\lib\site-packages\django\template\base.py", line 898, in _resolve_lookup
    current = current[int(bit)]
ValueError: invalid literal for int() with base 10: 'is_popup'

During handling of the above exception, another exception occurred:

Traceback (most recent call last):
  File "E:\cursotaller\initial_vemo
\ve_vemo
\lib\site-packages\django\template\base.py", line 905, in _resolve_lookup
    (bit, current))  # missing attribute
django.template.base.VariableDoesNotExist: Failed lookup for key [is_popup] in "[{'None': None, 'False': False, 'True': True}, {'csrf_token': <SimpleLazyObject: <function csrf.<locals>._get_val at 0x04948DB0>>, 'messages': <django.contrib.messages.storage.fallback.FallbackStorage object at 0x04A53D30>, 'request': <WSGIRequest: GET '/admin/'>, 'perms': <django.contrib.auth.context_processors.PermWrapper object at 0x04A36C50>, 'user': <SimpleLazyObject: <User: admin>>, 'DEFAULT_MESSAGE_LEVELS': {'WARNING': 30, 'SUCCESS': 25, 'DEBUG': 10, 'INFO': 20, 'ERROR': 40}}, {}, {'LANGUAGE_CODE': 'en-us', 'available_apps': [{'app_url': '/admin/auth/', 'has_module_perms': True, 'app_label': 'auth', 'name': <django.utils.functional.lazy.<locals>.__proxy__ object at 0x03D09030>, 'models': [{'perms': {'add': True, 'change': True, 'delete': True}, 'add_url': '/admin/auth/group/add/', 'admin_url': '/admin/auth/group/', 'name': <django.utils.functional.lazy.<locals>.__proxy__ object at 0x04A53570>, 'object_name': 'Group'}, {'perms': {'add': True, 'change': True, 'delete': True}, 'add_url': '/admin/auth/permission/add/', 'admin_url': '/admin/auth/permission/', 'name': <django.utils.functional.lazy.<locals>.__proxy__ object at 0x04A53DB0>, 'object_name': 'Permission'}]}, {'app_url': '/admin/auths/', 'has_module_perms': True, 'app_label': 'auths', 'name': 'Auths', 'models': [{'perms': {'add': True, 'change': True, 'delete': True}, 'add_url': '/admin/auths/hierarchytype/add/', 'admin_url': '/admin/auths/hierarchytype/', 'name': <django.utils.functional.lazy.<locals>.__proxy__ object at 0x04A534D0>, 'object_name': 'HierarchyType'}, {'perms': {'add': True, 'change': True, 'delete': True}, 'add_url': '/admin/auths/hierarchy/add/', 'admin_url': '/admin/auths/hierarchy/', 'name': <django.utils.functional.lazy.<locals>.__proxy__ object at 0x04A53E90>, 'object_name': 'Hierarchy'}, {'perms': {'add': True, 'change': True, 'delete': True}, 'add_url': '/admin/auths/menu/add/', 'admin_url': '/admin/auths/menu/', 'name': <django.utils.functional.lazy.<locals>.__proxy__ object at 0x04A53450>, 'object_name': 'Menu'}, {'perms': {'add': True, 'change': True, 'delete': True}, 'add_url': '/admin/auths/person/add/', 'admin_url': '/admin/auths/person/', 'name': <django.utils.functional.lazy.<locals>.__proxy__ object at 0x04A535B0>, 'object_name': 'Person'}, {'perms': {'add': True, 'change': True, 'delete': True}, 'add_url': '/admin/auths/userhierarchygroup/add/', 'admin_url': '/admin/auths/userhierarchygroup/', 'name': <django.utils.functional.lazy.<locals>.__proxy__ object at 0x04A53FF0>, 'object_name': 'UserHierarchyGroup'}, {'perms': {'add': True, 'change': True, 'delete': True}, 'add_url': '/admin/auths/userhierarchypermission/add/', 'admin_url': '/admin/auths/userhierarchypermission/', 'name': <django.utils.functional.lazy.<locals>.__proxy__ object at 0x04A53AB0>, 'object_name': 'UserHierarchyPermission'}, {'perms': {'add': True, 'change': True, 'delete': True}, 'add_url': '/admin/auths/user/add/', 'admin_url': '/admin/auths/user/', 'name': <django.utils.functional.lazy.<locals>.__proxy__ object at 0x04A53950>, 'object_name': 'User'}]}, {'app_url': '/admin/catalogo/', 'has_module_perms': True, 'app_label': 'catalogo', 'name': 'Catalogo', 'models': [{'perms': {'add': True, 'change': True, 'delete': True}, 'add_url': '/admin/catalogo/autor/add/', 'admin_url': '/admin/catalogo/autor/', 'name': 'Autores', 'object_name': 'Autor'}, {'perms': {'add': True, 'change': True, 'delete': True}, 'add_url': '/admin/catalogo/categoria/add/', 'admin_url': '/admin/catalogo/categoria/', 'name': 'Categorias', 'object_name': 'Categoria'}, {'perms': {'add': True, 'change': True, 'delete': True}, 'add_url': '/admin/catalogo/libro/add/', 'admin_url': '/admin/catalogo/libro/', 'name': 'Libros', 'object_name': 'Libro'}]}, {'app_url': '/admin/contenttypes/', 'has_module_perms': True, 'app_label': 'contenttypes', 'name': <django.utils.functional.lazy.<locals>.__proxy__ object at 0x03D09070>, 'models': [{'perms': {'add': True, 'change': True, 'delete': True}, 'add_url': '/admin/contenttypes/contenttype/add/', 'admin_url': '/admin/contenttypes/contenttype/', 'name': <django.utils.functional.lazy.<locals>.__proxy__ object at 0x04A533F0>, 'object_name': 'ContentType'}]}, {'app_url': '/admin/oauth2_provider/', 'has_module_perms': True, 'app_label': 'oauth2_provider', 'name': 'Django OAuth Toolkit', 'models': [{'perms': {'add': True, 'change': True, 'delete': True}, 'add_url': '/admin/oauth2_provider/accesstoken/add/', 'admin_url': '/admin/oauth2_provider/accesstoken/', 'name': <django.utils.functional.lazy.<locals>.__proxy__ object at 0x04A539F0>, 'object_name': 'AccessToken'}, {'perms': {'add': True, 'change': True, 'delete': True}, 'add_url': '/admin/oauth2_provider/application/add/', 'admin_url': '/admin/oauth2_provider/application/', 'name': <django.utils.functional.lazy.<locals>.__proxy__ object at 0x04A53610>, 'object_name': 'Application'}, {'perms': {'add': True, 'change': True, 'delete': True}, 'add_url': '/admin/oauth2_provider/grant/add/', 'admin_url': '/admin/oauth2_provider/grant/', 'name': <django.utils.functional.lazy.<locals>.__proxy__ object at 0x04A53630>, 'object_name': 'Grant'}, {'perms': {'add': True, 'change': True, 'delete': True}, 'add_url': '/admin/oauth2_provider/refreshtoken/add/', 'admin_url': '/admin/oauth2_provider/refreshtoken/', 'name': <django.utils.functional.lazy.<locals>.__proxy__ object at 0x04A53670>, 'object_name': 'RefreshToken'}]}], 'app_list': [{'app_url': '/admin/auth/', 'has_module_perms': True, 'app_label': 'auth', 'name': <django.utils.functional.lazy.<locals>.__proxy__ object at 0x03D09030>, 'models': [{'perms': {'add': True, 'change': True, 'delete': True}, 'add_url': '/admin/auth/group/add/', 'admin_url': '/admin/auth/group/', 'name': <django.utils.functional.lazy.<locals>.__proxy__ object at 0x04A53310>, 'object_name': 'Group'}, {'perms': {'add': True, 'change': True, 'delete': True}, 'add_url': '/admin/auth/permission/add/', 'admin_url': '/admin/auth/permission/', 'name': <django.utils.functional.lazy.<locals>.__proxy__ object at 0x04A53FB0>, 'object_name': 'Permission'}]}, {'app_url': '/admin/auths/', 'has_module_perms': True, 'app_label': 'auths', 'name': 'Auths', 'models': [{'perms': {'add': True, 'change': True, 'delete': True}, 'add_url': '/admin/auths/hierarchytype/add/', 'admin_url': '/admin/auths/hierarchytype/', 'name': <django.utils.functional.lazy.<locals>.__proxy__ object at 0x04A537F0>, 'object_name': 'HierarchyType'}, {'perms': {'add': True, 'change': True, 'delete': True}, 'add_url': '/admin/auths/hierarchy/add/', 'admin_url': '/admin/auths/hierarchy/', 'name': <django.utils.functional.lazy.<locals>.__proxy__ object at 0x04A539D0>, 'object_name': 'Hierarchy'}, {'perms': {'add': True, 'change': True, 'delete': True}, 'add_url': '/admin/auths/menu/add/', 'admin_url': '/admin/auths/menu/', 'name': <django.utils.functional.lazy.<locals>.__proxy__ object at 0x04A533B0>, 'object_name': 'Menu'}, {'perms': {'add': True, 'change': True, 'delete': True}, 'add_url': '/admin/auths/person/add/', 'admin_url': '/admin/auths/person/', 'name': <django.utils.functional.lazy.<locals>.__proxy__ object at 0x04A53BD0>, 'object_name': 'Person'}, {'perms': {'add': True, 'change': True, 'delete': True}, 'add_url': '/admin/auths/userhierarchygroup/add/', 'admin_url': '/admin/auths/userhierarchygroup/', 'name': <django.utils.functional.lazy.<locals>.__proxy__ object at 0x04A53A10>, 'object_name': 'UserHierarchyGroup'}, {'perms': {'add': True, 'change': True, 'delete': True}, 'add_url': '/admin/auths/userhierarchypermission/add/', 'admin_url': '/admin/auths/userhierarchypermission/', 'name': <django.utils.functional.lazy.<locals>.__proxy__ object at 0x04A537D0>, 'object_name': 'UserHierarchyPermission'}, {'perms': {'add': True, 'change': True, 'delete': True}, 'add_url': '/admin/auths/user/add/', 'admin_url': '/admin/auths/user/', 'name': <django.utils.functional.lazy.<locals>.__proxy__ object at 0x04A53970>, 'object_name': 'User'}]}, {'app_url': '/admin/catalogo/', 'has_module_perms': True, 'app_label': 'catalogo', 'name': 'Catalogo', 'models': [{'perms': {'add': True, 'change': True, 'delete': True}, 'add_url': '/admin/catalogo/autor/add/', 'admin_url': '/admin/catalogo/autor/', 'name': 'Autores', 'object_name': 'Autor'}, {'perms': {'add': True, 'change': True, 'delete': True}, 'add_url': '/admin/catalogo/categoria/add/', 'admin_url': '/admin/catalogo/categoria/', 'name': 'Categorias', 'object_name': 'Categoria'}, {'perms': {'add': True, 'change': True, 'delete': True}, 'add_url': '/admin/catalogo/libro/add/', 'admin_url': '/admin/catalogo/libro/', 'name': 'Libros', 'object_name': 'Libro'}]}, {'app_url': '/admin/contenttypes/', 'has_module_perms': True, 'app_label': 'contenttypes', 'name': <django.utils.functional.lazy.<locals>.__proxy__ object at 0x03D09070>, 'models': [{'perms': {'add': True, 'change': True, 'delete': True}, 'add_url': '/admin/contenttypes/contenttype/add/', 'admin_url': '/admin/contenttypes/contenttype/', 'name': <django.utils.functional.lazy.<locals>.__proxy__ object at 0x04A53BB0>, 'object_name': 'ContentType'}]}, {'app_url': '/admin/oauth2_provider/', 'has_module_perms': True, 'app_label': 'oauth2_provider', 'name': 'Django OAuth Toolkit', 'models': [{'perms': {'add': True, 'change': True, 'delete': True}, 'add_url': '/admin/oauth2_provider/accesstoken/add/', 'admin_url': '/admin/oauth2_provider/accesstoken/', 'name': <django.utils.functional.lazy.<locals>.__proxy__ object at 0x04A53EB0>, 'object_name': 'AccessToken'}, {'perms': {'add': True, 'change': True, 'delete': True}, 'add_url': '/admin/oauth2_provider/application/add/', 'admin_url': '/admin/oauth2_provider/application/', 'name': <django.utils.functional.lazy.<locals>.__proxy__ object at 0x04A53430>, 'object_name': 'Application'}, {'perms': {'add': True, 'change': True, 'delete': True}, 'add_url': '/admin/oauth2_provider/grant/add/', 'admin_url': '/admin/oauth2_provider/grant/', 'name': <django.utils.functional.lazy.<locals>.__proxy__ object at 0x04A53930>, 'object_name': 'Grant'}, {'perms': {'add': True, 'change': True, 'delete': True}, 'add_url': '/admin/oauth2_provider/refreshtoken/add/', 'admin_url': '/admin/oauth2_provider/refreshtoken/', 'name': <django.utils.functional.lazy.<locals>.__proxy__ object at 0x04A53350>, 'object_name': 'RefreshToken'}]}], 'LANGUAGE_BIDI': False, 'title': <django.utils.functional.lazy.<locals>.__proxy__ object at 0x03CFFAF0>, 'site_title': <django.utils.functional.lazy.<locals>.__proxy__ object at 0x03CFF9F0>, 'site_url': '/', 'has_permission': True, 'site_header': <django.utils.functional.lazy.<locals>.__proxy__ object at 0x03CFFAB0>}]"
[2016-10-27 18:04:40] DEBUG [django.template:927] Exception while resolving variable 'is_popup' in template 'admin/index.html'.
Traceback (most recent call last):
  File "E:\cursotaller\initial_vemo
\ve_vemo
\lib\site-packages\django\template\base.py", line 883, in _resolve_lookup
    current = current[bit]
  File "E:\cursotaller\initial_vemo
\ve_vemo
\lib\site-packages\django\template\context.py", line 77, in __getitem__
    raise KeyError(key)
KeyError: 'is_popup'

During handling of the above exception, another exception occurred:

Traceback (most recent call last):
  File "E:\cursotaller\initial_vemo
\ve_vemo
\lib\site-packages\django\template\base.py", line 889, in _resolve_lookup
    if isinstance(current, BaseContext) and getattr(type(current), bit):
AttributeError: type object 'RequestContext' has no attribute 'is_popup'

During handling of the above exception, another exception occurred:

Traceback (most recent call last):
  File "E:\cursotaller\initial_vemo
\ve_vemo
\lib\site-packages\django\template\base.py", line 898, in _resolve_lookup
    current = current[int(bit)]
ValueError: invalid literal for int() with base 10: 'is_popup'

During handling of the above exception, another exception occurred:

Traceback (most recent call last):
  File "E:\cursotaller\initial_vemo
\ve_vemo
\lib\site-packages\django\template\base.py", line 905, in _resolve_lookup
    (bit, current))  # missing attribute
django.template.base.VariableDoesNotExist: Failed lookup for key [is_popup] in "[{'None': None, 'False': False, 'True': True}, {'csrf_token': <SimpleLazyObject: <function csrf.<locals>._get_val at 0x04948DB0>>, 'messages': <django.contrib.messages.storage.fallback.FallbackStorage object at 0x04A53D30>, 'request': <WSGIRequest: GET '/admin/'>, 'perms': <django.contrib.auth.context_processors.PermWrapper object at 0x04A36C50>, 'user': <SimpleLazyObject: <User: admin>>, 'DEFAULT_MESSAGE_LEVELS': {'WARNING': 30, 'SUCCESS': 25, 'DEBUG': 10, 'INFO': 20, 'ERROR': 40}}, {}, {'LANGUAGE_CODE': 'en-us', 'available_apps': [{'app_url': '/admin/auth/', 'has_module_perms': True, 'app_label': 'auth', 'name': <django.utils.functional.lazy.<locals>.__proxy__ object at 0x03D09030>, 'models': [{'perms': {'add': True, 'change': True, 'delete': True}, 'add_url': '/admin/auth/group/add/', 'admin_url': '/admin/auth/group/', 'name': <django.utils.functional.lazy.<locals>.__proxy__ object at 0x04A53570>, 'object_name': 'Group'}, {'perms': {'add': True, 'change': True, 'delete': True}, 'add_url': '/admin/auth/permission/add/', 'admin_url': '/admin/auth/permission/', 'name': <django.utils.functional.lazy.<locals>.__proxy__ object at 0x04A53DB0>, 'object_name': 'Permission'}]}, {'app_url': '/admin/auths/', 'has_module_perms': True, 'app_label': 'auths', 'name': 'Auths', 'models': [{'perms': {'add': True, 'change': True, 'delete': True}, 'add_url': '/admin/auths/hierarchytype/add/', 'admin_url': '/admin/auths/hierarchytype/', 'name': <django.utils.functional.lazy.<locals>.__proxy__ object at 0x04A534D0>, 'object_name': 'HierarchyType'}, {'perms': {'add': True, 'change': True, 'delete': True}, 'add_url': '/admin/auths/hierarchy/add/', 'admin_url': '/admin/auths/hierarchy/', 'name': <django.utils.functional.lazy.<locals>.__proxy__ object at 0x04A53E90>, 'object_name': 'Hierarchy'}, {'perms': {'add': True, 'change': True, 'delete': True}, 'add_url': '/admin/auths/menu/add/', 'admin_url': '/admin/auths/menu/', 'name': <django.utils.functional.lazy.<locals>.__proxy__ object at 0x04A53450>, 'object_name': 'Menu'}, {'perms': {'add': True, 'change': True, 'delete': True}, 'add_url': '/admin/auths/person/add/', 'admin_url': '/admin/auths/person/', 'name': <django.utils.functional.lazy.<locals>.__proxy__ object at 0x04A535B0>, 'object_name': 'Person'}, {'perms': {'add': True, 'change': True, 'delete': True}, 'add_url': '/admin/auths/userhierarchygroup/add/', 'admin_url': '/admin/auths/userhierarchygroup/', 'name': <django.utils.functional.lazy.<locals>.__proxy__ object at 0x04A53FF0>, 'object_name': 'UserHierarchyGroup'}, {'perms': {'add': True, 'change': True, 'delete': True}, 'add_url': '/admin/auths/userhierarchypermission/add/', 'admin_url': '/admin/auths/userhierarchypermission/', 'name': <django.utils.functional.lazy.<locals>.__proxy__ object at 0x04A53AB0>, 'object_name': 'UserHierarchyPermission'}, {'perms': {'add': True, 'change': True, 'delete': True}, 'add_url': '/admin/auths/user/add/', 'admin_url': '/admin/auths/user/', 'name': <django.utils.functional.lazy.<locals>.__proxy__ object at 0x04A53950>, 'object_name': 'User'}]}, {'app_url': '/admin/catalogo/', 'has_module_perms': True, 'app_label': 'catalogo', 'name': 'Catalogo', 'models': [{'perms': {'add': True, 'change': True, 'delete': True}, 'add_url': '/admin/catalogo/autor/add/', 'admin_url': '/admin/catalogo/autor/', 'name': 'Autores', 'object_name': 'Autor'}, {'perms': {'add': True, 'change': True, 'delete': True}, 'add_url': '/admin/catalogo/categoria/add/', 'admin_url': '/admin/catalogo/categoria/', 'name': 'Categorias', 'object_name': 'Categoria'}, {'perms': {'add': True, 'change': True, 'delete': True}, 'add_url': '/admin/catalogo/libro/add/', 'admin_url': '/admin/catalogo/libro/', 'name': 'Libros', 'object_name': 'Libro'}]}, {'app_url': '/admin/contenttypes/', 'has_module_perms': True, 'app_label': 'contenttypes', 'name': <django.utils.functional.lazy.<locals>.__proxy__ object at 0x03D09070>, 'models': [{'perms': {'add': True, 'change': True, 'delete': True}, 'add_url': '/admin/contenttypes/contenttype/add/', 'admin_url': '/admin/contenttypes/contenttype/', 'name': <django.utils.functional.lazy.<locals>.__proxy__ object at 0x04A533F0>, 'object_name': 'ContentType'}]}, {'app_url': '/admin/oauth2_provider/', 'has_module_perms': True, 'app_label': 'oauth2_provider', 'name': 'Django OAuth Toolkit', 'models': [{'perms': {'add': True, 'change': True, 'delete': True}, 'add_url': '/admin/oauth2_provider/accesstoken/add/', 'admin_url': '/admin/oauth2_provider/accesstoken/', 'name': <django.utils.functional.lazy.<locals>.__proxy__ object at 0x04A539F0>, 'object_name': 'AccessToken'}, {'perms': {'add': True, 'change': True, 'delete': True}, 'add_url': '/admin/oauth2_provider/application/add/', 'admin_url': '/admin/oauth2_provider/application/', 'name': <django.utils.functional.lazy.<locals>.__proxy__ object at 0x04A53610>, 'object_name': 'Application'}, {'perms': {'add': True, 'change': True, 'delete': True}, 'add_url': '/admin/oauth2_provider/grant/add/', 'admin_url': '/admin/oauth2_provider/grant/', 'name': <django.utils.functional.lazy.<locals>.__proxy__ object at 0x04A53630>, 'object_name': 'Grant'}, {'perms': {'add': True, 'change': True, 'delete': True}, 'add_url': '/admin/oauth2_provider/refreshtoken/add/', 'admin_url': '/admin/oauth2_provider/refreshtoken/', 'name': <django.utils.functional.lazy.<locals>.__proxy__ object at 0x04A53670>, 'object_name': 'RefreshToken'}]}], 'app_list': [{'app_url': '/admin/auth/', 'has_module_perms': True, 'app_label': 'auth', 'name': <django.utils.functional.lazy.<locals>.__proxy__ object at 0x03D09030>, 'models': [{'perms': {'add': True, 'change': True, 'delete': True}, 'add_url': '/admin/auth/group/add/', 'admin_url': '/admin/auth/group/', 'name': <django.utils.functional.lazy.<locals>.__proxy__ object at 0x04A53310>, 'object_name': 'Group'}, {'perms': {'add': True, 'change': True, 'delete': True}, 'add_url': '/admin/auth/permission/add/', 'admin_url': '/admin/auth/permission/', 'name': <django.utils.functional.lazy.<locals>.__proxy__ object at 0x04A53FB0>, 'object_name': 'Permission'}]}, {'app_url': '/admin/auths/', 'has_module_perms': True, 'app_label': 'auths', 'name': 'Auths', 'models': [{'perms': {'add': True, 'change': True, 'delete': True}, 'add_url': '/admin/auths/hierarchytype/add/', 'admin_url': '/admin/auths/hierarchytype/', 'name': <django.utils.functional.lazy.<locals>.__proxy__ object at 0x04A537F0>, 'object_name': 'HierarchyType'}, {'perms': {'add': True, 'change': True, 'delete': True}, 'add_url': '/admin/auths/hierarchy/add/', 'admin_url': '/admin/auths/hierarchy/', 'name': <django.utils.functional.lazy.<locals>.__proxy__ object at 0x04A539D0>, 'object_name': 'Hierarchy'}, {'perms': {'add': True, 'change': True, 'delete': True}, 'add_url': '/admin/auths/menu/add/', 'admin_url': '/admin/auths/menu/', 'name': <django.utils.functional.lazy.<locals>.__proxy__ object at 0x04A533B0>, 'object_name': 'Menu'}, {'perms': {'add': True, 'change': True, 'delete': True}, 'add_url': '/admin/auths/person/add/', 'admin_url': '/admin/auths/person/', 'name': <django.utils.functional.lazy.<locals>.__proxy__ object at 0x04A53BD0>, 'object_name': 'Person'}, {'perms': {'add': True, 'change': True, 'delete': True}, 'add_url': '/admin/auths/userhierarchygroup/add/', 'admin_url': '/admin/auths/userhierarchygroup/', 'name': <django.utils.functional.lazy.<locals>.__proxy__ object at 0x04A53A10>, 'object_name': 'UserHierarchyGroup'}, {'perms': {'add': True, 'change': True, 'delete': True}, 'add_url': '/admin/auths/userhierarchypermission/add/', 'admin_url': '/admin/auths/userhierarchypermission/', 'name': <django.utils.functional.lazy.<locals>.__proxy__ object at 0x04A537D0>, 'object_name': 'UserHierarchyPermission'}, {'perms': {'add': True, 'change': True, 'delete': True}, 'add_url': '/admin/auths/user/add/', 'admin_url': '/admin/auths/user/', 'name': <django.utils.functional.lazy.<locals>.__proxy__ object at 0x04A53970>, 'object_name': 'User'}]}, {'app_url': '/admin/catalogo/', 'has_module_perms': True, 'app_label': 'catalogo', 'name': 'Catalogo', 'models': [{'perms': {'add': True, 'change': True, 'delete': True}, 'add_url': '/admin/catalogo/autor/add/', 'admin_url': '/admin/catalogo/autor/', 'name': 'Autores', 'object_name': 'Autor'}, {'perms': {'add': True, 'change': True, 'delete': True}, 'add_url': '/admin/catalogo/categoria/add/', 'admin_url': '/admin/catalogo/categoria/', 'name': 'Categorias', 'object_name': 'Categoria'}, {'perms': {'add': True, 'change': True, 'delete': True}, 'add_url': '/admin/catalogo/libro/add/', 'admin_url': '/admin/catalogo/libro/', 'name': 'Libros', 'object_name': 'Libro'}]}, {'app_url': '/admin/contenttypes/', 'has_module_perms': True, 'app_label': 'contenttypes', 'name': <django.utils.functional.lazy.<locals>.__proxy__ object at 0x03D09070>, 'models': [{'perms': {'add': True, 'change': True, 'delete': True}, 'add_url': '/admin/contenttypes/contenttype/add/', 'admin_url': '/admin/contenttypes/contenttype/', 'name': <django.utils.functional.lazy.<locals>.__proxy__ object at 0x04A53BB0>, 'object_name': 'ContentType'}]}, {'app_url': '/admin/oauth2_provider/', 'has_module_perms': True, 'app_label': 'oauth2_provider', 'name': 'Django OAuth Toolkit', 'models': [{'perms': {'add': True, 'change': True, 'delete': True}, 'add_url': '/admin/oauth2_provider/accesstoken/add/', 'admin_url': '/admin/oauth2_provider/accesstoken/', 'name': <django.utils.functional.lazy.<locals>.__proxy__ object at 0x04A53EB0>, 'object_name': 'AccessToken'}, {'perms': {'add': True, 'change': True, 'delete': True}, 'add_url': '/admin/oauth2_provider/application/add/', 'admin_url': '/admin/oauth2_provider/application/', 'name': <django.utils.functional.lazy.<locals>.__proxy__ object at 0x04A53430>, 'object_name': 'Application'}, {'perms': {'add': True, 'change': True, 'delete': True}, 'add_url': '/admin/oauth2_provider/grant/add/', 'admin_url': '/admin/oauth2_provider/grant/', 'name': <django.utils.functional.lazy.<locals>.__proxy__ object at 0x04A53930>, 'object_name': 'Grant'}, {'perms': {'add': True, 'change': True, 'delete': True}, 'add_url': '/admin/oauth2_provider/refreshtoken/add/', 'admin_url': '/admin/oauth2_provider/refreshtoken/', 'name': <django.utils.functional.lazy.<locals>.__proxy__ object at 0x04A53350>, 'object_name': 'RefreshToken'}]}], 'LANGUAGE_BIDI': False, 'title': <django.utils.functional.lazy.<locals>.__proxy__ object at 0x03CFFAF0>, 'site_title': <django.utils.functional.lazy.<locals>.__proxy__ object at 0x03CFF9F0>, 'site_url': '/', 'has_permission': True, 'site_header': <django.utils.functional.lazy.<locals>.__proxy__ object at 0x03CFFAB0>}]"
[2016-10-27 18:04:40] DEBUG [django.db.backends:89] (0.000) SELECT "django_admin_log"."id", "django_admin_log"."action_time", "django_admin_log"."user_id", "django_admin_log"."content_type_id", "django_admin_log"."object_id", "django_admin_log"."object_repr", "django_admin_log"."action_flag", "django_admin_log"."change_message", "auths_user"."password", "auths_user"."last_login", "auths_user"."is_superuser", "auths_user"."username", "auths_user"."first_name", "auths_user"."last_name", "auths_user"."email", "auths_user"."is_staff", "auths_user"."is_active", "auths_user"."date_joined", "auths_user"."id", "auths_user"."last_hierarchy_id", "auths_user"."last_module_id", "auths_user"."person_id", "auths_user"."updated_at", "auths_user"."registered_by", "django_content_type"."id", "django_content_type"."app_label", "django_content_type"."model" FROM "django_admin_log" INNER JOIN "auths_user" ON ("django_admin_log"."user_id" = "auths_user"."id") LEFT OUTER JOIN "django_content_type" ON ("django_admin_log"."content_type_id" = "django_content_type"."id") WHERE "django_admin_log"."user_id" = '98c929be19fb4598b30233dd1ddbfcfd' ORDER BY "django_admin_log"."action_time" DESC LIMIT 10; args=('98c929be19fb4598b30233dd1ddbfcfd',)
[2016-10-27 18:05:36] DEBUG [django.db.backends:89] (0.000) SELECT "oauth2_provider_application"."id", "oauth2_provider_application"."client_id", "oauth2_provider_application"."user_id", "oauth2_provider_application"."redirect_uris", "oauth2_provider_application"."client_type", "oauth2_provider_application"."authorization_grant_type", "oauth2_provider_application"."client_secret", "oauth2_provider_application"."name", "oauth2_provider_application"."skip_authorization" FROM "oauth2_provider_application" WHERE "oauth2_provider_application"."client_id" = '1mDR3zdKmNxeMHoqSJfOfX4JBwSvw93zRK2GaZ61'; args=('1mDR3zdKmNxeMHoqSJfOfX4JBwSvw93zRK2GaZ61',)
[2016-10-27 18:05:36] DEBUG [django.db.backends:89] (0.000) SELECT "auths_user"."password", "auths_user"."last_login", "auths_user"."is_superuser", "auths_user"."username", "auths_user"."first_name", "auths_user"."last_name", "auths_user"."email", "auths_user"."is_staff", "auths_user"."is_active", "auths_user"."date_joined", "auths_user"."id", "auths_user"."last_hierarchy_id", "auths_user"."last_module_id", "auths_user"."person_id", "auths_user"."updated_at", "auths_user"."registered_by" FROM "auths_user" WHERE "auths_user"."username" = 'admin'; args=('admin',)
[2016-10-27 18:05:36] DEBUG [django.db.backends:89] (0.000) BEGIN; args=None
[2016-10-27 18:05:36] DEBUG [django.db.backends:89] (0.000) INSERT INTO "oauth2_provider_accesstoken" ("user_id", "token", "application_id", "expires", "scope") VALUES ('98c929be19fb4598b30233dd1ddbfcfd', '2sTBQrqOt2c79w6CJdrQrT18aJ6Pra', 1, '2016-10-28 10:05:36.746297', 'read write'); args=['98c929be19fb4598b30233dd1ddbfcfd', '2sTBQrqOt2c79w6CJdrQrT18aJ6Pra', 1, '2016-10-28 10:05:36.746297', 'read write']
[2016-10-27 18:05:36] DEBUG [django.db.backends:89] (0.000) BEGIN; args=None
[2016-10-27 18:05:36] DEBUG [django.db.backends:89] (0.000) INSERT INTO "oauth2_provider_refreshtoken" ("user_id", "token", "application_id", "access_token_id") VALUES ('98c929be19fb4598b30233dd1ddbfcfd', 'u2hfKbLHNcB94rnpVnWqGG4jJf1nmm', 1, 20); args=['98c929be19fb4598b30233dd1ddbfcfd', 'u2hfKbLHNcB94rnpVnWqGG4jJf1nmm', 1, 20]
[2016-10-27 18:05:37] DEBUG [django.db.backends:89] (0.000) SELECT "auths_user"."password", "auths_user"."last_login", "auths_user"."is_superuser", "auths_user"."username", "auths_user"."first_name", "auths_user"."last_name", "auths_user"."email", "auths_user"."is_staff", "auths_user"."is_active", "auths_user"."date_joined", "auths_user"."id", "auths_user"."last_hierarchy_id", "auths_user"."last_module_id", "auths_user"."person_id", "auths_user"."updated_at", "auths_user"."registered_by" FROM "auths_user" WHERE "auths_user"."username" IS NULL; args=()
[2016-10-27 18:05:37] DEBUG [django.db.backends:89] (0.000) SELECT "oauth2_provider_accesstoken"."id", "oauth2_provider_accesstoken"."user_id", "oauth2_provider_accesstoken"."token", "oauth2_provider_accesstoken"."application_id", "oauth2_provider_accesstoken"."expires", "oauth2_provider_accesstoken"."scope", "auths_user"."password", "auths_user"."last_login", "auths_user"."is_superuser", "auths_user"."username", "auths_user"."first_name", "auths_user"."last_name", "auths_user"."email", "auths_user"."is_staff", "auths_user"."is_active", "auths_user"."date_joined", "auths_user"."id", "auths_user"."last_hierarchy_id", "auths_user"."last_module_id", "auths_user"."person_id", "auths_user"."updated_at", "auths_user"."registered_by", "oauth2_provider_application"."id", "oauth2_provider_application"."client_id", "oauth2_provider_application"."user_id", "oauth2_provider_application"."redirect_uris", "oauth2_provider_application"."client_type", "oauth2_provider_application"."authorization_grant_type", "oauth2_provider_application"."client_secret", "oauth2_provider_application"."name", "oauth2_provider_application"."skip_authorization" FROM "oauth2_provider_accesstoken" LEFT OUTER JOIN "auths_user" ON ("oauth2_provider_accesstoken"."user_id" = "auths_user"."id") INNER JOIN "oauth2_provider_application" ON ("oauth2_provider_accesstoken"."application_id" = "oauth2_provider_application"."id") WHERE "oauth2_provider_accesstoken"."token" = '2sTBQrqOt2c79w6CJdrQrT18aJ6Pra'; args=('2sTBQrqOt2c79w6CJdrQrT18aJ6Pra',)
[2016-10-27 18:05:37] DEBUG [django.db.backends:89] (0.000) SELECT "auth_group"."id", "auth_group"."name" FROM "auth_group" INNER JOIN "auths_user_groups" ON ("auth_group"."id" = "auths_user_groups"."group_id") WHERE "auths_user_groups"."user_id" = '98c929be19fb4598b30233dd1ddbfcfd'; args=('98c929be19fb4598b30233dd1ddbfcfd',)
[2016-10-27 18:05:37] DEBUG [django.db.backends:89] (0.000) SELECT "auth_permission"."id", "auth_permission"."name", "auth_permission"."content_type_id", "auth_permission"."codename" FROM "auth_permission" INNER JOIN "auths_user_user_permissions" ON ("auth_permission"."id" = "auths_user_user_permissions"."permission_id") INNER JOIN "django_content_type" ON ("auth_permission"."content_type_id" = "django_content_type"."id") WHERE "auths_user_user_permissions"."user_id" = '98c929be19fb4598b30233dd1ddbfcfd' ORDER BY "django_content_type"."app_label" ASC, "django_content_type"."model" ASC, "auth_permission"."codename" ASC; args=('98c929be19fb4598b30233dd1ddbfcfd',)
[2016-10-27 18:05:38] DEBUG [django.db.backends:89] (0.000) SELECT "auths_user"."password", "auths_user"."last_login", "auths_user"."is_superuser", "auths_user"."username", "auths_user"."first_name", "auths_user"."last_name", "auths_user"."email", "auths_user"."is_staff", "auths_user"."is_active", "auths_user"."date_joined", "auths_user"."id", "auths_user"."last_hierarchy_id", "auths_user"."last_module_id", "auths_user"."person_id", "auths_user"."updated_at", "auths_user"."registered_by" FROM "auths_user" WHERE "auths_user"."username" IS NULL; args=()
[2016-10-27 18:05:38] DEBUG [django.db.backends:89] (0.000) SELECT "oauth2_provider_accesstoken"."id", "oauth2_provider_accesstoken"."user_id", "oauth2_provider_accesstoken"."token", "oauth2_provider_accesstoken"."application_id", "oauth2_provider_accesstoken"."expires", "oauth2_provider_accesstoken"."scope", "auths_user"."password", "auths_user"."last_login", "auths_user"."is_superuser", "auths_user"."username", "auths_user"."first_name", "auths_user"."last_name", "auths_user"."email", "auths_user"."is_staff", "auths_user"."is_active", "auths_user"."date_joined", "auths_user"."id", "auths_user"."last_hierarchy_id", "auths_user"."last_module_id", "auths_user"."person_id", "auths_user"."updated_at", "auths_user"."registered_by", "oauth2_provider_application"."id", "oauth2_provider_application"."client_id", "oauth2_provider_application"."user_id", "oauth2_provider_application"."redirect_uris", "oauth2_provider_application"."client_type", "oauth2_provider_application"."authorization_grant_type", "oauth2_provider_application"."client_secret", "oauth2_provider_application"."name", "oauth2_provider_application"."skip_authorization" FROM "oauth2_provider_accesstoken" LEFT OUTER JOIN "auths_user" ON ("oauth2_provider_accesstoken"."user_id" = "auths_user"."id") INNER JOIN "oauth2_provider_application" ON ("oauth2_provider_accesstoken"."application_id" = "oauth2_provider_application"."id") WHERE "oauth2_provider_accesstoken"."token" = '2sTBQrqOt2c79w6CJdrQrT18aJ6Pra'; args=('2sTBQrqOt2c79w6CJdrQrT18aJ6Pra',)
[2016-10-27 18:05:38] DEBUG [django.db.backends:89] (0.000) SELECT "auths_menu"."id" FROM "auths_menu" WHERE ("auths_menu"."id" IS NOT NULL AND "auths_menu"."is_active" = 1 AND "auths_menu"."module" = 'BACKEND') ORDER BY "auths_menu"."pos" ASC; args=(True, 'BACKEND')
[2016-10-27 18:05:38] DEBUG [django.db.backends:89] (0.000) SELECT DISTINCT "auths_menu"."id", "auths_menu"."module", "auths_menu"."state", "auths_menu"."title", "auths_menu"."url", "auths_menu"."template_url", "auths_menu"."pos", "auths_menu"."icon", "auths_menu"."is_active", "auths_menu"."is_abstract", "auths_menu"."description", "auths_menu"."permission_id", "auths_menu"."parent_id", "auths_menu"."created_at", "auths_menu"."updated_at", "auths_menu"."registered_by" FROM "auths_menu" INNER JOIN "auths_menu" T2 ON ("auths_menu"."id" = T2."parent_id") WHERE (T2."id" IN ('b479e020c80844478293cf7e1320fa5b', '89e73f9bfbde41d3aa4e612f2a2d2d00') AND "auths_menu"."is_active" = 1 AND "auths_menu"."module" = 'BACKEND') ORDER BY "auths_menu"."pos" ASC; args=('b479e020c80844478293cf7e1320fa5b', '89e73f9bfbde41d3aa4e612f2a2d2d00', True, 'BACKEND')
[2016-10-27 18:05:38] DEBUG [django.db.backends:89] (0.000) SELECT "auths_menu"."id", "auths_menu"."module", "auths_menu"."state", "auths_menu"."title", "auths_menu"."url", "auths_menu"."template_url", "auths_menu"."pos", "auths_menu"."icon", "auths_menu"."is_active", "auths_menu"."is_abstract", "auths_menu"."description", "auths_menu"."permission_id", "auths_menu"."parent_id", "auths_menu"."created_at", "auths_menu"."updated_at", "auths_menu"."registered_by" FROM "auths_menu" WHERE ("auths_menu"."id" IS NOT NULL AND "auths_menu"."is_active" = 1 AND "auths_menu"."parent_id" = 'b479e020c80844478293cf7e1320fa5b' AND "auths_menu"."module" = 'BACKEND') ORDER BY "auths_menu"."pos" ASC; args=(True, 'b479e020c80844478293cf7e1320fa5b', 'BACKEND')
[2016-10-27 18:05:38] DEBUG [django.db.backends:89] (0.000) SELECT "auths_menu"."id", "auths_menu"."module", "auths_menu"."state", "auths_menu"."title", "auths_menu"."url", "auths_menu"."template_url", "auths_menu"."pos", "auths_menu"."icon", "auths_menu"."is_active", "auths_menu"."is_abstract", "auths_menu"."description", "auths_menu"."permission_id", "auths_menu"."parent_id", "auths_menu"."created_at", "auths_menu"."updated_at", "auths_menu"."registered_by" FROM "auths_menu" WHERE "auths_menu"."id" = 'b479e020c80844478293cf7e1320fa5b'; args=('b479e020c80844478293cf7e1320fa5b',)
[2016-10-27 18:05:38] DEBUG [django.db.backends:89] (0.000) SELECT (1) AS "a" FROM "django_session" WHERE "django_session"."session_key" = 'w2qobqxd4ssnteppsuysp960wy4bvaln' LIMIT 1; args=('w2qobqxd4ssnteppsuysp960wy4bvaln',)
[2016-10-27 18:05:38] DEBUG [django.db.backends:89] (0.000) BEGIN; args=None
[2016-10-27 18:05:38] DEBUG [django.db.backends:89] (0.016) INSERT INTO "django_session" ("session_key", "session_data", "expire_date") SELECT 'w2qobqxd4ssnteppsuysp960wy4bvaln', 'ZWMyMmE2MTA1MzM3NDcxZTRmYzk5YzliZTNiYjg2ZTZkMjFlMTc0NTp7Il9zZXNzaW9uX2V4cGlyeSI6MzB9', '2016-10-28 00:06:08.122021'; args=('w2qobqxd4ssnteppsuysp960wy4bvaln', 'ZWMyMmE2MTA1MzM3NDcxZTRmYzk5YzliZTNiYjg2ZTZkMjFlMTc0NTp7Il9zZXNzaW9uX2V4cGlyeSI6MzB9', '2016-10-28 00:06:08.122021')
[2016-10-27 18:05:43] DEBUG [django.db.backends:89] (0.004) SELECT "auths_user"."password", "auths_user"."last_login", "auths_user"."is_superuser", "auths_user"."username", "auths_user"."first_name", "auths_user"."last_name", "auths_user"."email", "auths_user"."is_staff", "auths_user"."is_active", "auths_user"."date_joined", "auths_user"."id", "auths_user"."last_hierarchy_id", "auths_user"."last_module_id", "auths_user"."person_id", "auths_user"."updated_at", "auths_user"."registered_by" FROM "auths_user" WHERE "auths_user"."username" IS NULL; args=()
[2016-10-27 18:05:43] DEBUG [django.db.backends:89] (0.004) SELECT "oauth2_provider_accesstoken"."id", "oauth2_provider_accesstoken"."user_id", "oauth2_provider_accesstoken"."token", "oauth2_provider_accesstoken"."application_id", "oauth2_provider_accesstoken"."expires", "oauth2_provider_accesstoken"."scope", "auths_user"."password", "auths_user"."last_login", "auths_user"."is_superuser", "auths_user"."username", "auths_user"."first_name", "auths_user"."last_name", "auths_user"."email", "auths_user"."is_staff", "auths_user"."is_active", "auths_user"."date_joined", "auths_user"."id", "auths_user"."last_hierarchy_id", "auths_user"."last_module_id", "auths_user"."person_id", "auths_user"."updated_at", "auths_user"."registered_by", "oauth2_provider_application"."id", "oauth2_provider_application"."client_id", "oauth2_provider_application"."user_id", "oauth2_provider_application"."redirect_uris", "oauth2_provider_application"."client_type", "oauth2_provider_application"."authorization_grant_type", "oauth2_provider_application"."client_secret", "oauth2_provider_application"."name", "oauth2_provider_application"."skip_authorization" FROM "oauth2_provider_accesstoken" LEFT OUTER JOIN "auths_user" ON ("oauth2_provider_accesstoken"."user_id" = "auths_user"."id") INNER JOIN "oauth2_provider_application" ON ("oauth2_provider_accesstoken"."application_id" = "oauth2_provider_application"."id") WHERE "oauth2_provider_accesstoken"."token" = '2sTBQrqOt2c79w6CJdrQrT18aJ6Pra'; args=('2sTBQrqOt2c79w6CJdrQrT18aJ6Pra',)
[2016-10-27 18:05:43] DEBUG [django.db.backends:89] (0.000) SELECT "catalogo_categoria"."id", "catalogo_categoria"."nombre", "catalogo_categoria"."codigo", "catalogo_categoria"."estado" FROM "catalogo_categoria" WHERE ("catalogo_categoria"."codigo" LIKE '%%' ESCAPE '\' OR "catalogo_categoria"."nombre" LIKE '%%' ESCAPE '\'); args=('%%', '%%')
